[2023-10-29 14:29:13 +0000] [107889] [INFO] Starting gunicorn 21.2.0
[2023-10-29 14:29:13 +0000] [107889] [INFO] Listening at: http://0.0.0.0:8000 (107889)
[2023-10-29 14:29:13 +0000] [107889] [INFO] Using worker: sync
[2023-10-29 14:29:13 +0000] [107890] [INFO] Booting worker with pid: 107890
[2023-10-29 14:29:13 +0000] [107890] [ERROR] Exception in worker process
Traceback (most recent call last):
  File "/home/tech/DataIssueTracker/env/lib/python3.10/site-packages/gunicorn/arbiter.py", line 609, in spawn_worker
    worker.init_process()
  File "/home/tech/DataIssueTracker/env/lib/python3.10/site-packages/gunicorn/workers/base.py", line 134, in init_process
    self.load_wsgi()
  File "/home/tech/DataIssueTracker/env/lib/python3.10/site-packages/gunicorn/workers/base.py", line 146, in load_wsgi
    self.wsgi = self.app.wsgi()
  File "/home/tech/DataIssueTracker/env/lib/python3.10/site-packages/gunicorn/app/base.py", line 67, in wsgi
    self.callable = self.load()
  File "/home/tech/DataIssueTracker/env/lib/python3.10/site-packages/gunicorn/app/wsgiapp.py", line 58, in load
    return self.load_wsgiapp()
  File "/home/tech/DataIssueTracker/env/lib/python3.10/site-packages/gunicorn/app/wsgiapp.py", line 48, in load_wsgiapp
    return util.import_app(self.app_uri)
  File "/home/tech/DataIssueTracker/env/lib/python3.10/site-packages/gunicorn/util.py", line 371, in import_app
    mod = importlib.import_module(module)
  File "/usr/lib/python3.10/importlib/__init__.py", line 126, in import_module
    return _bootstrap._gcd_import(name[level:], package, level)
  File "<frozen importlib._bootstrap>", line 1050, in _gcd_import
  File "<frozen importlib._bootstrap>", line 1027, in _find_and_load
  File "<frozen importlib._bootstrap>", line 1004, in _find_and_load_unlocked
ModuleNotFoundError: No module named 'DITApi.wsgi'
[2023-10-29 14:29:13 +0000] [107890] [INFO] Worker exiting (pid: 107890)
[2023-10-29 14:29:13 +0000] [107889] [ERROR] Worker (pid:107890) exited with code 3
[2023-10-29 14:29:13 +0000] [107889] [ERROR] Shutting down: Master
[2023-10-29 14:29:13 +0000] [107889] [ERROR] Reason: Worker failed to boot.
[2023-10-29 14:30:05 +0000] [107898] [INFO] Starting gunicorn 21.2.0
[2023-10-29 14:30:05 +0000] [107898] [INFO] Listening at: http://0.0.0.0:8000 (107898)
[2023-10-29 14:30:05 +0000] [107898] [INFO] Using worker: sync
[2023-10-29 14:30:05 +0000] [107899] [INFO] Booting worker with pid: 107899
[2023-10-29 14:30:05 +0000] [107899] [ERROR] Exception in worker process
Traceback (most recent call last):
  File "/home/tech/DataIssueTracker/env/lib/python3.10/site-packages/gunicorn/arbiter.py", line 609, in spawn_worker
    worker.init_process()
  File "/home/tech/DataIssueTracker/env/lib/python3.10/site-packages/gunicorn/workers/base.py", line 134, in init_process
    self.load_wsgi()
  File "/home/tech/DataIssueTracker/env/lib/python3.10/site-packages/gunicorn/workers/base.py", line 146, in load_wsgi
    self.wsgi = self.app.wsgi()
  File "/home/tech/DataIssueTracker/env/lib/python3.10/site-packages/gunicorn/app/base.py", line 67, in wsgi
    self.callable = self.load()
  File "/home/tech/DataIssueTracker/env/lib/python3.10/site-packages/gunicorn/app/wsgiapp.py", line 58, in load
    return self.load_wsgiapp()
  File "/home/tech/DataIssueTracker/env/lib/python3.10/site-packages/gunicorn/app/wsgiapp.py", line 48, in load_wsgiapp
    return util.import_app(self.app_uri)
  File "/home/tech/DataIssueTracker/env/lib/python3.10/site-packages/gunicorn/util.py", line 371, in import_app
    mod = importlib.import_module(module)
  File "/usr/lib/python3.10/importlib/__init__.py", line 126, in import_module
    return _bootstrap._gcd_import(name[level:], package, level)
  File "<frozen importlib._bootstrap>", line 1050, in _gcd_import
  File "<frozen importlib._bootstrap>", line 1027, in _find_and_load
  File "<frozen importlib._bootstrap>", line 1004, in _find_and_load_unlocked
ModuleNotFoundError: No module named 'DITApi.wsgi'
[2023-10-29 14:30:05 +0000] [107899] [INFO] Worker exiting (pid: 107899)
[2023-10-29 14:30:05 +0000] [107898] [ERROR] Worker (pid:107899) exited with code 3
[2023-10-29 14:30:05 +0000] [107898] [ERROR] Shutting down: Master
[2023-10-29 14:30:05 +0000] [107898] [ERROR] Reason: Worker failed to boot.
[2023-10-29 14:30:51 +0000] [107954] [INFO] Starting gunicorn 21.2.0
[2023-10-29 14:30:51 +0000] [107954] [INFO] Listening at: http://0.0.0.0:8000 (107954)
[2023-10-29 14:30:51 +0000] [107954] [INFO] Using worker: sync
[2023-10-29 14:30:51 +0000] [107955] [INFO] Booting worker with pid: 107955
[2023-10-29 14:30:51 +0000] [107955] [ERROR] Exception in worker process
Traceback (most recent call last):
  File "/home/tech/DataIssueTracker/env/lib/python3.10/site-packages/gunicorn/arbiter.py", line 609, in spawn_worker
    worker.init_process()
  File "/home/tech/DataIssueTracker/env/lib/python3.10/site-packages/gunicorn/workers/base.py", line 134, in init_process
    self.load_wsgi()
  File "/home/tech/DataIssueTracker/env/lib/python3.10/site-packages/gunicorn/workers/base.py", line 146, in load_wsgi
    self.wsgi = self.app.wsgi()
  File "/home/tech/DataIssueTracker/env/lib/python3.10/site-packages/gunicorn/app/base.py", line 67, in wsgi
    self.callable = self.load()
  File "/home/tech/DataIssueTracker/env/lib/python3.10/site-packages/gunicorn/app/wsgiapp.py", line 58, in load
    return self.load_wsgiapp()
  File "/home/tech/DataIssueTracker/env/lib/python3.10/site-packages/gunicorn/app/wsgiapp.py", line 48, in load_wsgiapp
    return util.import_app(self.app_uri)
  File "/home/tech/DataIssueTracker/env/lib/python3.10/site-packages/gunicorn/util.py", line 371, in import_app
    mod = importlib.import_module(module)
  File "/usr/lib/python3.10/importlib/__init__.py", line 126, in import_module
    return _bootstrap._gcd_import(name[level:], package, level)
  File "<frozen importlib._bootstrap>", line 1050, in _gcd_import
  File "<frozen importlib._bootstrap>", line 1027, in _find_and_load
  File "<frozen importlib._bootstrap>", line 1004, in _find_and_load_unlocked
ModuleNotFoundError: No module named 'DITApi.wsgi'
[2023-10-29 14:30:51 +0000] [107955] [INFO] Worker exiting (pid: 107955)
[2023-10-29 14:30:51 +0000] [107954] [ERROR] Worker (pid:107955) exited with code 3
[2023-10-29 14:30:51 +0000] [107954] [ERROR] Shutting down: Master
[2023-10-29 14:30:51 +0000] [107954] [ERROR] Reason: Worker failed to boot.
[2023-10-29 15:44:57 +0000] [109350] [INFO] Starting gunicorn 21.2.0
[2023-10-29 15:44:57 +0000] [109350] [INFO] Listening at: http://0.0.0.0:8000 (109350)
[2023-10-29 15:44:57 +0000] [109350] [INFO] Using worker: sync
[2023-10-29 15:44:57 +0000] [109351] [INFO] Booting worker with pid: 109351
[2023-10-29 15:44:57 +0000] [109351] [ERROR] Exception in worker process
Traceback (most recent call last):
  File "/home/tech/DataIssueTracker/env/lib/python3.10/site-packages/gunicorn/arbiter.py", line 609, in spawn_worker
    worker.init_process()
  File "/home/tech/DataIssueTracker/env/lib/python3.10/site-packages/gunicorn/workers/base.py", line 134, in init_process
    self.load_wsgi()
  File "/home/tech/DataIssueTracker/env/lib/python3.10/site-packages/gunicorn/workers/base.py", line 146, in load_wsgi
    self.wsgi = self.app.wsgi()
  File "/home/tech/DataIssueTracker/env/lib/python3.10/site-packages/gunicorn/app/base.py", line 67, in wsgi
    self.callable = self.load()
  File "/home/tech/DataIssueTracker/env/lib/python3.10/site-packages/gunicorn/app/wsgiapp.py", line 58, in load
    return self.load_wsgiapp()
  File "/home/tech/DataIssueTracker/env/lib/python3.10/site-packages/gunicorn/app/wsgiapp.py", line 48, in load_wsgiapp
    return util.import_app(self.app_uri)
  File "/home/tech/DataIssueTracker/env/lib/python3.10/site-packages/gunicorn/util.py", line 371, in import_app
    mod = importlib.import_module(module)
  File "/usr/lib/python3.10/importlib/__init__.py", line 126, in import_module
    return _bootstrap._gcd_import(name[level:], package, level)
  File "<frozen importlib._bootstrap>", line 1050, in _gcd_import
  File "<frozen importlib._bootstrap>", line 1027, in _find_and_load
  File "<frozen importlib._bootstrap>", line 1004, in _find_and_load_unlocked
ModuleNotFoundError: No module named 'DITApi.wsgi'
[2023-10-29 15:44:57 +0000] [109351] [INFO] Worker exiting (pid: 109351)
[2023-10-29 15:44:57 +0000] [109350] [ERROR] Worker (pid:109351) exited with code 3
[2023-10-29 15:44:57 +0000] [109350] [ERROR] Shutting down: Master
[2023-10-29 15:44:57 +0000] [109350] [ERROR] Reason: Worker failed to boot.
