Watching for file changes with StatReloader
Adding job tentatively -- it will be properly scheduled when the scheduler starts
Added job "Command.handle" to job store "default"
Scheduler started
Looking for jobs to run
Next wakeup is due at 2023-10-29 19:08:12.359946+03:00 (in 3599.993661 seconds)
Successfully imported extension module "markdown.extensions.toc".
Successfully loaded extension "markdown.extensions.toc.TocExtension".
Method Not Allowed: /api/sync_data/
Successfully imported extension module "markdown.extensions.toc".
Successfully loaded extension "markdown.extensions.toc.TocExtension".
Method Not Allowed: /api/login/
Processing login mail
Email thread started!
Successfully imported extension module "markdown.extensions.toc".
Successfully loaded extension "markdown.extensions.toc.TocExtension".
Not Found: /api/data/
Successfully imported extension module "markdown.extensions.toc".
Successfully loaded extension "markdown.extensions.toc.TocExtension".
Method Not Allowed: /api/sync_data/
Data sync active...
[Errno 2] No such file or directory: '/app/facility data issues'
Successfully imported extension module "markdown.extensions.toc".
Successfully loaded extension "markdown.extensions.toc.TocExtension".
Successfully imported extension module "markdown.extensions.toc".
Successfully loaded extension "markdown.extensions.toc.TocExtension".
Method Not Allowed: /api/sync_data/
Couldnt reverse DQIT_Endpoint
avatar field must be an ImageField/URLField on the user model, or a callable
Couldnt reverse DQIT_Endpoint
Couldnt reverse DQIT_Endpoint
avatar field must be an ImageField/URLField on the user model, or a callable
Couldnt reverse DQIT_Endpoint
avatar field must be an ImageField/URLField on the user model, or a callable
Couldnt reverse DQIT_Endpoint
avatar field must be an ImageField/URLField on the user model, or a callable
Couldnt reverse DQIT_Endpoint
avatar field must be an ImageField/URLField on the user model, or a callable
Couldnt reverse DQIT_Endpoint
avatar field must be an ImageField/URLField on the user model, or a callable
Couldnt reverse DQIT_Endpoint
avatar field must be an ImageField/URLField on the user model, or a callable
Data sync active...
[Errno 2] No such file or directory: 'E:/projects/DataIssueTracker/DITApi/media/facility data issues'
Successfully imported extension module "markdown.extensions.toc".
Successfully loaded extension "markdown.extensions.toc.TocExtension".
Couldnt reverse DQIT_Endpoint
avatar field must be an ImageField/URLField on the user model, or a callable
Couldnt reverse DQIT_Endpoint
avatar field must be an ImageField/URLField on the user model, or a callable
Data sync active...
All files processed
Successfully imported extension module "markdown.extensions.toc".
Successfully loaded extension "markdown.extensions.toc.TocExtension".
/home/titusdev/projects/DataIssueTracker/DITApi/DQITAuth/views.py changed, reloading.
Watching for file changes with StatReloader
Adding job tentatively -- it will be properly scheduled when the scheduler starts
Added job "Command.handle" to job store "default"
Scheduler started
Looking for jobs to run
Next wakeup is due at 2023-10-29 19:19:30.162336+03:00 (in 3599.998630 seconds)
/home/titusdev/projects/DataIssueTracker/DITApi/DQIT_Endpoint/views.py changed, reloading.
Watching for file changes with StatReloader
Adding job tentatively -- it will be properly scheduled when the scheduler starts
Added job "Command.handle" to job store "default"
Scheduler started
Looking for jobs to run
Next wakeup is due at 2023-10-29 19:20:03.037067+03:00 (in 3599.999096 seconds)
/home/titusdev/projects/DataIssueTracker/DITApi/DQIT_Endpoint/views.py changed, reloading.
Watching for file changes with StatReloader
Adding job tentatively -- it will be properly scheduled when the scheduler starts
Added job "Command.handle" to job store "default"
Scheduler started
Looking for jobs to run
Next wakeup is due at 2023-10-29 19:20:17.567423+03:00 (in 3599.998832 seconds)
Couldnt reverse DQIT_Endpoint
avatar field must be an ImageField/URLField on the user model, or a callable
Couldnt reverse DQIT_Endpoint
avatar field must be an ImageField/URLField on the user model, or a callable
Data sync active...
All files processed
Successfully imported extension module "markdown.extensions.toc".
Successfully loaded extension "markdown.extensions.toc.TocExtension".
/home/titusdev/projects/DataIssueTracker/DITApi/DQIT_Endpoint/utils.py changed, reloading.
Watching for file changes with StatReloader
Adding job tentatively -- it will be properly scheduled when the scheduler starts
Added job "Command.handle" to job store "default"
Scheduler started
Looking for jobs to run
Next wakeup is due at 2023-10-29 19:22:07.527670+03:00 (in 3599.998870 seconds)
/home/titusdev/projects/DataIssueTracker/DITApi/DQIT_Endpoint/utils.py changed, reloading.
Watching for file changes with StatReloader
Adding job tentatively -- it will be properly scheduled when the scheduler starts
Added job "Command.handle" to job store "default"
Scheduler started
Looking for jobs to run
Next wakeup is due at 2023-10-29 19:22:17.295277+03:00 (in 3599.993706 seconds)
/home/titusdev/projects/DataIssueTracker/DITApi/DQIT_Endpoint/utils.py changed, reloading.
Watching for file changes with StatReloader
Adding job tentatively -- it will be properly scheduled when the scheduler starts
Added job "Command.handle" to job store "default"
Scheduler started
Looking for jobs to run
Next wakeup is due at 2023-10-29 19:22:23.594591+03:00 (in 3599.993593 seconds)
/home/titusdev/projects/DataIssueTracker/DITApi/DQIT_Endpoint/utils.py changed, reloading.
Watching for file changes with StatReloader
Adding job tentatively -- it will be properly scheduled when the scheduler starts
Added job "Command.handle" to job store "default"
Scheduler started
Looking for jobs to run
Next wakeup is due at 2023-10-29 19:22:31.055539+03:00 (in 3599.993775 seconds)
Adding job tentatively -- it will be properly scheduled when the scheduler starts
Added job "Command.handle" to job store "default"
Scheduler started
Looking for jobs to run
Next wakeup is due at 2023-10-29 19:27:09.690794+03:00 (in 3599.987943 seconds)
Couldnt reverse DQIT_Endpoint
avatar field must be an ImageField/URLField on the user model, or a callable
Successfully imported extension module "markdown.extensions.toc".
Successfully loaded extension "markdown.extensions.toc.TocExtension".
Method Not Allowed: /api/sync_data/
Adding job tentatively -- it will be properly scheduled when the scheduler starts
Added job "Command.handle" to job store "default"
Scheduler started
Looking for jobs to run
Next wakeup is due at 2023-10-29 19:43:21.864735+03:00 (in 3599.989970 seconds)
Couldnt reverse DQIT_Endpoint
avatar field must be an ImageField/URLField on the user model, or a callable
Successfully imported extension module "markdown.extensions.toc".
Successfully loaded extension "markdown.extensions.toc.TocExtension".
Method Not Allowed: /api/sync_data/
Adding job tentatively -- it will be properly scheduled when the scheduler starts
Added job "Command.handle" to job store "default"
Scheduler started
Looking for jobs to run
Next wakeup is due at 2023-10-29 19:46:09.497708+03:00 (in 3599.991139 seconds)
Successfully imported extension module "markdown.extensions.toc".
Successfully loaded extension "markdown.extensions.toc.TocExtension".
Method Not Allowed: /api/sync_data/
Couldnt reverse DQIT_Endpoint
avatar field must be an ImageField/URLField on the user model, or a callable
Data sync active...
Adding job tentatively -- it will be properly scheduled when the scheduler starts
Added job "Command.handle" to job store "default"
Scheduler started
Looking for jobs to run
Next wakeup is due at 2023-10-29 19:47:01.130712+03:00 (in 3599.991713 seconds)
Successfully imported extension module "markdown.extensions.toc".
Successfully loaded extension "markdown.extensions.toc.TocExtension".
Method Not Allowed: /api/sync_data/
Couldnt reverse DQIT_Endpoint
avatar field must be an ImageField/URLField on the user model, or a callable
Couldnt reverse DQIT_Endpoint
avatar field must be an ImageField/URLField on the user model, or a callable
Couldnt reverse DQIT_Endpoint
avatar field must be an ImageField/URLField on the user model, or a callable
Data sync active...
Adding job tentatively -- it will be properly scheduled when the scheduler starts
Added job "Command.handle" to job store "default"
Scheduler started
Looking for jobs to run
Next wakeup is due at 2023-10-29 19:48:38.308526+03:00 (in 3599.993767 seconds)
Successfully imported extension module "markdown.extensions.toc".
Successfully loaded extension "markdown.extensions.toc.TocExtension".
Method Not Allowed: /api/sync_data/
Processing login mail
Email thread started!
Unauthorized: /api/analytics/
Unauthorized: /api/data_issue_stats/
Unauthorized: /api/data_issues/
Unauthorized: /api/user-logs/
Unauthorized: /api/facilities/
Processing login mail
Email thread started!
Internal Server Error: /api/user-logs/
Traceback (most recent call last):
  File "/home/tech/DataIssueTracker/env/lib/python3.10/site-packages/django/db/backends/utils.py", line 89, in _execute
    return self.cursor.execute(sql, params)
  File "/home/tech/DataIssueTracker/env/lib/python3.10/site-packages/django/db/backends/mysql/base.py", line 75, in execute
    return self.cursor.execute(query, args)
  File "/home/tech/DataIssueTracker/env/lib/python3.10/site-packages/MySQLdb/cursors.py", line 179, in execute
    res = self._query(mogrified_query)
  File "/home/tech/DataIssueTracker/env/lib/python3.10/site-packages/MySQLdb/cursors.py", line 330, in _query
    db.query(q)
  File "/home/tech/DataIssueTracker/env/lib/python3.10/site-packages/MySQLdb/connections.py", line 255, in query
    _mysql.connection.query(self, query)
MySQLdb.ProgrammingError: (1146, "Table 'dqits.DQITAuth_userlog' doesn't exist")

The above exception was the direct cause of the following exception:

Traceback (most recent call last):
  File "/home/tech/DataIssueTracker/env/lib/python3.10/site-packages/django/core/handlers/exception.py", line 55, in inner
    response = get_response(request)
  File "/home/tech/DataIssueTracker/env/lib/python3.10/site-packages/django/core/handlers/base.py", line 197, in _get_response
    response = wrapped_callback(request, *callback_args, **callback_kwargs)
  File "/home/tech/DataIssueTracker/env/lib/python3.10/site-packages/django/views/decorators/csrf.py", line 56, in wrapper_view
    return view_func(*args, **kwargs)
  File "/home/tech/DataIssueTracker/env/lib/python3.10/site-packages/django/views/generic/base.py", line 104, in view
    return self.dispatch(request, *args, **kwargs)
  File "/home/tech/DataIssueTracker/env/lib/python3.10/site-packages/rest_framework/views.py", line 509, in dispatch
    response = self.handle_exception(exc)
  File "/home/tech/DataIssueTracker/env/lib/python3.10/site-packages/rest_framework/views.py", line 469, in handle_exception
    self.raise_uncaught_exception(exc)
  File "/home/tech/DataIssueTracker/env/lib/python3.10/site-packages/rest_framework/views.py", line 480, in raise_uncaught_exception
    raise exc
  File "/home/tech/DataIssueTracker/env/lib/python3.10/site-packages/rest_framework/views.py", line 506, in dispatch
    response = handler(request, *args, **kwargs)
  File "/home/tech/DataIssueTracker/DITApi/DQITAuth/views.py", line 312, in get
    result_page = paginator.paginate_queryset(logs, request)
  File "/home/tech/DataIssueTracker/env/lib/python3.10/site-packages/rest_framework/pagination.py", line 387, in paginate_queryset
    self.count = self.get_count(queryset)
  File "/home/tech/DataIssueTracker/env/lib/python3.10/site-packages/rest_framework/pagination.py", line 525, in get_count
    return queryset.count()
  File "/home/tech/DataIssueTracker/env/lib/python3.10/site-packages/django/db/models/query.py", line 608, in count
    return self.query.get_count(using=self.db)
  File "/home/tech/DataIssueTracker/env/lib/python3.10/site-packages/django/db/models/sql/query.py", line 568, in get_count
    return obj.get_aggregation(using, {"__count": Count("*")})["__count"]
  File "/home/tech/DataIssueTracker/env/lib/python3.10/site-packages/django/db/models/sql/query.py", line 554, in get_aggregation
    result = compiler.execute_sql(SINGLE)
  File "/home/tech/DataIssueTracker/env/lib/python3.10/site-packages/django/db/models/sql/compiler.py", line 1562, in execute_sql
    cursor.execute(sql, params)
  File "/home/tech/DataIssueTracker/env/lib/python3.10/site-packages/django/db/backends/utils.py", line 102, in execute
    return super().execute(sql, params)
  File "/home/tech/DataIssueTracker/env/lib/python3.10/site-packages/django/db/backends/utils.py", line 67, in execute
    return self._execute_with_wrappers(
  File "/home/tech/DataIssueTracker/env/lib/python3.10/site-packages/django/db/backends/utils.py", line 80, in _execute_with_wrappers
    return executor(sql, params, many, context)
  File "/home/tech/DataIssueTracker/env/lib/python3.10/site-packages/django/db/backends/utils.py", line 84, in _execute
    with self.db.wrap_database_errors:
  File "/home/tech/DataIssueTracker/env/lib/python3.10/site-packages/django/db/utils.py", line 91, in __exit__
    raise dj_exc_value.with_traceback(traceback) from exc_value
  File "/home/tech/DataIssueTracker/env/lib/python3.10/site-packages/django/db/backends/utils.py", line 89, in _execute
    return self.cursor.execute(sql, params)
  File "/home/tech/DataIssueTracker/env/lib/python3.10/site-packages/django/db/backends/mysql/base.py", line 75, in execute
    return self.cursor.execute(query, args)
  File "/home/tech/DataIssueTracker/env/lib/python3.10/site-packages/MySQLdb/cursors.py", line 179, in execute
    res = self._query(mogrified_query)
  File "/home/tech/DataIssueTracker/env/lib/python3.10/site-packages/MySQLdb/cursors.py", line 330, in _query
    db.query(q)
  File "/home/tech/DataIssueTracker/env/lib/python3.10/site-packages/MySQLdb/connections.py", line 255, in query
    _mysql.connection.query(self, query)
django.db.utils.ProgrammingError: (1146, "Table 'dqits.DQITAuth_userlog' doesn't exist")
Data sync active...
Adding job tentatively -- it will be properly scheduled when the scheduler starts
Added job "Command.handle" to job store "default"
Scheduler started
Looking for jobs to run
Next wakeup is due at 2023-10-29 19:55:38.576238+03:00 (in 3599.993114 seconds)
Couldnt reverse DQIT_Endpoint
avatar field must be an ImageField/URLField on the user model, or a callable
Data sync active...
Adding job tentatively -- it will be properly scheduled when the scheduler starts
Added job "Command.handle" to job store "default"
Scheduler started
Looking for jobs to run
Next wakeup is due at 2023-10-29 19:56:20.298495+03:00 (in 3599.991785 seconds)
Successfully imported extension module "markdown.extensions.toc".
Successfully loaded extension "markdown.extensions.toc.TocExtension".
Method Not Allowed: /api/sync_data/
Internal Server Error: /api/user-logs/
Traceback (most recent call last):
  File "/home/tech/DataIssueTracker/env/lib/python3.10/site-packages/django/db/backends/utils.py", line 89, in _execute
    return self.cursor.execute(sql, params)
  File "/home/tech/DataIssueTracker/env/lib/python3.10/site-packages/django/db/backends/mysql/base.py", line 75, in execute
    return self.cursor.execute(query, args)
  File "/home/tech/DataIssueTracker/env/lib/python3.10/site-packages/MySQLdb/cursors.py", line 179, in execute
    res = self._query(mogrified_query)
  File "/home/tech/DataIssueTracker/env/lib/python3.10/site-packages/MySQLdb/cursors.py", line 330, in _query
    db.query(q)
  File "/home/tech/DataIssueTracker/env/lib/python3.10/site-packages/MySQLdb/connections.py", line 255, in query
    _mysql.connection.query(self, query)
MySQLdb.ProgrammingError: (1146, "Table 'dqits.DQITAuth_userlog' doesn't exist")

The above exception was the direct cause of the following exception:

Traceback (most recent call last):
  File "/home/tech/DataIssueTracker/env/lib/python3.10/site-packages/django/core/handlers/exception.py", line 55, in inner
    response = get_response(request)
  File "/home/tech/DataIssueTracker/env/lib/python3.10/site-packages/django/core/handlers/base.py", line 197, in _get_response
    response = wrapped_callback(request, *callback_args, **callback_kwargs)
  File "/home/tech/DataIssueTracker/env/lib/python3.10/site-packages/django/views/decorators/csrf.py", line 56, in wrapper_view
    return view_func(*args, **kwargs)
  File "/home/tech/DataIssueTracker/env/lib/python3.10/site-packages/django/views/generic/base.py", line 104, in view
    return self.dispatch(request, *args, **kwargs)
  File "/home/tech/DataIssueTracker/env/lib/python3.10/site-packages/rest_framework/views.py", line 509, in dispatch
    response = self.handle_exception(exc)
  File "/home/tech/DataIssueTracker/env/lib/python3.10/site-packages/rest_framework/views.py", line 469, in handle_exception
    self.raise_uncaught_exception(exc)
  File "/home/tech/DataIssueTracker/env/lib/python3.10/site-packages/rest_framework/views.py", line 480, in raise_uncaught_exception
    raise exc
  File "/home/tech/DataIssueTracker/env/lib/python3.10/site-packages/rest_framework/views.py", line 506, in dispatch
    response = handler(request, *args, **kwargs)
  File "/home/tech/DataIssueTracker/DITApi/DQITAuth/views.py", line 312, in get
    result_page = paginator.paginate_queryset(logs, request)
  File "/home/tech/DataIssueTracker/env/lib/python3.10/site-packages/rest_framework/pagination.py", line 387, in paginate_queryset
    self.count = self.get_count(queryset)
  File "/home/tech/DataIssueTracker/env/lib/python3.10/site-packages/rest_framework/pagination.py", line 525, in get_count
    return queryset.count()
  File "/home/tech/DataIssueTracker/env/lib/python3.10/site-packages/django/db/models/query.py", line 608, in count
    return self.query.get_count(using=self.db)
  File "/home/tech/DataIssueTracker/env/lib/python3.10/site-packages/django/db/models/sql/query.py", line 568, in get_count
    return obj.get_aggregation(using, {"__count": Count("*")})["__count"]
  File "/home/tech/DataIssueTracker/env/lib/python3.10/site-packages/django/db/models/sql/query.py", line 554, in get_aggregation
    result = compiler.execute_sql(SINGLE)
  File "/home/tech/DataIssueTracker/env/lib/python3.10/site-packages/django/db/models/sql/compiler.py", line 1562, in execute_sql
    cursor.execute(sql, params)
  File "/home/tech/DataIssueTracker/env/lib/python3.10/site-packages/django/db/backends/utils.py", line 102, in execute
    return super().execute(sql, params)
  File "/home/tech/DataIssueTracker/env/lib/python3.10/site-packages/django/db/backends/utils.py", line 67, in execute
    return self._execute_with_wrappers(
  File "/home/tech/DataIssueTracker/env/lib/python3.10/site-packages/django/db/backends/utils.py", line 80, in _execute_with_wrappers
    return executor(sql, params, many, context)
  File "/home/tech/DataIssueTracker/env/lib/python3.10/site-packages/django/db/backends/utils.py", line 84, in _execute
    with self.db.wrap_database_errors:
  File "/home/tech/DataIssueTracker/env/lib/python3.10/site-packages/django/db/utils.py", line 91, in __exit__
    raise dj_exc_value.with_traceback(traceback) from exc_value
  File "/home/tech/DataIssueTracker/env/lib/python3.10/site-packages/django/db/backends/utils.py", line 89, in _execute
    return self.cursor.execute(sql, params)
  File "/home/tech/DataIssueTracker/env/lib/python3.10/site-packages/django/db/backends/mysql/base.py", line 75, in execute
    return self.cursor.execute(query, args)
  File "/home/tech/DataIssueTracker/env/lib/python3.10/site-packages/MySQLdb/cursors.py", line 179, in execute
    res = self._query(mogrified_query)
  File "/home/tech/DataIssueTracker/env/lib/python3.10/site-packages/MySQLdb/cursors.py", line 330, in _query
    db.query(q)
  File "/home/tech/DataIssueTracker/env/lib/python3.10/site-packages/MySQLdb/connections.py", line 255, in query
    _mysql.connection.query(self, query)
django.db.utils.ProgrammingError: (1146, "Table 'dqits.DQITAuth_userlog' doesn't exist")
Internal Server Error: /api/user-logs/
Traceback (most recent call last):
  File "/home/tech/DataIssueTracker/env/lib/python3.10/site-packages/django/db/backends/utils.py", line 89, in _execute
    return self.cursor.execute(sql, params)
  File "/home/tech/DataIssueTracker/env/lib/python3.10/site-packages/django/db/backends/mysql/base.py", line 75, in execute
    return self.cursor.execute(query, args)
  File "/home/tech/DataIssueTracker/env/lib/python3.10/site-packages/MySQLdb/cursors.py", line 179, in execute
    res = self._query(mogrified_query)
  File "/home/tech/DataIssueTracker/env/lib/python3.10/site-packages/MySQLdb/cursors.py", line 330, in _query
    db.query(q)
  File "/home/tech/DataIssueTracker/env/lib/python3.10/site-packages/MySQLdb/connections.py", line 255, in query
    _mysql.connection.query(self, query)
MySQLdb.ProgrammingError: (1146, "Table 'dqits.DQITAuth_userlog' doesn't exist")

The above exception was the direct cause of the following exception:

Traceback (most recent call last):
  File "/home/tech/DataIssueTracker/env/lib/python3.10/site-packages/django/core/handlers/exception.py", line 55, in inner
    response = get_response(request)
  File "/home/tech/DataIssueTracker/env/lib/python3.10/site-packages/django/core/handlers/base.py", line 197, in _get_response
    response = wrapped_callback(request, *callback_args, **callback_kwargs)
  File "/home/tech/DataIssueTracker/env/lib/python3.10/site-packages/django/views/decorators/csrf.py", line 56, in wrapper_view
    return view_func(*args, **kwargs)
  File "/home/tech/DataIssueTracker/env/lib/python3.10/site-packages/django/views/generic/base.py", line 104, in view
    return self.dispatch(request, *args, **kwargs)
  File "/home/tech/DataIssueTracker/env/lib/python3.10/site-packages/rest_framework/views.py", line 509, in dispatch
    response = self.handle_exception(exc)
  File "/home/tech/DataIssueTracker/env/lib/python3.10/site-packages/rest_framework/views.py", line 469, in handle_exception
    self.raise_uncaught_exception(exc)
  File "/home/tech/DataIssueTracker/env/lib/python3.10/site-packages/rest_framework/views.py", line 480, in raise_uncaught_exception
    raise exc
  File "/home/tech/DataIssueTracker/env/lib/python3.10/site-packages/rest_framework/views.py", line 506, in dispatch
    response = handler(request, *args, **kwargs)
  File "/home/tech/DataIssueTracker/DITApi/DQITAuth/views.py", line 312, in get
    result_page = paginator.paginate_queryset(logs, request)
  File "/home/tech/DataIssueTracker/env/lib/python3.10/site-packages/rest_framework/pagination.py", line 387, in paginate_queryset
    self.count = self.get_count(queryset)
  File "/home/tech/DataIssueTracker/env/lib/python3.10/site-packages/rest_framework/pagination.py", line 525, in get_count
    return queryset.count()
  File "/home/tech/DataIssueTracker/env/lib/python3.10/site-packages/django/db/models/query.py", line 608, in count
    return self.query.get_count(using=self.db)
  File "/home/tech/DataIssueTracker/env/lib/python3.10/site-packages/django/db/models/sql/query.py", line 568, in get_count
    return obj.get_aggregation(using, {"__count": Count("*")})["__count"]
  File "/home/tech/DataIssueTracker/env/lib/python3.10/site-packages/django/db/models/sql/query.py", line 554, in get_aggregation
    result = compiler.execute_sql(SINGLE)
  File "/home/tech/DataIssueTracker/env/lib/python3.10/site-packages/django/db/models/sql/compiler.py", line 1562, in execute_sql
    cursor.execute(sql, params)
  File "/home/tech/DataIssueTracker/env/lib/python3.10/site-packages/django/db/backends/utils.py", line 102, in execute
    return super().execute(sql, params)
  File "/home/tech/DataIssueTracker/env/lib/python3.10/site-packages/django/db/backends/utils.py", line 67, in execute
    return self._execute_with_wrappers(
  File "/home/tech/DataIssueTracker/env/lib/python3.10/site-packages/django/db/backends/utils.py", line 80, in _execute_with_wrappers
    return executor(sql, params, many, context)
  File "/home/tech/DataIssueTracker/env/lib/python3.10/site-packages/django/db/backends/utils.py", line 84, in _execute
    with self.db.wrap_database_errors:
  File "/home/tech/DataIssueTracker/env/lib/python3.10/site-packages/django/db/utils.py", line 91, in __exit__
    raise dj_exc_value.with_traceback(traceback) from exc_value
  File "/home/tech/DataIssueTracker/env/lib/python3.10/site-packages/django/db/backends/utils.py", line 89, in _execute
    return self.cursor.execute(sql, params)
  File "/home/tech/DataIssueTracker/env/lib/python3.10/site-packages/django/db/backends/mysql/base.py", line 75, in execute
    return self.cursor.execute(query, args)
  File "/home/tech/DataIssueTracker/env/lib/python3.10/site-packages/MySQLdb/cursors.py", line 179, in execute
    res = self._query(mogrified_query)
  File "/home/tech/DataIssueTracker/env/lib/python3.10/site-packages/MySQLdb/cursors.py", line 330, in _query
    db.query(q)
  File "/home/tech/DataIssueTracker/env/lib/python3.10/site-packages/MySQLdb/connections.py", line 255, in query
    _mysql.connection.query(self, query)
django.db.utils.ProgrammingError: (1146, "Table 'dqits.DQITAuth_userlog' doesn't exist")
Internal Server Error: /api/user-logs/
Traceback (most recent call last):
  File "/home/tech/DataIssueTracker/env/lib/python3.10/site-packages/django/db/backends/utils.py", line 89, in _execute
    return self.cursor.execute(sql, params)
  File "/home/tech/DataIssueTracker/env/lib/python3.10/site-packages/django/db/backends/mysql/base.py", line 75, in execute
    return self.cursor.execute(query, args)
  File "/home/tech/DataIssueTracker/env/lib/python3.10/site-packages/MySQLdb/cursors.py", line 179, in execute
    res = self._query(mogrified_query)
  File "/home/tech/DataIssueTracker/env/lib/python3.10/site-packages/MySQLdb/cursors.py", line 330, in _query
    db.query(q)
  File "/home/tech/DataIssueTracker/env/lib/python3.10/site-packages/MySQLdb/connections.py", line 255, in query
    _mysql.connection.query(self, query)
MySQLdb.ProgrammingError: (1146, "Table 'dqits.DQITAuth_userlog' doesn't exist")

The above exception was the direct cause of the following exception:

Traceback (most recent call last):
  File "/home/tech/DataIssueTracker/env/lib/python3.10/site-packages/django/core/handlers/exception.py", line 55, in inner
    response = get_response(request)
  File "/home/tech/DataIssueTracker/env/lib/python3.10/site-packages/django/core/handlers/base.py", line 197, in _get_response
    response = wrapped_callback(request, *callback_args, **callback_kwargs)
  File "/home/tech/DataIssueTracker/env/lib/python3.10/site-packages/django/views/decorators/csrf.py", line 56, in wrapper_view
    return view_func(*args, **kwargs)
  File "/home/tech/DataIssueTracker/env/lib/python3.10/site-packages/django/views/generic/base.py", line 104, in view
    return self.dispatch(request, *args, **kwargs)
  File "/home/tech/DataIssueTracker/env/lib/python3.10/site-packages/rest_framework/views.py", line 509, in dispatch
    response = self.handle_exception(exc)
  File "/home/tech/DataIssueTracker/env/lib/python3.10/site-packages/rest_framework/views.py", line 469, in handle_exception
    self.raise_uncaught_exception(exc)
  File "/home/tech/DataIssueTracker/env/lib/python3.10/site-packages/rest_framework/views.py", line 480, in raise_uncaught_exception
    raise exc
  File "/home/tech/DataIssueTracker/env/lib/python3.10/site-packages/rest_framework/views.py", line 506, in dispatch
    response = handler(request, *args, **kwargs)
  File "/home/tech/DataIssueTracker/DITApi/DQITAuth/views.py", line 312, in get
    result_page = paginator.paginate_queryset(logs, request)
  File "/home/tech/DataIssueTracker/env/lib/python3.10/site-packages/rest_framework/pagination.py", line 387, in paginate_queryset
    self.count = self.get_count(queryset)
  File "/home/tech/DataIssueTracker/env/lib/python3.10/site-packages/rest_framework/pagination.py", line 525, in get_count
    return queryset.count()
  File "/home/tech/DataIssueTracker/env/lib/python3.10/site-packages/django/db/models/query.py", line 608, in count
    return self.query.get_count(using=self.db)
  File "/home/tech/DataIssueTracker/env/lib/python3.10/site-packages/django/db/models/sql/query.py", line 568, in get_count
    return obj.get_aggregation(using, {"__count": Count("*")})["__count"]
  File "/home/tech/DataIssueTracker/env/lib/python3.10/site-packages/django/db/models/sql/query.py", line 554, in get_aggregation
    result = compiler.execute_sql(SINGLE)
  File "/home/tech/DataIssueTracker/env/lib/python3.10/site-packages/django/db/models/sql/compiler.py", line 1562, in execute_sql
    cursor.execute(sql, params)
  File "/home/tech/DataIssueTracker/env/lib/python3.10/site-packages/django/db/backends/utils.py", line 102, in execute
    return super().execute(sql, params)
  File "/home/tech/DataIssueTracker/env/lib/python3.10/site-packages/django/db/backends/utils.py", line 67, in execute
    return self._execute_with_wrappers(
  File "/home/tech/DataIssueTracker/env/lib/python3.10/site-packages/django/db/backends/utils.py", line 80, in _execute_with_wrappers
    return executor(sql, params, many, context)
  File "/home/tech/DataIssueTracker/env/lib/python3.10/site-packages/django/db/backends/utils.py", line 84, in _execute
    with self.db.wrap_database_errors:
  File "/home/tech/DataIssueTracker/env/lib/python3.10/site-packages/django/db/utils.py", line 91, in __exit__
    raise dj_exc_value.with_traceback(traceback) from exc_value
  File "/home/tech/DataIssueTracker/env/lib/python3.10/site-packages/django/db/backends/utils.py", line 89, in _execute
    return self.cursor.execute(sql, params)
  File "/home/tech/DataIssueTracker/env/lib/python3.10/site-packages/django/db/backends/mysql/base.py", line 75, in execute
    return self.cursor.execute(query, args)
  File "/home/tech/DataIssueTracker/env/lib/python3.10/site-packages/MySQLdb/cursors.py", line 179, in execute
    res = self._query(mogrified_query)
  File "/home/tech/DataIssueTracker/env/lib/python3.10/site-packages/MySQLdb/cursors.py", line 330, in _query
    db.query(q)
  File "/home/tech/DataIssueTracker/env/lib/python3.10/site-packages/MySQLdb/connections.py", line 255, in query
    _mysql.connection.query(self, query)
django.db.utils.ProgrammingError: (1146, "Table 'dqits.DQITAuth_userlog' doesn't exist")
Internal Server Error: /api/user-logs/
Traceback (most recent call last):
  File "/home/tech/DataIssueTracker/env/lib/python3.10/site-packages/django/db/backends/utils.py", line 89, in _execute
    return self.cursor.execute(sql, params)
  File "/home/tech/DataIssueTracker/env/lib/python3.10/site-packages/django/db/backends/mysql/base.py", line 75, in execute
    return self.cursor.execute(query, args)
  File "/home/tech/DataIssueTracker/env/lib/python3.10/site-packages/MySQLdb/cursors.py", line 179, in execute
    res = self._query(mogrified_query)
  File "/home/tech/DataIssueTracker/env/lib/python3.10/site-packages/MySQLdb/cursors.py", line 330, in _query
    db.query(q)
  File "/home/tech/DataIssueTracker/env/lib/python3.10/site-packages/MySQLdb/connections.py", line 255, in query
    _mysql.connection.query(self, query)
MySQLdb.ProgrammingError: (1146, "Table 'dqits.DQITAuth_userlog' doesn't exist")

The above exception was the direct cause of the following exception:

Traceback (most recent call last):
  File "/home/tech/DataIssueTracker/env/lib/python3.10/site-packages/django/core/handlers/exception.py", line 55, in inner
    response = get_response(request)
  File "/home/tech/DataIssueTracker/env/lib/python3.10/site-packages/django/core/handlers/base.py", line 197, in _get_response
    response = wrapped_callback(request, *callback_args, **callback_kwargs)
  File "/home/tech/DataIssueTracker/env/lib/python3.10/site-packages/django/views/decorators/csrf.py", line 56, in wrapper_view
    return view_func(*args, **kwargs)
  File "/home/tech/DataIssueTracker/env/lib/python3.10/site-packages/django/views/generic/base.py", line 104, in view
    return self.dispatch(request, *args, **kwargs)
  File "/home/tech/DataIssueTracker/env/lib/python3.10/site-packages/rest_framework/views.py", line 509, in dispatch
    response = self.handle_exception(exc)
  File "/home/tech/DataIssueTracker/env/lib/python3.10/site-packages/rest_framework/views.py", line 469, in handle_exception
    self.raise_uncaught_exception(exc)
  File "/home/tech/DataIssueTracker/env/lib/python3.10/site-packages/rest_framework/views.py", line 480, in raise_uncaught_exception
    raise exc
  File "/home/tech/DataIssueTracker/env/lib/python3.10/site-packages/rest_framework/views.py", line 506, in dispatch
    response = handler(request, *args, **kwargs)
  File "/home/tech/DataIssueTracker/DITApi/DQITAuth/views.py", line 312, in get
    result_page = paginator.paginate_queryset(logs, request)
  File "/home/tech/DataIssueTracker/env/lib/python3.10/site-packages/rest_framework/pagination.py", line 387, in paginate_queryset
    self.count = self.get_count(queryset)
  File "/home/tech/DataIssueTracker/env/lib/python3.10/site-packages/rest_framework/pagination.py", line 525, in get_count
    return queryset.count()
  File "/home/tech/DataIssueTracker/env/lib/python3.10/site-packages/django/db/models/query.py", line 608, in count
    return self.query.get_count(using=self.db)
  File "/home/tech/DataIssueTracker/env/lib/python3.10/site-packages/django/db/models/sql/query.py", line 568, in get_count
    return obj.get_aggregation(using, {"__count": Count("*")})["__count"]
  File "/home/tech/DataIssueTracker/env/lib/python3.10/site-packages/django/db/models/sql/query.py", line 554, in get_aggregation
    result = compiler.execute_sql(SINGLE)
  File "/home/tech/DataIssueTracker/env/lib/python3.10/site-packages/django/db/models/sql/compiler.py", line 1562, in execute_sql
    cursor.execute(sql, params)
  File "/home/tech/DataIssueTracker/env/lib/python3.10/site-packages/django/db/backends/utils.py", line 102, in execute
    return super().execute(sql, params)
  File "/home/tech/DataIssueTracker/env/lib/python3.10/site-packages/django/db/backends/utils.py", line 67, in execute
    return self._execute_with_wrappers(
  File "/home/tech/DataIssueTracker/env/lib/python3.10/site-packages/django/db/backends/utils.py", line 80, in _execute_with_wrappers
    return executor(sql, params, many, context)
  File "/home/tech/DataIssueTracker/env/lib/python3.10/site-packages/django/db/backends/utils.py", line 84, in _execute
    with self.db.wrap_database_errors:
  File "/home/tech/DataIssueTracker/env/lib/python3.10/site-packages/django/db/utils.py", line 91, in __exit__
    raise dj_exc_value.with_traceback(traceback) from exc_value
  File "/home/tech/DataIssueTracker/env/lib/python3.10/site-packages/django/db/backends/utils.py", line 89, in _execute
    return self.cursor.execute(sql, params)
  File "/home/tech/DataIssueTracker/env/lib/python3.10/site-packages/django/db/backends/mysql/base.py", line 75, in execute
    return self.cursor.execute(query, args)
  File "/home/tech/DataIssueTracker/env/lib/python3.10/site-packages/MySQLdb/cursors.py", line 179, in execute
    res = self._query(mogrified_query)
  File "/home/tech/DataIssueTracker/env/lib/python3.10/site-packages/MySQLdb/cursors.py", line 330, in _query
    db.query(q)
  File "/home/tech/DataIssueTracker/env/lib/python3.10/site-packages/MySQLdb/connections.py", line 255, in query
    _mysql.connection.query(self, query)
django.db.utils.ProgrammingError: (1146, "Table 'dqits.DQITAuth_userlog' doesn't exist")
Internal Server Error: /api/user-logs/
Traceback (most recent call last):
  File "/home/tech/DataIssueTracker/env/lib/python3.10/site-packages/django/db/backends/utils.py", line 89, in _execute
    return self.cursor.execute(sql, params)
  File "/home/tech/DataIssueTracker/env/lib/python3.10/site-packages/django/db/backends/mysql/base.py", line 75, in execute
    return self.cursor.execute(query, args)
  File "/home/tech/DataIssueTracker/env/lib/python3.10/site-packages/MySQLdb/cursors.py", line 179, in execute
    res = self._query(mogrified_query)
  File "/home/tech/DataIssueTracker/env/lib/python3.10/site-packages/MySQLdb/cursors.py", line 330, in _query
    db.query(q)
  File "/home/tech/DataIssueTracker/env/lib/python3.10/site-packages/MySQLdb/connections.py", line 255, in query
    _mysql.connection.query(self, query)
MySQLdb.ProgrammingError: (1146, "Table 'dqits.DQITAuth_userlog' doesn't exist")

The above exception was the direct cause of the following exception:

Traceback (most recent call last):
  File "/home/tech/DataIssueTracker/env/lib/python3.10/site-packages/django/core/handlers/exception.py", line 55, in inner
    response = get_response(request)
  File "/home/tech/DataIssueTracker/env/lib/python3.10/site-packages/django/core/handlers/base.py", line 197, in _get_response
    response = wrapped_callback(request, *callback_args, **callback_kwargs)
  File "/home/tech/DataIssueTracker/env/lib/python3.10/site-packages/django/views/decorators/csrf.py", line 56, in wrapper_view
    return view_func(*args, **kwargs)
  File "/home/tech/DataIssueTracker/env/lib/python3.10/site-packages/django/views/generic/base.py", line 104, in view
    return self.dispatch(request, *args, **kwargs)
  File "/home/tech/DataIssueTracker/env/lib/python3.10/site-packages/rest_framework/views.py", line 509, in dispatch
    response = self.handle_exception(exc)
  File "/home/tech/DataIssueTracker/env/lib/python3.10/site-packages/rest_framework/views.py", line 469, in handle_exception
    self.raise_uncaught_exception(exc)
  File "/home/tech/DataIssueTracker/env/lib/python3.10/site-packages/rest_framework/views.py", line 480, in raise_uncaught_exception
    raise exc
  File "/home/tech/DataIssueTracker/env/lib/python3.10/site-packages/rest_framework/views.py", line 506, in dispatch
    response = handler(request, *args, **kwargs)
  File "/home/tech/DataIssueTracker/DITApi/DQITAuth/views.py", line 312, in get
    result_page = paginator.paginate_queryset(logs, request)
  File "/home/tech/DataIssueTracker/env/lib/python3.10/site-packages/rest_framework/pagination.py", line 387, in paginate_queryset
    self.count = self.get_count(queryset)
  File "/home/tech/DataIssueTracker/env/lib/python3.10/site-packages/rest_framework/pagination.py", line 525, in get_count
    return queryset.count()
  File "/home/tech/DataIssueTracker/env/lib/python3.10/site-packages/django/db/models/query.py", line 608, in count
    return self.query.get_count(using=self.db)
  File "/home/tech/DataIssueTracker/env/lib/python3.10/site-packages/django/db/models/sql/query.py", line 568, in get_count
    return obj.get_aggregation(using, {"__count": Count("*")})["__count"]
  File "/home/tech/DataIssueTracker/env/lib/python3.10/site-packages/django/db/models/sql/query.py", line 554, in get_aggregation
    result = compiler.execute_sql(SINGLE)
  File "/home/tech/DataIssueTracker/env/lib/python3.10/site-packages/django/db/models/sql/compiler.py", line 1562, in execute_sql
    cursor.execute(sql, params)
  File "/home/tech/DataIssueTracker/env/lib/python3.10/site-packages/django/db/backends/utils.py", line 102, in execute
    return super().execute(sql, params)
  File "/home/tech/DataIssueTracker/env/lib/python3.10/site-packages/django/db/backends/utils.py", line 67, in execute
    return self._execute_with_wrappers(
  File "/home/tech/DataIssueTracker/env/lib/python3.10/site-packages/django/db/backends/utils.py", line 80, in _execute_with_wrappers
    return executor(sql, params, many, context)
  File "/home/tech/DataIssueTracker/env/lib/python3.10/site-packages/django/db/backends/utils.py", line 84, in _execute
    with self.db.wrap_database_errors:
  File "/home/tech/DataIssueTracker/env/lib/python3.10/site-packages/django/db/utils.py", line 91, in __exit__
    raise dj_exc_value.with_traceback(traceback) from exc_value
  File "/home/tech/DataIssueTracker/env/lib/python3.10/site-packages/django/db/backends/utils.py", line 89, in _execute
    return self.cursor.execute(sql, params)
  File "/home/tech/DataIssueTracker/env/lib/python3.10/site-packages/django/db/backends/mysql/base.py", line 75, in execute
    return self.cursor.execute(query, args)
  File "/home/tech/DataIssueTracker/env/lib/python3.10/site-packages/MySQLdb/cursors.py", line 179, in execute
    res = self._query(mogrified_query)
  File "/home/tech/DataIssueTracker/env/lib/python3.10/site-packages/MySQLdb/cursors.py", line 330, in _query
    db.query(q)
  File "/home/tech/DataIssueTracker/env/lib/python3.10/site-packages/MySQLdb/connections.py", line 255, in query
    _mysql.connection.query(self, query)
django.db.utils.ProgrammingError: (1146, "Table 'dqits.DQITAuth_userlog' doesn't exist")
Couldnt reverse DQIT_Endpoint
avatar field must be an ImageField/URLField on the user model, or a callable
Data sync active...
Adding job tentatively -- it will be properly scheduled when the scheduler starts
Added job "Command.handle" to job store "default"
Scheduler started
Looking for jobs to run
Next wakeup is due at 2023-10-29 20:00:36.441188+03:00 (in 3599.994321 seconds)
Successfully imported extension module "markdown.extensions.toc".
Successfully loaded extension "markdown.extensions.toc.TocExtension".
Method Not Allowed: /api/sync_data/
Couldnt reverse DQIT_Endpoint
avatar field must be an ImageField/URLField on the user model, or a callable
Couldnt reverse DQIT_Endpoint
Adding job tentatively -- it will be properly scheduled when the scheduler starts
Added job "Command.handle" to job store "default"
Scheduler started
Looking for jobs to run
Next wakeup is due at 2023-10-29 20:23:12.103429+03:00 (in 3599.987419 seconds)
Couldnt reverse DQIT_Endpoint
avatar field must be an ImageField/URLField on the user model, or a callable
Couldnt reverse DQIT_Endpoint
Successfully imported extension module "markdown.extensions.toc".
Successfully loaded extension "markdown.extensions.toc.TocExtension".
Method Not Allowed: /api/sync_data/
Couldnt reverse DQIT_Endpoint
avatar field must be an ImageField/URLField on the user model, or a callable
Couldnt reverse DQIT_Endpoint
Couldnt reverse DQIT_Endpoint
avatar field must be an ImageField/URLField on the user model, or a callable
Adding job tentatively -- it will be properly scheduled when the scheduler starts
Added job "Command.handle" to job store "default"
Scheduler started
Looking for jobs to run
Next wakeup is due at 2023-10-29 20:34:04.332514+03:00 (in 3599.993658 seconds)
Successfully imported extension module "markdown.extensions.toc".
Successfully loaded extension "markdown.extensions.toc.TocExtension".
Method Not Allowed: /api/sync_data/
Couldnt reverse DQIT_Endpoint
avatar field must be an ImageField/URLField on the user model, or a callable
Couldnt reverse DQIT_Endpoint
avatar field must be an ImageField/URLField on the user model, or a callable
Couldnt reverse DQIT_Endpoint
avatar field must be an ImageField/URLField on the user model, or a callable
STREAM b'IHDR' 16 13
STREAM b'sRGB' 41 1
STREAM b'gAMA' 54 4
STREAM b'pHYs' 70 9
STREAM b'IDAT' 91 23120
Importing BlpImagePlugin
Importing BmpImagePlugin
Importing BufrStubImagePlugin
Importing CurImagePlugin
Importing DcxImagePlugin
Importing DdsImagePlugin
Importing EpsImagePlugin
Importing FitsImagePlugin
Importing FliImagePlugin
Importing FpxImagePlugin
Image: failed to import FpxImagePlugin: No module named 'olefile'
Importing FtexImagePlugin
Importing GbrImagePlugin
Importing GifImagePlugin
Importing GribStubImagePlugin
Importing Hdf5StubImagePlugin
Importing IcnsImagePlugin
Importing IcoImagePlugin
Importing ImImagePlugin
Importing ImtImagePlugin
Importing IptcImagePlugin
Importing JpegImagePlugin
Importing Jpeg2KImagePlugin
Importing McIdasImagePlugin
Importing MicImagePlugin
Image: failed to import MicImagePlugin: No module named 'olefile'
Importing MpegImagePlugin
Importing MpoImagePlugin
Importing MspImagePlugin
Importing PalmImagePlugin
Importing PcdImagePlugin
Importing PcxImagePlugin
Importing PdfImagePlugin
Importing PixarImagePlugin
Importing PngImagePlugin
Importing PpmImagePlugin
Importing PsdImagePlugin
Importing QoiImagePlugin
Importing SgiImagePlugin
Importing SpiderImagePlugin
Importing SunImagePlugin
Importing TgaImagePlugin
Importing TiffImagePlugin
Importing WebPImagePlugin
Importing WmfImagePlugin
Importing XbmImagePlugin
Importing XpmImagePlugin
Importing XVThumbImagePlugin
Couldnt reverse DQIT_Endpoint
avatar field must be an ImageField/URLField on the user model, or a callable
Couldnt reverse DQIT_Endpoint
avatar field must be an ImageField/URLField on the user model, or a callable
Couldnt reverse DQIT_Endpoint
avatar field must be an ImageField/URLField on the user model, or a callable
Couldnt reverse DQIT_Endpoint
avatar field must be an ImageField/URLField on the user model, or a callable
Adding job tentatively -- it will be properly scheduled when the scheduler starts
Added job "Command.handle" to job store "default"
Scheduler started
Looking for jobs to run
Next wakeup is due at 2023-10-29 20:41:27.521669+03:00 (in 3599.994377 seconds)
Processing login mail
Email thread started!
Unauthorized: /api/analytics/
Unauthorized: /api/data_issue_stats/
Unauthorized: /api/data_issues/
Unauthorized: /api/user-logs/
Unauthorized: /api/facilities/
Processing login mail
Email thread started!
Unauthorized: /api/analytics/
Unauthorized: /api/data_issues/
Unauthorized: /api/data_issue_stats/
Unauthorized: /api/user-logs/
Unauthorized: /api/facilities/
Processing login mail
Email thread started!
Unauthorized: /api/analytics/
Unauthorized: /api/data_issue_stats/
Unauthorized: /api/data_issues/
Unauthorized: /api/facilities/
Unauthorized: /api/user-logs/
Unauthorized: /api/facilities/
Unauthorized: /api/data_issues/
Unauthorized: /api/analytics/
Unauthorized: /api/data_issues/
Unauthorized: /api/data_issue_stats/
Unauthorized: /api/facilities/
Unauthorized: /api/user-logs/
Processing login mail
Email thread started!
Internal Server Error: /api/user-logs/
Traceback (most recent call last):
  File "/home/tech/DataIssueTracker/env/lib/python3.10/site-packages/django/db/backends/utils.py", line 89, in _execute
    return self.cursor.execute(sql, params)
  File "/home/tech/DataIssueTracker/env/lib/python3.10/site-packages/django/db/backends/mysql/base.py", line 75, in execute
    return self.cursor.execute(query, args)
  File "/home/tech/DataIssueTracker/env/lib/python3.10/site-packages/MySQLdb/cursors.py", line 179, in execute
    res = self._query(mogrified_query)
  File "/home/tech/DataIssueTracker/env/lib/python3.10/site-packages/MySQLdb/cursors.py", line 330, in _query
    db.query(q)
  File "/home/tech/DataIssueTracker/env/lib/python3.10/site-packages/MySQLdb/connections.py", line 255, in query
    _mysql.connection.query(self, query)
MySQLdb.ProgrammingError: (1146, "Table 'dqits.DQITAuth_userlog' doesn't exist")

The above exception was the direct cause of the following exception:

Traceback (most recent call last):
  File "/home/tech/DataIssueTracker/env/lib/python3.10/site-packages/django/core/handlers/exception.py", line 55, in inner
    response = get_response(request)
  File "/home/tech/DataIssueTracker/env/lib/python3.10/site-packages/django/core/handlers/base.py", line 197, in _get_response
    response = wrapped_callback(request, *callback_args, **callback_kwargs)
  File "/home/tech/DataIssueTracker/env/lib/python3.10/site-packages/django/views/decorators/csrf.py", line 56, in wrapper_view
    return view_func(*args, **kwargs)
  File "/home/tech/DataIssueTracker/env/lib/python3.10/site-packages/django/views/generic/base.py", line 104, in view
    return self.dispatch(request, *args, **kwargs)
  File "/home/tech/DataIssueTracker/env/lib/python3.10/site-packages/rest_framework/views.py", line 509, in dispatch
    response = self.handle_exception(exc)
  File "/home/tech/DataIssueTracker/env/lib/python3.10/site-packages/rest_framework/views.py", line 469, in handle_exception
    self.raise_uncaught_exception(exc)
  File "/home/tech/DataIssueTracker/env/lib/python3.10/site-packages/rest_framework/views.py", line 480, in raise_uncaught_exception
    raise exc
  File "/home/tech/DataIssueTracker/env/lib/python3.10/site-packages/rest_framework/views.py", line 506, in dispatch
    response = handler(request, *args, **kwargs)
  File "/home/tech/DataIssueTracker/DITApi/DQITAuth/views.py", line 312, in get
    result_page = paginator.paginate_queryset(logs, request)
  File "/home/tech/DataIssueTracker/env/lib/python3.10/site-packages/rest_framework/pagination.py", line 387, in paginate_queryset
    self.count = self.get_count(queryset)
  File "/home/tech/DataIssueTracker/env/lib/python3.10/site-packages/rest_framework/pagination.py", line 525, in get_count
    return queryset.count()
  File "/home/tech/DataIssueTracker/env/lib/python3.10/site-packages/django/db/models/query.py", line 608, in count
    return self.query.get_count(using=self.db)
  File "/home/tech/DataIssueTracker/env/lib/python3.10/site-packages/django/db/models/sql/query.py", line 568, in get_count
    return obj.get_aggregation(using, {"__count": Count("*")})["__count"]
  File "/home/tech/DataIssueTracker/env/lib/python3.10/site-packages/django/db/models/sql/query.py", line 554, in get_aggregation
    result = compiler.execute_sql(SINGLE)
  File "/home/tech/DataIssueTracker/env/lib/python3.10/site-packages/django/db/models/sql/compiler.py", line 1562, in execute_sql
    cursor.execute(sql, params)
  File "/home/tech/DataIssueTracker/env/lib/python3.10/site-packages/django/db/backends/utils.py", line 102, in execute
    return super().execute(sql, params)
  File "/home/tech/DataIssueTracker/env/lib/python3.10/site-packages/django/db/backends/utils.py", line 67, in execute
    return self._execute_with_wrappers(
  File "/home/tech/DataIssueTracker/env/lib/python3.10/site-packages/django/db/backends/utils.py", line 80, in _execute_with_wrappers
    return executor(sql, params, many, context)
  File "/home/tech/DataIssueTracker/env/lib/python3.10/site-packages/django/db/backends/utils.py", line 84, in _execute
    with self.db.wrap_database_errors:
  File "/home/tech/DataIssueTracker/env/lib/python3.10/site-packages/django/db/utils.py", line 91, in __exit__
    raise dj_exc_value.with_traceback(traceback) from exc_value
  File "/home/tech/DataIssueTracker/env/lib/python3.10/site-packages/django/db/backends/utils.py", line 89, in _execute
    return self.cursor.execute(sql, params)
  File "/home/tech/DataIssueTracker/env/lib/python3.10/site-packages/django/db/backends/mysql/base.py", line 75, in execute
    return self.cursor.execute(query, args)
  File "/home/tech/DataIssueTracker/env/lib/python3.10/site-packages/MySQLdb/cursors.py", line 179, in execute
    res = self._query(mogrified_query)
  File "/home/tech/DataIssueTracker/env/lib/python3.10/site-packages/MySQLdb/cursors.py", line 330, in _query
    db.query(q)
  File "/home/tech/DataIssueTracker/env/lib/python3.10/site-packages/MySQLdb/connections.py", line 255, in query
    _mysql.connection.query(self, query)
django.db.utils.ProgrammingError: (1146, "Table 'dqits.DQITAuth_userlog' doesn't exist")
Processing login mail
Email thread started!
Internal Server Error: /api/user-logs/
Traceback (most recent call last):
  File "/home/tech/DataIssueTracker/env/lib/python3.10/site-packages/django/db/backends/utils.py", line 89, in _execute
    return self.cursor.execute(sql, params)
  File "/home/tech/DataIssueTracker/env/lib/python3.10/site-packages/django/db/backends/mysql/base.py", line 75, in execute
    return self.cursor.execute(query, args)
  File "/home/tech/DataIssueTracker/env/lib/python3.10/site-packages/MySQLdb/cursors.py", line 179, in execute
    res = self._query(mogrified_query)
  File "/home/tech/DataIssueTracker/env/lib/python3.10/site-packages/MySQLdb/cursors.py", line 330, in _query
    db.query(q)
  File "/home/tech/DataIssueTracker/env/lib/python3.10/site-packages/MySQLdb/connections.py", line 255, in query
    _mysql.connection.query(self, query)
MySQLdb.ProgrammingError: (1146, "Table 'dqits.DQITAuth_userlog' doesn't exist")

The above exception was the direct cause of the following exception:

Traceback (most recent call last):
  File "/home/tech/DataIssueTracker/env/lib/python3.10/site-packages/django/core/handlers/exception.py", line 55, in inner
    response = get_response(request)
  File "/home/tech/DataIssueTracker/env/lib/python3.10/site-packages/django/core/handlers/base.py", line 197, in _get_response
    response = wrapped_callback(request, *callback_args, **callback_kwargs)
  File "/home/tech/DataIssueTracker/env/lib/python3.10/site-packages/django/views/decorators/csrf.py", line 56, in wrapper_view
    return view_func(*args, **kwargs)
  File "/home/tech/DataIssueTracker/env/lib/python3.10/site-packages/django/views/generic/base.py", line 104, in view
    return self.dispatch(request, *args, **kwargs)
  File "/home/tech/DataIssueTracker/env/lib/python3.10/site-packages/rest_framework/views.py", line 509, in dispatch
    response = self.handle_exception(exc)
  File "/home/tech/DataIssueTracker/env/lib/python3.10/site-packages/rest_framework/views.py", line 469, in handle_exception
    self.raise_uncaught_exception(exc)
  File "/home/tech/DataIssueTracker/env/lib/python3.10/site-packages/rest_framework/views.py", line 480, in raise_uncaught_exception
    raise exc
  File "/home/tech/DataIssueTracker/env/lib/python3.10/site-packages/rest_framework/views.py", line 506, in dispatch
    response = handler(request, *args, **kwargs)
  File "/home/tech/DataIssueTracker/DITApi/DQITAuth/views.py", line 312, in get
    result_page = paginator.paginate_queryset(logs, request)
  File "/home/tech/DataIssueTracker/env/lib/python3.10/site-packages/rest_framework/pagination.py", line 387, in paginate_queryset
    self.count = self.get_count(queryset)
  File "/home/tech/DataIssueTracker/env/lib/python3.10/site-packages/rest_framework/pagination.py", line 525, in get_count
    return queryset.count()
  File "/home/tech/DataIssueTracker/env/lib/python3.10/site-packages/django/db/models/query.py", line 608, in count
    return self.query.get_count(using=self.db)
  File "/home/tech/DataIssueTracker/env/lib/python3.10/site-packages/django/db/models/sql/query.py", line 568, in get_count
    return obj.get_aggregation(using, {"__count": Count("*")})["__count"]
  File "/home/tech/DataIssueTracker/env/lib/python3.10/site-packages/django/db/models/sql/query.py", line 554, in get_aggregation
    result = compiler.execute_sql(SINGLE)
  File "/home/tech/DataIssueTracker/env/lib/python3.10/site-packages/django/db/models/sql/compiler.py", line 1562, in execute_sql
    cursor.execute(sql, params)
  File "/home/tech/DataIssueTracker/env/lib/python3.10/site-packages/django/db/backends/utils.py", line 102, in execute
    return super().execute(sql, params)
  File "/home/tech/DataIssueTracker/env/lib/python3.10/site-packages/django/db/backends/utils.py", line 67, in execute
    return self._execute_with_wrappers(
  File "/home/tech/DataIssueTracker/env/lib/python3.10/site-packages/django/db/backends/utils.py", line 80, in _execute_with_wrappers
    return executor(sql, params, many, context)
  File "/home/tech/DataIssueTracker/env/lib/python3.10/site-packages/django/db/backends/utils.py", line 84, in _execute
    with self.db.wrap_database_errors:
  File "/home/tech/DataIssueTracker/env/lib/python3.10/site-packages/django/db/utils.py", line 91, in __exit__
    raise dj_exc_value.with_traceback(traceback) from exc_value
  File "/home/tech/DataIssueTracker/env/lib/python3.10/site-packages/django/db/backends/utils.py", line 89, in _execute
    return self.cursor.execute(sql, params)
  File "/home/tech/DataIssueTracker/env/lib/python3.10/site-packages/django/db/backends/mysql/base.py", line 75, in execute
    return self.cursor.execute(query, args)
  File "/home/tech/DataIssueTracker/env/lib/python3.10/site-packages/MySQLdb/cursors.py", line 179, in execute
    res = self._query(mogrified_query)
  File "/home/tech/DataIssueTracker/env/lib/python3.10/site-packages/MySQLdb/cursors.py", line 330, in _query
    db.query(q)
  File "/home/tech/DataIssueTracker/env/lib/python3.10/site-packages/MySQLdb/connections.py", line 255, in query
    _mysql.connection.query(self, query)
django.db.utils.ProgrammingError: (1146, "Table 'dqits.DQITAuth_userlog' doesn't exist")
Adding job tentatively -- it will be properly scheduled when the scheduler starts
Added job "Command.handle" to job store "default"
Scheduler started
Looking for jobs to run
Next wakeup is due at 2023-10-29 20:48:49.564037+03:00 (in 3599.989857 seconds)
Processing login mail
Email thread started!
Not Found: /api/null
Not Found: /api/null
Not Found: /api/null
Processing login mail
Email thread started!
Not Found: /api//media/profiles/logo.png
Not Found: /api//media/profiles/logo.png
Not Found: /api/media/profiles/logo.png
Processing login mail
Email thread started!
