[2023-10-29 14:32:01 +0000] [107971] [INFO] Starting gunicorn 21.2.0
[2023-10-29 14:32:01 +0000] [107971] [INFO] Listening at: http://0.0.0.0:8000 (107971)
[2023-10-29 14:32:01 +0000] [107971] [INFO] Using worker: sync
[2023-10-29 14:32:01 +0000] [107972] [INFO] Booting worker with pid: 107972
[2023-10-29 14:32:06 +0000] [107971] [INFO] Handling signal: int
[2023-10-29 14:32:06 +0000] [107971] [INFO] Shutting down: Master
[2023-10-29 14:32:36 +0000] [107976] [INFO] Starting gunicorn 21.2.0
[2023-10-29 14:32:36 +0000] [107976] [INFO] Listening at: http://0.0.0.0:8000 (107976)
[2023-10-29 14:32:36 +0000] [107976] [INFO] Using worker: sync
[2023-10-29 14:32:36 +0000] [107977] [INFO] Booting worker with pid: 107977
[2023-10-29 17:33:36 +0300] [107977] [ERROR] Error handling request /admin/DQITAuth/customuser/1/change/
Traceback (most recent call last):
  File "/home/tech/DataIssueTracker/env/lib/python3.10/site-packages/django/core/handlers/exception.py", line 55, in inner
    response = get_response(request)
  File "/home/tech/DataIssueTracker/env/lib/python3.10/site-packages/django/core/handlers/base.py", line 181, in _get_response
    callback, callback_args, callback_kwargs = self.resolve_request(request)
  File "/home/tech/DataIssueTracker/env/lib/python3.10/site-packages/django/core/handlers/base.py", line 313, in resolve_request
    resolver_match = resolver.resolve(request.path_info)
  File "/home/tech/DataIssueTracker/env/lib/python3.10/site-packages/django/urls/resolvers.py", line 663, in resolve
    for pattern in self.url_patterns:
  File "/home/tech/DataIssueTracker/env/lib/python3.10/site-packages/django/utils/functional.py", line 57, in __get__
    res = instance.__dict__[self.name] = self.func(instance)
  File "/home/tech/DataIssueTracker/env/lib/python3.10/site-packages/django/urls/resolvers.py", line 715, in url_patterns
    patterns = getattr(self.urlconf_module, "urlpatterns", self.urlconf_module)
  File "/home/tech/DataIssueTracker/env/lib/python3.10/site-packages/django/utils/functional.py", line 57, in __get__
    res = instance.__dict__[self.name] = self.func(instance)
  File "/home/tech/DataIssueTracker/env/lib/python3.10/site-packages/django/urls/resolvers.py", line 708, in urlconf_module
    return import_module(self.urlconf_name)
  File "/usr/lib/python3.10/importlib/__init__.py", line 126, in import_module
    return _bootstrap._gcd_import(name[level:], package, level)
  File "<frozen importlib._bootstrap>", line 1050, in _gcd_import
  File "<frozen importlib._bootstrap>", line 1027, in _find_and_load
  File "<frozen importlib._bootstrap>", line 1006, in _find_and_load_unlocked
  File "<frozen importlib._bootstrap>", line 688, in _load_unlocked
  File "<frozen importlib._bootstrap_external>", line 883, in exec_module
  File "<frozen importlib._bootstrap>", line 241, in _call_with_frames_removed
  File "/home/tech/DataIssueTracker/DITApi/DITApi/urls.py", line 27, in <module>
    path('api/',include('DQITAuth.urls')),
  File "/home/tech/DataIssueTracker/env/lib/python3.10/site-packages/django/urls/conf.py", line 38, in include
    urlconf_module = import_module(urlconf_module)
  File "/usr/lib/python3.10/importlib/__init__.py", line 126, in import_module
    return _bootstrap._gcd_import(name[level:], package, level)
  File "<frozen importlib._bootstrap>", line 1050, in _gcd_import
  File "<frozen importlib._bootstrap>", line 1027, in _find_and_load
  File "<frozen importlib._bootstrap>", line 1006, in _find_and_load_unlocked
  File "<frozen importlib._bootstrap>", line 688, in _load_unlocked
  File "<frozen importlib._bootstrap_external>", line 883, in exec_module
  File "<frozen importlib._bootstrap>", line 241, in _call_with_frames_removed
  File "/home/tech/DataIssueTracker/DITApi/DQITAuth/urls.py", line 3, in <module>
    from .views import (
  File "/home/tech/DataIssueTracker/DITApi/DQITAuth/views.py", line 88
    role = user.role.role_name if user.role else None
IndentationError: expected an indented block after 'except' statement on line 84

During handling of the above exception, another exception occurred:

Traceback (most recent call last):
  File "/home/tech/DataIssueTracker/env/lib/python3.10/site-packages/django/core/handlers/exception.py", line 55, in inner
    response = get_response(request)
  File "/home/tech/DataIssueTracker/DITApi/DQITAuth/middleware.py", line 14, in __call__
    response = self.get_response(request)
  File "/home/tech/DataIssueTracker/env/lib/python3.10/site-packages/django/core/handlers/exception.py", line 57, in inner
    response = response_for_exception(request, exc)
  File "/home/tech/DataIssueTracker/env/lib/python3.10/site-packages/django/core/handlers/exception.py", line 140, in response_for_exception
    response = handle_uncaught_exception(
  File "/home/tech/DataIssueTracker/env/lib/python3.10/site-packages/django/core/handlers/exception.py", line 181, in handle_uncaught_exception
    return debug.technical_500_response(request, *exc_info)
  File "/home/tech/DataIssueTracker/env/lib/python3.10/site-packages/django/views/debug.py", line 67, in technical_500_response
    html = reporter.get_traceback_html()
  File "/home/tech/DataIssueTracker/env/lib/python3.10/site-packages/django/views/debug.py", line 410, in get_traceback_html
    c = Context(self.get_traceback_data(), use_l10n=False)
  File "/home/tech/DataIssueTracker/env/lib/python3.10/site-packages/django/views/debug.py", line 393, in get_traceback_data
    c["raising_view_name"] = get_caller(self.request)
  File "/home/tech/DataIssueTracker/env/lib/python3.10/site-packages/django/views/debug.py", line 100, in get_caller
    resolver_match = resolve(request.path)
  File "/home/tech/DataIssueTracker/env/lib/python3.10/site-packages/django/urls/base.py", line 24, in resolve
    return get_resolver(urlconf).resolve(path)
  File "/home/tech/DataIssueTracker/env/lib/python3.10/site-packages/django/urls/resolvers.py", line 663, in resolve
    for pattern in self.url_patterns:
  File "/home/tech/DataIssueTracker/env/lib/python3.10/site-packages/django/utils/functional.py", line 57, in __get__
    res = instance.__dict__[self.name] = self.func(instance)
  File "/home/tech/DataIssueTracker/env/lib/python3.10/site-packages/django/urls/resolvers.py", line 715, in url_patterns
    patterns = getattr(self.urlconf_module, "urlpatterns", self.urlconf_module)
  File "/home/tech/DataIssueTracker/env/lib/python3.10/site-packages/django/utils/functional.py", line 57, in __get__
    res = instance.__dict__[self.name] = self.func(instance)
  File "/home/tech/DataIssueTracker/env/lib/python3.10/site-packages/django/urls/resolvers.py", line 708, in urlconf_module
    return import_module(self.urlconf_name)
  File "/usr/lib/python3.10/importlib/__init__.py", line 126, in import_module
    return _bootstrap._gcd_import(name[level:], package, level)
  File "<frozen importlib._bootstrap>", line 1050, in _gcd_import
  File "<frozen importlib._bootstrap>", line 1027, in _find_and_load
  File "<frozen importlib._bootstrap>", line 1006, in _find_and_load_unlocked
  File "<frozen importlib._bootstrap>", line 688, in _load_unlocked
  File "<frozen importlib._bootstrap_external>", line 883, in exec_module
  File "<frozen importlib._bootstrap>", line 241, in _call_with_frames_removed
  File "/home/tech/DataIssueTracker/DITApi/DITApi/urls.py", line 27, in <module>
    path('api/',include('DQITAuth.urls')),
  File "/home/tech/DataIssueTracker/env/lib/python3.10/site-packages/django/urls/conf.py", line 38, in include
    urlconf_module = import_module(urlconf_module)
  File "/usr/lib/python3.10/importlib/__init__.py", line 126, in import_module
    return _bootstrap._gcd_import(name[level:], package, level)
  File "<frozen importlib._bootstrap>", line 1050, in _gcd_import
  File "<frozen importlib._bootstrap>", line 1027, in _find_and_load
  File "<frozen importlib._bootstrap>", line 1006, in _find_and_load_unlocked
  File "<frozen importlib._bootstrap>", line 688, in _load_unlocked
  File "<frozen importlib._bootstrap_external>", line 883, in exec_module
  File "<frozen importlib._bootstrap>", line 241, in _call_with_frames_removed
  File "/home/tech/DataIssueTracker/DITApi/DQITAuth/urls.py", line 3, in <module>
    from .views import (
  File "/home/tech/DataIssueTracker/DITApi/DQITAuth/views.py", line 88
    role = user.role.role_name if user.role else None
IndentationError: expected an indented block after 'except' statement on line 84

During handling of the above exception, another exception occurred:

Traceback (most recent call last):
  File "/home/tech/DataIssueTracker/env/lib/python3.10/site-packages/django/core/handlers/exception.py", line 55, in inner
    response = get_response(request)
  File "/home/tech/DataIssueTracker/env/lib/python3.10/site-packages/django/utils/deprecation.py", line 134, in __call__
    response = response or self.get_response(request)
  File "/home/tech/DataIssueTracker/env/lib/python3.10/site-packages/django/core/handlers/exception.py", line 57, in inner
    response = response_for_exception(request, exc)
  File "/home/tech/DataIssueTracker/env/lib/python3.10/site-packages/django/core/handlers/exception.py", line 140, in response_for_exception
    response = handle_uncaught_exception(
  File "/home/tech/DataIssueTracker/env/lib/python3.10/site-packages/django/core/handlers/exception.py", line 181, in handle_uncaught_exception
    return debug.technical_500_response(request, *exc_info)
  File "/home/tech/DataIssueTracker/env/lib/python3.10/site-packages/django/views/debug.py", line 67, in technical_500_response
    html = reporter.get_traceback_html()
  File "/home/tech/DataIssueTracker/env/lib/python3.10/site-packages/django/views/debug.py", line 410, in get_traceback_html
    c = Context(self.get_traceback_data(), use_l10n=False)
  File "/home/tech/DataIssueTracker/env/lib/python3.10/site-packages/django/views/debug.py", line 393, in get_traceback_data
    c["raising_view_name"] = get_caller(self.request)
  File "/home/tech/DataIssueTracker/env/lib/python3.10/site-packages/django/views/debug.py", line 100, in get_caller
    resolver_match = resolve(request.path)
  File "/home/tech/DataIssueTracker/env/lib/python3.10/site-packages/django/urls/base.py", line 24, in resolve
    return get_resolver(urlconf).resolve(path)
  File "/home/tech/DataIssueTracker/env/lib/python3.10/site-packages/django/urls/resolvers.py", line 663, in resolve
    for pattern in self.url_patterns:
  File "/home/tech/DataIssueTracker/env/lib/python3.10/site-packages/django/utils/functional.py", line 57, in __get__
    res = instance.__dict__[self.name] = self.func(instance)
  File "/home/tech/DataIssueTracker/env/lib/python3.10/site-packages/django/urls/resolvers.py", line 715, in url_patterns
    patterns = getattr(self.urlconf_module, "urlpatterns", self.urlconf_module)
  File "/home/tech/DataIssueTracker/env/lib/python3.10/site-packages/django/utils/functional.py", line 57, in __get__
    res = instance.__dict__[self.name] = self.func(instance)
  File "/home/tech/DataIssueTracker/env/lib/python3.10/site-packages/django/urls/resolvers.py", line 708, in urlconf_module
    return import_module(self.urlconf_name)
  File "/usr/lib/python3.10/importlib/__init__.py", line 126, in import_module
    return _bootstrap._gcd_import(name[level:], package, level)
  File "<frozen importlib._bootstrap>", line 1050, in _gcd_import
  File "<frozen importlib._bootstrap>", line 1027, in _find_and_load
  File "<frozen importlib._bootstrap>", line 1006, in _find_and_load_unlocked
  File "<frozen importlib._bootstrap>", line 688, in _load_unlocked
  File "<frozen importlib._bootstrap_external>", line 883, in exec_module
  File "<frozen importlib._bootstrap>", line 241, in _call_with_frames_removed
  File "/home/tech/DataIssueTracker/DITApi/DITApi/urls.py", line 27, in <module>
    path('api/',include('DQITAuth.urls')),
  File "/home/tech/DataIssueTracker/env/lib/python3.10/site-packages/django/urls/conf.py", line 38, in include
    urlconf_module = import_module(urlconf_module)
  File "/usr/lib/python3.10/importlib/__init__.py", line 126, in import_module
    return _bootstrap._gcd_import(name[level:], package, level)
  File "<frozen importlib._bootstrap>", line 1050, in _gcd_import
  File "<frozen importlib._bootstrap>", line 1027, in _find_and_load
  File "<frozen importlib._bootstrap>", line 1006, in _find_and_load_unlocked
  File "<frozen importlib._bootstrap>", line 688, in _load_unlocked
  File "<frozen importlib._bootstrap_external>", line 883, in exec_module
  File "<frozen importlib._bootstrap>", line 241, in _call_with_frames_removed
  File "/home/tech/DataIssueTracker/DITApi/DQITAuth/urls.py", line 3, in <module>
    from .views import (
  File "/home/tech/DataIssueTracker/DITApi/DQITAuth/views.py", line 88
    role = user.role.role_name if user.role else None
IndentationError: expected an indented block after 'except' statement on line 84

During handling of the above exception, another exception occurred:

Traceback (most recent call last):
  File "/home/tech/DataIssueTracker/env/lib/python3.10/site-packages/django/core/handlers/exception.py", line 55, in inner
    response = get_response(request)
  File "/home/tech/DataIssueTracker/env/lib/python3.10/site-packages/django/utils/deprecation.py", line 134, in __call__
    response = response or self.get_response(request)
  File "/home/tech/DataIssueTracker/env/lib/python3.10/site-packages/django/core/handlers/exception.py", line 57, in inner
    response = response_for_exception(request, exc)
  File "/home/tech/DataIssueTracker/env/lib/python3.10/site-packages/django/core/handlers/exception.py", line 140, in response_for_exception
    response = handle_uncaught_exception(
  File "/home/tech/DataIssueTracker/env/lib/python3.10/site-packages/django/core/handlers/exception.py", line 181, in handle_uncaught_exception
    return debug.technical_500_response(request, *exc_info)
  File "/home/tech/DataIssueTracker/env/lib/python3.10/site-packages/django/views/debug.py", line 67, in technical_500_response
    html = reporter.get_traceback_html()
  File "/home/tech/DataIssueTracker/env/lib/python3.10/site-packages/django/views/debug.py", line 410, in get_traceback_html
    c = Context(self.get_traceback_data(), use_l10n=False)
  File "/home/tech/DataIssueTracker/env/lib/python3.10/site-packages/django/views/debug.py", line 393, in get_traceback_data
    c["raising_view_name"] = get_caller(self.request)
  File "/home/tech/DataIssueTracker/env/lib/python3.10/site-packages/django/views/debug.py", line 100, in get_caller
    resolver_match = resolve(request.path)
  File "/home/tech/DataIssueTracker/env/lib/python3.10/site-packages/django/urls/base.py", line 24, in resolve
    return get_resolver(urlconf).resolve(path)
  File "/home/tech/DataIssueTracker/env/lib/python3.10/site-packages/django/urls/resolvers.py", line 663, in resolve
    for pattern in self.url_patterns:
  File "/home/tech/DataIssueTracker/env/lib/python3.10/site-packages/django/utils/functional.py", line 57, in __get__
    res = instance.__dict__[self.name] = self.func(instance)
  File "/home/tech/DataIssueTracker/env/lib/python3.10/site-packages/django/urls/resolvers.py", line 715, in url_patterns
    patterns = getattr(self.urlconf_module, "urlpatterns", self.urlconf_module)
  File "/home/tech/DataIssueTracker/env/lib/python3.10/site-packages/django/utils/functional.py", line 57, in __get__
    res = instance.__dict__[self.name] = self.func(instance)
  File "/home/tech/DataIssueTracker/env/lib/python3.10/site-packages/django/urls/resolvers.py", line 708, in urlconf_module
    return import_module(self.urlconf_name)
  File "/usr/lib/python3.10/importlib/__init__.py", line 126, in import_module
    return _bootstrap._gcd_import(name[level:], package, level)
  File "<frozen importlib._bootstrap>", line 1050, in _gcd_import
  File "<frozen importlib._bootstrap>", line 1027, in _find_and_load
  File "<frozen importlib._bootstrap>", line 1006, in _find_and_load_unlocked
  File "<frozen importlib._bootstrap>", line 688, in _load_unlocked
  File "<frozen importlib._bootstrap_external>", line 883, in exec_module
  File "<frozen importlib._bootstrap>", line 241, in _call_with_frames_removed
  File "/home/tech/DataIssueTracker/DITApi/DITApi/urls.py", line 27, in <module>
    path('api/',include('DQITAuth.urls')),
  File "/home/tech/DataIssueTracker/env/lib/python3.10/site-packages/django/urls/conf.py", line 38, in include
    urlconf_module = import_module(urlconf_module)
  File "/usr/lib/python3.10/importlib/__init__.py", line 126, in import_module
    return _bootstrap._gcd_import(name[level:], package, level)
  File "<frozen importlib._bootstrap>", line 1050, in _gcd_import
  File "<frozen importlib._bootstrap>", line 1027, in _find_and_load
  File "<frozen importlib._bootstrap>", line 1006, in _find_and_load_unlocked
  File "<frozen importlib._bootstrap>", line 688, in _load_unlocked
  File "<frozen importlib._bootstrap_external>", line 883, in exec_module
  File "<frozen importlib._bootstrap>", line 241, in _call_with_frames_removed
  File "/home/tech/DataIssueTracker/DITApi/DQITAuth/urls.py", line 3, in <module>
    from .views import (
  File "/home/tech/DataIssueTracker/DITApi/DQITAuth/views.py", line 88
    role = user.role.role_name if user.role else None
IndentationError: expected an indented block after 'except' statement on line 84

During handling of the above exception, another exception occurred:

Traceback (most recent call last):
  File "/home/tech/DataIssueTracker/env/lib/python3.10/site-packages/django/core/handlers/exception.py", line 55, in inner
    response = get_response(request)
  File "/home/tech/DataIssueTracker/env/lib/python3.10/site-packages/django/utils/deprecation.py", line 134, in __call__
    response = response or self.get_response(request)
  File "/home/tech/DataIssueTracker/env/lib/python3.10/site-packages/django/core/handlers/exception.py", line 57, in inner
    response = response_for_exception(request, exc)
  File "/home/tech/DataIssueTracker/env/lib/python3.10/site-packages/django/core/handlers/exception.py", line 140, in response_for_exception
    response = handle_uncaught_exception(
  File "/home/tech/DataIssueTracker/env/lib/python3.10/site-packages/django/core/handlers/exception.py", line 181, in handle_uncaught_exception
    return debug.technical_500_response(request, *exc_info)
  File "/home/tech/DataIssueTracker/env/lib/python3.10/site-packages/django/views/debug.py", line 67, in technical_500_response
    html = reporter.get_traceback_html()
  File "/home/tech/DataIssueTracker/env/lib/python3.10/site-packages/django/views/debug.py", line 410, in get_traceback_html
    c = Context(self.get_traceback_data(), use_l10n=False)
  File "/home/tech/DataIssueTracker/env/lib/python3.10/site-packages/django/views/debug.py", line 393, in get_traceback_data
    c["raising_view_name"] = get_caller(self.request)
  File "/home/tech/DataIssueTracker/env/lib/python3.10/site-packages/django/views/debug.py", line 100, in get_caller
    resolver_match = resolve(request.path)
  File "/home/tech/DataIssueTracker/env/lib/python3.10/site-packages/django/urls/base.py", line 24, in resolve
    return get_resolver(urlconf).resolve(path)
  File "/home/tech/DataIssueTracker/env/lib/python3.10/site-packages/django/urls/resolvers.py", line 663, in resolve
    for pattern in self.url_patterns:
  File "/home/tech/DataIssueTracker/env/lib/python3.10/site-packages/django/utils/functional.py", line 57, in __get__
    res = instance.__dict__[self.name] = self.func(instance)
  File "/home/tech/DataIssueTracker/env/lib/python3.10/site-packages/django/urls/resolvers.py", line 715, in url_patterns
    patterns = getattr(self.urlconf_module, "urlpatterns", self.urlconf_module)
  File "/home/tech/DataIssueTracker/env/lib/python3.10/site-packages/django/utils/functional.py", line 57, in __get__
    res = instance.__dict__[self.name] = self.func(instance)
  File "/home/tech/DataIssueTracker/env/lib/python3.10/site-packages/django/urls/resolvers.py", line 708, in urlconf_module
    return import_module(self.urlconf_name)
  File "/usr/lib/python3.10/importlib/__init__.py", line 126, in import_module
    return _bootstrap._gcd_import(name[level:], package, level)
  File "<frozen importlib._bootstrap>", line 1050, in _gcd_import
  File "<frozen importlib._bootstrap>", line 1027, in _find_and_load
  File "<frozen importlib._bootstrap>", line 1006, in _find_and_load_unlocked
  File "<frozen importlib._bootstrap>", line 688, in _load_unlocked
  File "<frozen importlib._bootstrap_external>", line 883, in exec_module
  File "<frozen importlib._bootstrap>", line 241, in _call_with_frames_removed
  File "/home/tech/DataIssueTracker/DITApi/DITApi/urls.py", line 27, in <module>
    path('api/',include('DQITAuth.urls')),
  File "/home/tech/DataIssueTracker/env/lib/python3.10/site-packages/django/urls/conf.py", line 38, in include
    urlconf_module = import_module(urlconf_module)
  File "/usr/lib/python3.10/importlib/__init__.py", line 126, in import_module
    return _bootstrap._gcd_import(name[level:], package, level)
  File "<frozen importlib._bootstrap>", line 1050, in _gcd_import
  File "<frozen importlib._bootstrap>", line 1027, in _find_and_load
  File "<frozen importlib._bootstrap>", line 1006, in _find_and_load_unlocked
  File "<frozen importlib._bootstrap>", line 688, in _load_unlocked
  File "<frozen importlib._bootstrap_external>", line 883, in exec_module
  File "<frozen importlib._bootstrap>", line 241, in _call_with_frames_removed
  File "/home/tech/DataIssueTracker/DITApi/DQITAuth/urls.py", line 3, in <module>
    from .views import (
  File "/home/tech/DataIssueTracker/DITApi/DQITAuth/views.py", line 88
    role = user.role.role_name if user.role else None
IndentationError: expected an indented block after 'except' statement on line 84

During handling of the above exception, another exception occurred:

Traceback (most recent call last):
  File "/home/tech/DataIssueTracker/env/lib/python3.10/site-packages/django/core/handlers/exception.py", line 55, in inner
    response = get_response(request)
  File "/home/tech/DataIssueTracker/env/lib/python3.10/site-packages/django/utils/deprecation.py", line 134, in __call__
    response = response or self.get_response(request)
  File "/home/tech/DataIssueTracker/env/lib/python3.10/site-packages/django/core/handlers/exception.py", line 57, in inner
    response = response_for_exception(request, exc)
  File "/home/tech/DataIssueTracker/env/lib/python3.10/site-packages/django/core/handlers/exception.py", line 140, in response_for_exception
    response = handle_uncaught_exception(
  File "/home/tech/DataIssueTracker/env/lib/python3.10/site-packages/django/core/handlers/exception.py", line 181, in handle_uncaught_exception
    return debug.technical_500_response(request, *exc_info)
  File "/home/tech/DataIssueTracker/env/lib/python3.10/site-packages/django/views/debug.py", line 67, in technical_500_response
    html = reporter.get_traceback_html()
  File "/home/tech/DataIssueTracker/env/lib/python3.10/site-packages/django/views/debug.py", line 410, in get_traceback_html
    c = Context(self.get_traceback_data(), use_l10n=False)
  File "/home/tech/DataIssueTracker/env/lib/python3.10/site-packages/django/views/debug.py", line 393, in get_traceback_data
    c["raising_view_name"] = get_caller(self.request)
  File "/home/tech/DataIssueTracker/env/lib/python3.10/site-packages/django/views/debug.py", line 100, in get_caller
    resolver_match = resolve(request.path)
  File "/home/tech/DataIssueTracker/env/lib/python3.10/site-packages/django/urls/base.py", line 24, in resolve
    return get_resolver(urlconf).resolve(path)
  File "/home/tech/DataIssueTracker/env/lib/python3.10/site-packages/django/urls/resolvers.py", line 663, in resolve
    for pattern in self.url_patterns:
  File "/home/tech/DataIssueTracker/env/lib/python3.10/site-packages/django/utils/functional.py", line 57, in __get__
    res = instance.__dict__[self.name] = self.func(instance)
  File "/home/tech/DataIssueTracker/env/lib/python3.10/site-packages/django/urls/resolvers.py", line 715, in url_patterns
    patterns = getattr(self.urlconf_module, "urlpatterns", self.urlconf_module)
  File "/home/tech/DataIssueTracker/env/lib/python3.10/site-packages/django/utils/functional.py", line 57, in __get__
    res = instance.__dict__[self.name] = self.func(instance)
  File "/home/tech/DataIssueTracker/env/lib/python3.10/site-packages/django/urls/resolvers.py", line 708, in urlconf_module
    return import_module(self.urlconf_name)
  File "/usr/lib/python3.10/importlib/__init__.py", line 126, in import_module
    return _bootstrap._gcd_import(name[level:], package, level)
  File "<frozen importlib._bootstrap>", line 1050, in _gcd_import
  File "<frozen importlib._bootstrap>", line 1027, in _find_and_load
  File "<frozen importlib._bootstrap>", line 1006, in _find_and_load_unlocked
  File "<frozen importlib._bootstrap>", line 688, in _load_unlocked
  File "<frozen importlib._bootstrap_external>", line 883, in exec_module
  File "<frozen importlib._bootstrap>", line 241, in _call_with_frames_removed
  File "/home/tech/DataIssueTracker/DITApi/DITApi/urls.py", line 27, in <module>
    path('api/',include('DQITAuth.urls')),
  File "/home/tech/DataIssueTracker/env/lib/python3.10/site-packages/django/urls/conf.py", line 38, in include
    urlconf_module = import_module(urlconf_module)
  File "/usr/lib/python3.10/importlib/__init__.py", line 126, in import_module
    return _bootstrap._gcd_import(name[level:], package, level)
  File "<frozen importlib._bootstrap>", line 1050, in _gcd_import
  File "<frozen importlib._bootstrap>", line 1027, in _find_and_load
  File "<frozen importlib._bootstrap>", line 1006, in _find_and_load_unlocked
  File "<frozen importlib._bootstrap>", line 688, in _load_unlocked
  File "<frozen importlib._bootstrap_external>", line 883, in exec_module
  File "<frozen importlib._bootstrap>", line 241, in _call_with_frames_removed
  File "/home/tech/DataIssueTracker/DITApi/DQITAuth/urls.py", line 3, in <module>
    from .views import (
  File "/home/tech/DataIssueTracker/DITApi/DQITAuth/views.py", line 88
    role = user.role.role_name if user.role else None
IndentationError: expected an indented block after 'except' statement on line 84

During handling of the above exception, another exception occurred:

Traceback (most recent call last):
  File "/home/tech/DataIssueTracker/env/lib/python3.10/site-packages/django/core/handlers/exception.py", line 55, in inner
    response = get_response(request)
  File "/home/tech/DataIssueTracker/env/lib/python3.10/site-packages/django/utils/deprecation.py", line 134, in __call__
    response = response or self.get_response(request)
  File "/home/tech/DataIssueTracker/env/lib/python3.10/site-packages/django/core/handlers/exception.py", line 57, in inner
    response = response_for_exception(request, exc)
  File "/home/tech/DataIssueTracker/env/lib/python3.10/site-packages/django/core/handlers/exception.py", line 140, in response_for_exception
    response = handle_uncaught_exception(
  File "/home/tech/DataIssueTracker/env/lib/python3.10/site-packages/django/core/handlers/exception.py", line 181, in handle_uncaught_exception
    return debug.technical_500_response(request, *exc_info)
  File "/home/tech/DataIssueTracker/env/lib/python3.10/site-packages/django/views/debug.py", line 67, in technical_500_response
    html = reporter.get_traceback_html()
  File "/home/tech/DataIssueTracker/env/lib/python3.10/site-packages/django/views/debug.py", line 410, in get_traceback_html
    c = Context(self.get_traceback_data(), use_l10n=False)
  File "/home/tech/DataIssueTracker/env/lib/python3.10/site-packages/django/views/debug.py", line 393, in get_traceback_data
    c["raising_view_name"] = get_caller(self.request)
  File "/home/tech/DataIssueTracker/env/lib/python3.10/site-packages/django/views/debug.py", line 100, in get_caller
    resolver_match = resolve(request.path)
  File "/home/tech/DataIssueTracker/env/lib/python3.10/site-packages/django/urls/base.py", line 24, in resolve
    return get_resolver(urlconf).resolve(path)
  File "/home/tech/DataIssueTracker/env/lib/python3.10/site-packages/django/urls/resolvers.py", line 663, in resolve
    for pattern in self.url_patterns:
  File "/home/tech/DataIssueTracker/env/lib/python3.10/site-packages/django/utils/functional.py", line 57, in __get__
    res = instance.__dict__[self.name] = self.func(instance)
  File "/home/tech/DataIssueTracker/env/lib/python3.10/site-packages/django/urls/resolvers.py", line 715, in url_patterns
    patterns = getattr(self.urlconf_module, "urlpatterns", self.urlconf_module)
  File "/home/tech/DataIssueTracker/env/lib/python3.10/site-packages/django/utils/functional.py", line 57, in __get__
    res = instance.__dict__[self.name] = self.func(instance)
  File "/home/tech/DataIssueTracker/env/lib/python3.10/site-packages/django/urls/resolvers.py", line 708, in urlconf_module
    return import_module(self.urlconf_name)
  File "/usr/lib/python3.10/importlib/__init__.py", line 126, in import_module
    return _bootstrap._gcd_import(name[level:], package, level)
  File "<frozen importlib._bootstrap>", line 1050, in _gcd_import
  File "<frozen importlib._bootstrap>", line 1027, in _find_and_load
  File "<frozen importlib._bootstrap>", line 1006, in _find_and_load_unlocked
  File "<frozen importlib._bootstrap>", line 688, in _load_unlocked
  File "<frozen importlib._bootstrap_external>", line 883, in exec_module
  File "<frozen importlib._bootstrap>", line 241, in _call_with_frames_removed
  File "/home/tech/DataIssueTracker/DITApi/DITApi/urls.py", line 27, in <module>
    path('api/',include('DQITAuth.urls')),
  File "/home/tech/DataIssueTracker/env/lib/python3.10/site-packages/django/urls/conf.py", line 38, in include
    urlconf_module = import_module(urlconf_module)
  File "/usr/lib/python3.10/importlib/__init__.py", line 126, in import_module
    return _bootstrap._gcd_import(name[level:], package, level)
  File "<frozen importlib._bootstrap>", line 1050, in _gcd_import
  File "<frozen importlib._bootstrap>", line 1027, in _find_and_load
  File "<frozen importlib._bootstrap>", line 1006, in _find_and_load_unlocked
  File "<frozen importlib._bootstrap>", line 688, in _load_unlocked
  File "<frozen importlib._bootstrap_external>", line 883, in exec_module
  File "<frozen importlib._bootstrap>", line 241, in _call_with_frames_removed
  File "/home/tech/DataIssueTracker/DITApi/DQITAuth/urls.py", line 3, in <module>
    from .views import (
  File "/home/tech/DataIssueTracker/DITApi/DQITAuth/views.py", line 88
    role = user.role.role_name if user.role else None
IndentationError: expected an indented block after 'except' statement on line 84

During handling of the above exception, another exception occurred:

Traceback (most recent call last):
  File "/home/tech/DataIssueTracker/env/lib/python3.10/site-packages/django/core/handlers/exception.py", line 55, in inner
    response = get_response(request)
  File "/home/tech/DataIssueTracker/env/lib/python3.10/site-packages/corsheaders/middleware.py", line 56, in __call__
    result = self.get_response(request)
  File "/home/tech/DataIssueTracker/env/lib/python3.10/site-packages/django/core/handlers/exception.py", line 57, in inner
    response = response_for_exception(request, exc)
  File "/home/tech/DataIssueTracker/env/lib/python3.10/site-packages/django/core/handlers/exception.py", line 140, in response_for_exception
    response = handle_uncaught_exception(
  File "/home/tech/DataIssueTracker/env/lib/python3.10/site-packages/django/core/handlers/exception.py", line 181, in handle_uncaught_exception
    return debug.technical_500_response(request, *exc_info)
  File "/home/tech/DataIssueTracker/env/lib/python3.10/site-packages/django/views/debug.py", line 67, in technical_500_response
    html = reporter.get_traceback_html()
  File "/home/tech/DataIssueTracker/env/lib/python3.10/site-packages/django/views/debug.py", line 410, in get_traceback_html
    c = Context(self.get_traceback_data(), use_l10n=False)
  File "/home/tech/DataIssueTracker/env/lib/python3.10/site-packages/django/views/debug.py", line 393, in get_traceback_data
    c["raising_view_name"] = get_caller(self.request)
  File "/home/tech/DataIssueTracker/env/lib/python3.10/site-packages/django/views/debug.py", line 100, in get_caller
    resolver_match = resolve(request.path)
  File "/home/tech/DataIssueTracker/env/lib/python3.10/site-packages/django/urls/base.py", line 24, in resolve
    return get_resolver(urlconf).resolve(path)
  File "/home/tech/DataIssueTracker/env/lib/python3.10/site-packages/django/urls/resolvers.py", line 663, in resolve
    for pattern in self.url_patterns:
  File "/home/tech/DataIssueTracker/env/lib/python3.10/site-packages/django/utils/functional.py", line 57, in __get__
    res = instance.__dict__[self.name] = self.func(instance)
  File "/home/tech/DataIssueTracker/env/lib/python3.10/site-packages/django/urls/resolvers.py", line 715, in url_patterns
    patterns = getattr(self.urlconf_module, "urlpatterns", self.urlconf_module)
  File "/home/tech/DataIssueTracker/env/lib/python3.10/site-packages/django/utils/functional.py", line 57, in __get__
    res = instance.__dict__[self.name] = self.func(instance)
  File "/home/tech/DataIssueTracker/env/lib/python3.10/site-packages/django/urls/resolvers.py", line 708, in urlconf_module
    return import_module(self.urlconf_name)
  File "/usr/lib/python3.10/importlib/__init__.py", line 126, in import_module
    return _bootstrap._gcd_import(name[level:], package, level)
  File "<frozen importlib._bootstrap>", line 1050, in _gcd_import
  File "<frozen importlib._bootstrap>", line 1027, in _find_and_load
  File "<frozen importlib._bootstrap>", line 1006, in _find_and_load_unlocked
  File "<frozen importlib._bootstrap>", line 688, in _load_unlocked
  File "<frozen importlib._bootstrap_external>", line 883, in exec_module
  File "<frozen importlib._bootstrap>", line 241, in _call_with_frames_removed
  File "/home/tech/DataIssueTracker/DITApi/DITApi/urls.py", line 27, in <module>
    path('api/',include('DQITAuth.urls')),
  File "/home/tech/DataIssueTracker/env/lib/python3.10/site-packages/django/urls/conf.py", line 38, in include
    urlconf_module = import_module(urlconf_module)
  File "/usr/lib/python3.10/importlib/__init__.py", line 126, in import_module
    return _bootstrap._gcd_import(name[level:], package, level)
  File "<frozen importlib._bootstrap>", line 1050, in _gcd_import
  File "<frozen importlib._bootstrap>", line 1027, in _find_and_load
  File "<frozen importlib._bootstrap>", line 1006, in _find_and_load_unlocked
  File "<frozen importlib._bootstrap>", line 688, in _load_unlocked
  File "<frozen importlib._bootstrap_external>", line 883, in exec_module
  File "<frozen importlib._bootstrap>", line 241, in _call_with_frames_removed
  File "/home/tech/DataIssueTracker/DITApi/DQITAuth/urls.py", line 3, in <module>
    from .views import (
  File "/home/tech/DataIssueTracker/DITApi/DQITAuth/views.py", line 88
    role = user.role.role_name if user.role else None
IndentationError: expected an indented block after 'except' statement on line 84

During handling of the above exception, another exception occurred:

Traceback (most recent call last):
  File "/home/tech/DataIssueTracker/env/lib/python3.10/site-packages/django/core/handlers/exception.py", line 55, in inner
    response = get_response(request)
  File "/home/tech/DataIssueTracker/env/lib/python3.10/site-packages/django/utils/deprecation.py", line 134, in __call__
    response = response or self.get_response(request)
  File "/home/tech/DataIssueTracker/env/lib/python3.10/site-packages/django/core/handlers/exception.py", line 57, in inner
    response = response_for_exception(request, exc)
  File "/home/tech/DataIssueTracker/env/lib/python3.10/site-packages/django/core/handlers/exception.py", line 140, in response_for_exception
    response = handle_uncaught_exception(
  File "/home/tech/DataIssueTracker/env/lib/python3.10/site-packages/django/core/handlers/exception.py", line 181, in handle_uncaught_exception
    return debug.technical_500_response(request, *exc_info)
  File "/home/tech/DataIssueTracker/env/lib/python3.10/site-packages/django/views/debug.py", line 67, in technical_500_response
    html = reporter.get_traceback_html()
  File "/home/tech/DataIssueTracker/env/lib/python3.10/site-packages/django/views/debug.py", line 410, in get_traceback_html
    c = Context(self.get_traceback_data(), use_l10n=False)
  File "/home/tech/DataIssueTracker/env/lib/python3.10/site-packages/django/views/debug.py", line 393, in get_traceback_data
    c["raising_view_name"] = get_caller(self.request)
  File "/home/tech/DataIssueTracker/env/lib/python3.10/site-packages/django/views/debug.py", line 100, in get_caller
    resolver_match = resolve(request.path)
  File "/home/tech/DataIssueTracker/env/lib/python3.10/site-packages/django/urls/base.py", line 24, in resolve
    return get_resolver(urlconf).resolve(path)
  File "/home/tech/DataIssueTracker/env/lib/python3.10/site-packages/django/urls/resolvers.py", line 663, in resolve
    for pattern in self.url_patterns:
  File "/home/tech/DataIssueTracker/env/lib/python3.10/site-packages/django/utils/functional.py", line 57, in __get__
    res = instance.__dict__[self.name] = self.func(instance)
  File "/home/tech/DataIssueTracker/env/lib/python3.10/site-packages/django/urls/resolvers.py", line 715, in url_patterns
    patterns = getattr(self.urlconf_module, "urlpatterns", self.urlconf_module)
  File "/home/tech/DataIssueTracker/env/lib/python3.10/site-packages/django/utils/functional.py", line 57, in __get__
    res = instance.__dict__[self.name] = self.func(instance)
  File "/home/tech/DataIssueTracker/env/lib/python3.10/site-packages/django/urls/resolvers.py", line 708, in urlconf_module
    return import_module(self.urlconf_name)
  File "/usr/lib/python3.10/importlib/__init__.py", line 126, in import_module
    return _bootstrap._gcd_import(name[level:], package, level)
  File "<frozen importlib._bootstrap>", line 1050, in _gcd_import
  File "<frozen importlib._bootstrap>", line 1027, in _find_and_load
  File "<frozen importlib._bootstrap>", line 1006, in _find_and_load_unlocked
  File "<frozen importlib._bootstrap>", line 688, in _load_unlocked
  File "<frozen importlib._bootstrap_external>", line 883, in exec_module
  File "<frozen importlib._bootstrap>", line 241, in _call_with_frames_removed
  File "/home/tech/DataIssueTracker/DITApi/DITApi/urls.py", line 27, in <module>
    path('api/',include('DQITAuth.urls')),
  File "/home/tech/DataIssueTracker/env/lib/python3.10/site-packages/django/urls/conf.py", line 38, in include
    urlconf_module = import_module(urlconf_module)
  File "/usr/lib/python3.10/importlib/__init__.py", line 126, in import_module
    return _bootstrap._gcd_import(name[level:], package, level)
  File "<frozen importlib._bootstrap>", line 1050, in _gcd_import
  File "<frozen importlib._bootstrap>", line 1027, in _find_and_load
  File "<frozen importlib._bootstrap>", line 1006, in _find_and_load_unlocked
  File "<frozen importlib._bootstrap>", line 688, in _load_unlocked
  File "<frozen importlib._bootstrap_external>", line 883, in exec_module
  File "<frozen importlib._bootstrap>", line 241, in _call_with_frames_removed
  File "/home/tech/DataIssueTracker/DITApi/DQITAuth/urls.py", line 3, in <module>
    from .views import (
  File "/home/tech/DataIssueTracker/DITApi/DQITAuth/views.py", line 88
    role = user.role.role_name if user.role else None
IndentationError: expected an indented block after 'except' statement on line 84

During handling of the above exception, another exception occurred:

Traceback (most recent call last):
  File "/home/tech/DataIssueTracker/env/lib/python3.10/site-packages/django/core/handlers/exception.py", line 55, in inner
    response = get_response(request)
  File "/home/tech/DataIssueTracker/env/lib/python3.10/site-packages/django/utils/deprecation.py", line 134, in __call__
    response = response or self.get_response(request)
  File "/home/tech/DataIssueTracker/env/lib/python3.10/site-packages/django/core/handlers/exception.py", line 57, in inner
    response = response_for_exception(request, exc)
  File "/home/tech/DataIssueTracker/env/lib/python3.10/site-packages/django/core/handlers/exception.py", line 140, in response_for_exception
    response = handle_uncaught_exception(
  File "/home/tech/DataIssueTracker/env/lib/python3.10/site-packages/django/core/handlers/exception.py", line 181, in handle_uncaught_exception
    return debug.technical_500_response(request, *exc_info)
  File "/home/tech/DataIssueTracker/env/lib/python3.10/site-packages/django/views/debug.py", line 67, in technical_500_response
    html = reporter.get_traceback_html()
  File "/home/tech/DataIssueTracker/env/lib/python3.10/site-packages/django/views/debug.py", line 410, in get_traceback_html
    c = Context(self.get_traceback_data(), use_l10n=False)
  File "/home/tech/DataIssueTracker/env/lib/python3.10/site-packages/django/views/debug.py", line 393, in get_traceback_data
    c["raising_view_name"] = get_caller(self.request)
  File "/home/tech/DataIssueTracker/env/lib/python3.10/site-packages/django/views/debug.py", line 100, in get_caller
    resolver_match = resolve(request.path)
  File "/home/tech/DataIssueTracker/env/lib/python3.10/site-packages/django/urls/base.py", line 24, in resolve
    return get_resolver(urlconf).resolve(path)
  File "/home/tech/DataIssueTracker/env/lib/python3.10/site-packages/django/urls/resolvers.py", line 663, in resolve
    for pattern in self.url_patterns:
  File "/home/tech/DataIssueTracker/env/lib/python3.10/site-packages/django/utils/functional.py", line 57, in __get__
    res = instance.__dict__[self.name] = self.func(instance)
  File "/home/tech/DataIssueTracker/env/lib/python3.10/site-packages/django/urls/resolvers.py", line 715, in url_patterns
    patterns = getattr(self.urlconf_module, "urlpatterns", self.urlconf_module)
  File "/home/tech/DataIssueTracker/env/lib/python3.10/site-packages/django/utils/functional.py", line 57, in __get__
    res = instance.__dict__[self.name] = self.func(instance)
  File "/home/tech/DataIssueTracker/env/lib/python3.10/site-packages/django/urls/resolvers.py", line 708, in urlconf_module
    return import_module(self.urlconf_name)
  File "/usr/lib/python3.10/importlib/__init__.py", line 126, in import_module
    return _bootstrap._gcd_import(name[level:], package, level)
  File "<frozen importlib._bootstrap>", line 1050, in _gcd_import
  File "<frozen importlib._bootstrap>", line 1027, in _find_and_load
  File "<frozen importlib._bootstrap>", line 1006, in _find_and_load_unlocked
  File "<frozen importlib._bootstrap>", line 688, in _load_unlocked
  File "<frozen importlib._bootstrap_external>", line 883, in exec_module
  File "<frozen importlib._bootstrap>", line 241, in _call_with_frames_removed
  File "/home/tech/DataIssueTracker/DITApi/DITApi/urls.py", line 27, in <module>
    path('api/',include('DQITAuth.urls')),
  File "/home/tech/DataIssueTracker/env/lib/python3.10/site-packages/django/urls/conf.py", line 38, in include
    urlconf_module = import_module(urlconf_module)
  File "/usr/lib/python3.10/importlib/__init__.py", line 126, in import_module
    return _bootstrap._gcd_import(name[level:], package, level)
  File "<frozen importlib._bootstrap>", line 1050, in _gcd_import
  File "<frozen importlib._bootstrap>", line 1027, in _find_and_load
  File "<frozen importlib._bootstrap>", line 1006, in _find_and_load_unlocked
  File "<frozen importlib._bootstrap>", line 688, in _load_unlocked
  File "<frozen importlib._bootstrap_external>", line 883, in exec_module
  File "<frozen importlib._bootstrap>", line 241, in _call_with_frames_removed
  File "/home/tech/DataIssueTracker/DITApi/DQITAuth/urls.py", line 3, in <module>
    from .views import (
  File "/home/tech/DataIssueTracker/DITApi/DQITAuth/views.py", line 88
    role = user.role.role_name if user.role else None
IndentationError: expected an indented block after 'except' statement on line 84

During handling of the above exception, another exception occurred:

Traceback (most recent call last):
  File "/home/tech/DataIssueTracker/env/lib/python3.10/site-packages/gunicorn/workers/sync.py", line 135, in handle
    self.handle_request(listener, req, client, addr)
  File "/home/tech/DataIssueTracker/env/lib/python3.10/site-packages/gunicorn/workers/sync.py", line 178, in handle_request
    respiter = self.wsgi(environ, resp.start_response)
  File "/home/tech/DataIssueTracker/env/lib/python3.10/site-packages/django/core/handlers/wsgi.py", line 124, in __call__
    response = self.get_response(request)
  File "/home/tech/DataIssueTracker/env/lib/python3.10/site-packages/django/core/handlers/base.py", line 140, in get_response
    response = self._middleware_chain(request)
  File "/home/tech/DataIssueTracker/env/lib/python3.10/site-packages/django/core/handlers/exception.py", line 57, in inner
    response = response_for_exception(request, exc)
  File "/home/tech/DataIssueTracker/env/lib/python3.10/site-packages/django/core/handlers/exception.py", line 140, in response_for_exception
    response = handle_uncaught_exception(
  File "/home/tech/DataIssueTracker/env/lib/python3.10/site-packages/django/core/handlers/exception.py", line 181, in handle_uncaught_exception
    return debug.technical_500_response(request, *exc_info)
  File "/home/tech/DataIssueTracker/env/lib/python3.10/site-packages/django/views/debug.py", line 67, in technical_500_response
    html = reporter.get_traceback_html()
  File "/home/tech/DataIssueTracker/env/lib/python3.10/site-packages/django/views/debug.py", line 410, in get_traceback_html
    c = Context(self.get_traceback_data(), use_l10n=False)
  File "/home/tech/DataIssueTracker/env/lib/python3.10/site-packages/django/views/debug.py", line 393, in get_traceback_data
    c["raising_view_name"] = get_caller(self.request)
  File "/home/tech/DataIssueTracker/env/lib/python3.10/site-packages/django/views/debug.py", line 100, in get_caller
    resolver_match = resolve(request.path)
  File "/home/tech/DataIssueTracker/env/lib/python3.10/site-packages/django/urls/base.py", line 24, in resolve
    return get_resolver(urlconf).resolve(path)
  File "/home/tech/DataIssueTracker/env/lib/python3.10/site-packages/django/urls/resolvers.py", line 663, in resolve
    for pattern in self.url_patterns:
  File "/home/tech/DataIssueTracker/env/lib/python3.10/site-packages/django/utils/functional.py", line 57, in __get__
    res = instance.__dict__[self.name] = self.func(instance)
  File "/home/tech/DataIssueTracker/env/lib/python3.10/site-packages/django/urls/resolvers.py", line 715, in url_patterns
    patterns = getattr(self.urlconf_module, "urlpatterns", self.urlconf_module)
  File "/home/tech/DataIssueTracker/env/lib/python3.10/site-packages/django/utils/functional.py", line 57, in __get__
    res = instance.__dict__[self.name] = self.func(instance)
  File "/home/tech/DataIssueTracker/env/lib/python3.10/site-packages/django/urls/resolvers.py", line 708, in urlconf_module
    return import_module(self.urlconf_name)
  File "/usr/lib/python3.10/importlib/__init__.py", line 126, in import_module
    return _bootstrap._gcd_import(name[level:], package, level)
  File "<frozen importlib._bootstrap>", line 1050, in _gcd_import
  File "<frozen importlib._bootstrap>", line 1027, in _find_and_load
  File "<frozen importlib._bootstrap>", line 1006, in _find_and_load_unlocked
  File "<frozen importlib._bootstrap>", line 688, in _load_unlocked
  File "<frozen importlib._bootstrap_external>", line 883, in exec_module
  File "<frozen importlib._bootstrap>", line 241, in _call_with_frames_removed
  File "/home/tech/DataIssueTracker/DITApi/DITApi/urls.py", line 27, in <module>
    path('api/',include('DQITAuth.urls')),
  File "/home/tech/DataIssueTracker/env/lib/python3.10/site-packages/django/urls/conf.py", line 38, in include
    urlconf_module = import_module(urlconf_module)
  File "/usr/lib/python3.10/importlib/__init__.py", line 126, in import_module
    return _bootstrap._gcd_import(name[level:], package, level)
  File "<frozen importlib._bootstrap>", line 1050, in _gcd_import
  File "<frozen importlib._bootstrap>", line 1027, in _find_and_load
  File "<frozen importlib._bootstrap>", line 1006, in _find_and_load_unlocked
  File "<frozen importlib._bootstrap>", line 688, in _load_unlocked
  File "<frozen importlib._bootstrap_external>", line 883, in exec_module
  File "<frozen importlib._bootstrap>", line 241, in _call_with_frames_removed
  File "/home/tech/DataIssueTracker/DITApi/DQITAuth/urls.py", line 3, in <module>
    from .views import (
  File "/home/tech/DataIssueTracker/DITApi/DQITAuth/views.py", line 88
    role = user.role.role_name if user.role else None
IndentationError: expected an indented block after 'except' statement on line 84
[2023-10-29 14:33:49 +0000] [107976] [INFO] Handling signal: int
[2023-10-29 14:33:50 +0000] [107976] [INFO] Shutting down: Master
[2023-10-29 14:36:14 +0000] [108015] [INFO] Starting gunicorn 21.2.0
[2023-10-29 14:36:14 +0000] [108015] [INFO] Listening at: http://0.0.0.0:8000 (108015)
[2023-10-29 14:36:14 +0000] [108015] [INFO] Using worker: sync
[2023-10-29 14:36:14 +0000] [108016] [INFO] Booting worker with pid: 108016
[2023-10-29 14:38:01 +0000] [108034] [INFO] Starting gunicorn 21.2.0
[2023-10-29 14:38:01 +0000] [108034] [INFO] Listening at: http://0.0.0.0:8001 (108034)
[2023-10-29 14:38:01 +0000] [108034] [INFO] Using worker: sync
[2023-10-29 14:38:01 +0000] [108035] [INFO] Booting worker with pid: 108035
[2023-10-29 14:38:29 +0000] [108038] [INFO] Starting gunicorn 21.2.0
[2023-10-29 14:38:29 +0000] [108038] [ERROR] Connection in use: ('0.0.0.0', 8001)
[2023-10-29 14:38:29 +0000] [108038] [ERROR] Retrying in 1 second.
[2023-10-29 14:38:30 +0000] [108038] [ERROR] Connection in use: ('0.0.0.0', 8001)
[2023-10-29 14:38:30 +0000] [108038] [ERROR] Retrying in 1 second.
[2023-10-29 14:38:31 +0000] [108038] [ERROR] Connection in use: ('0.0.0.0', 8001)
[2023-10-29 14:38:31 +0000] [108038] [ERROR] Retrying in 1 second.
[2023-10-29 14:38:32 +0000] [108038] [ERROR] Connection in use: ('0.0.0.0', 8001)
[2023-10-29 14:38:32 +0000] [108038] [ERROR] Retrying in 1 second.
[2023-10-29 14:38:33 +0000] [108038] [ERROR] Connection in use: ('0.0.0.0', 8001)
[2023-10-29 14:38:33 +0000] [108038] [ERROR] Retrying in 1 second.
[2023-10-29 14:38:34 +0000] [108038] [ERROR] Can't connect to ('0.0.0.0', 8001)
[2023-10-29 14:40:55 +0000] [108134] [INFO] Starting gunicorn 21.2.0
[2023-10-29 14:40:55 +0000] [108134] [INFO] Listening at: http://0.0.0.0:8001 (108134)
[2023-10-29 14:40:55 +0000] [108134] [INFO] Using worker: sync
[2023-10-29 14:40:55 +0000] [108135] [INFO] Booting worker with pid: 108135
[2023-10-29 14:50:20 +0000] [108316] [INFO] Starting gunicorn 21.2.0
[2023-10-29 14:50:20 +0000] [108316] [INFO] Listening at: http://0.0.0.0:8000 (108316)
[2023-10-29 14:50:20 +0000] [108316] [INFO] Using worker: sync
[2023-10-29 14:50:20 +0000] [108317] [INFO] Booting worker with pid: 108317
[2023-10-29 14:50:25 +0000] [108316] [INFO] Handling signal: int
[2023-10-29 14:50:26 +0000] [108316] [INFO] Shutting down: Master
[2023-10-29 15:10:27 +0000] [108696] [INFO] Starting gunicorn 21.2.0
[2023-10-29 15:10:27 +0000] [108696] [ERROR] Connection in use: ('0.0.0.0', 8000)
[2023-10-29 15:10:27 +0000] [108696] [ERROR] Retrying in 1 second.
[2023-10-29 15:10:28 +0000] [108696] [ERROR] Connection in use: ('0.0.0.0', 8000)
[2023-10-29 15:10:28 +0000] [108696] [ERROR] Retrying in 1 second.
[2023-10-29 15:10:29 +0000] [108696] [ERROR] Connection in use: ('0.0.0.0', 8000)
[2023-10-29 15:10:29 +0000] [108696] [ERROR] Retrying in 1 second.
[2023-10-29 15:10:30 +0000] [108696] [ERROR] Connection in use: ('0.0.0.0', 8000)
[2023-10-29 15:10:30 +0000] [108696] [ERROR] Retrying in 1 second.
[2023-10-29 15:10:31 +0000] [108696] [ERROR] Connection in use: ('0.0.0.0', 8000)
[2023-10-29 15:10:31 +0000] [108696] [ERROR] Retrying in 1 second.
[2023-10-29 15:10:32 +0000] [108696] [ERROR] Can't connect to ('0.0.0.0', 8000)
[2023-10-29 15:26:59 +0000] [108997] [INFO] Starting gunicorn 21.2.0
[2023-10-29 15:26:59 +0000] [108997] [INFO] Listening at: http://0.0.0.0:8000 (108997)
[2023-10-29 15:26:59 +0000] [108997] [INFO] Using worker: sync
[2023-10-29 15:26:59 +0000] [108998] [INFO] Booting worker with pid: 108998
Method Not Allowed: /api/sync_data/
[2023-10-29 15:28:56 +0000] [109076] [INFO] Starting gunicorn 21.2.0
[2023-10-29 15:28:56 +0000] [109076] [ERROR] Connection in use: ('0.0.0.0', 8000)
[2023-10-29 15:28:56 +0000] [109076] [ERROR] Retrying in 1 second.
[2023-10-29 15:28:57 +0000] [109076] [ERROR] Connection in use: ('0.0.0.0', 8000)
[2023-10-29 15:28:57 +0000] [109076] [ERROR] Retrying in 1 second.
[2023-10-29 15:28:58 +0000] [109076] [ERROR] Connection in use: ('0.0.0.0', 8000)
[2023-10-29 15:28:58 +0000] [109076] [ERROR] Retrying in 1 second.
[2023-10-29 15:28:59 +0000] [109076] [ERROR] Connection in use: ('0.0.0.0', 8000)
[2023-10-29 15:28:59 +0000] [109076] [ERROR] Retrying in 1 second.
[2023-10-29 15:29:00 +0000] [109076] [ERROR] Connection in use: ('0.0.0.0', 8000)
[2023-10-29 15:29:00 +0000] [109076] [ERROR] Retrying in 1 second.
[2023-10-29 15:29:01 +0000] [109076] [ERROR] Can't connect to ('0.0.0.0', 8000)
[2023-10-29 15:31:22 +0000] [109106] [INFO] Starting gunicorn 21.2.0
[2023-10-29 15:31:22 +0000] [109106] [ERROR] Connection in use: ('0.0.0.0', 8000)
[2023-10-29 15:31:22 +0000] [109106] [ERROR] Retrying in 1 second.
[2023-10-29 15:31:23 +0000] [109106] [ERROR] Connection in use: ('0.0.0.0', 8000)
[2023-10-29 15:31:23 +0000] [109106] [ERROR] Retrying in 1 second.
[2023-10-29 15:31:24 +0000] [109106] [ERROR] Connection in use: ('0.0.0.0', 8000)
[2023-10-29 15:31:24 +0000] [109106] [ERROR] Retrying in 1 second.
[2023-10-29 15:31:25 +0000] [109106] [ERROR] Connection in use: ('0.0.0.0', 8000)
[2023-10-29 15:31:25 +0000] [109106] [ERROR] Retrying in 1 second.
[2023-10-29 15:31:26 +0000] [109106] [ERROR] Connection in use: ('0.0.0.0', 8000)
[2023-10-29 15:31:26 +0000] [109106] [ERROR] Retrying in 1 second.
[2023-10-29 15:31:27 +0000] [109106] [ERROR] Can't connect to ('0.0.0.0', 8000)
[2023-10-29 15:37:51 +0000] [109175] [INFO] Starting gunicorn 21.2.0
[2023-10-29 15:37:51 +0000] [109175] [ERROR] Connection in use: ('0.0.0.0', 8000)
[2023-10-29 15:37:51 +0000] [109175] [ERROR] Retrying in 1 second.
[2023-10-29 15:37:52 +0000] [109175] [ERROR] Connection in use: ('0.0.0.0', 8000)
[2023-10-29 15:37:52 +0000] [109175] [ERROR] Retrying in 1 second.
[2023-10-29 15:37:53 +0000] [109175] [ERROR] Connection in use: ('0.0.0.0', 8000)
[2023-10-29 15:37:53 +0000] [109175] [ERROR] Retrying in 1 second.
[2023-10-29 15:37:54 +0000] [109175] [ERROR] Connection in use: ('0.0.0.0', 8000)
[2023-10-29 15:37:54 +0000] [109175] [ERROR] Retrying in 1 second.
[2023-10-29 15:37:55 +0000] [109175] [ERROR] Connection in use: ('0.0.0.0', 8000)
[2023-10-29 15:37:55 +0000] [109175] [ERROR] Retrying in 1 second.
[2023-10-29 15:37:56 +0000] [109175] [ERROR] Can't connect to ('0.0.0.0', 8000)
[2023-10-29 15:40:45 +0000] [109264] [INFO] Starting gunicorn 21.2.0
[2023-10-29 15:40:45 +0000] [109264] [ERROR] Connection in use: ('0.0.0.0', 8000)
[2023-10-29 15:40:45 +0000] [109264] [ERROR] Retrying in 1 second.
[2023-10-29 15:40:46 +0000] [109264] [ERROR] Connection in use: ('0.0.0.0', 8000)
[2023-10-29 15:40:46 +0000] [109264] [ERROR] Retrying in 1 second.
[2023-10-29 15:40:47 +0000] [109264] [ERROR] Connection in use: ('0.0.0.0', 8000)
[2023-10-29 15:40:47 +0000] [109264] [ERROR] Retrying in 1 second.
[2023-10-29 15:40:48 +0000] [109264] [ERROR] Connection in use: ('0.0.0.0', 8000)
[2023-10-29 15:40:48 +0000] [109264] [ERROR] Retrying in 1 second.
[2023-10-29 15:40:49 +0000] [109264] [ERROR] Connection in use: ('0.0.0.0', 8000)
[2023-10-29 15:40:49 +0000] [109264] [ERROR] Retrying in 1 second.
[2023-10-29 15:40:50 +0000] [109264] [ERROR] Can't connect to ('0.0.0.0', 8000)
[2023-10-29 15:43:05 +0000] [109314] [INFO] Starting gunicorn 21.2.0
[2023-10-29 15:43:05 +0000] [109314] [INFO] Listening at: http://0.0.0.0:8000 (109314)
[2023-10-29 15:43:05 +0000] [109314] [INFO] Using worker: sync
[2023-10-29 15:43:05 +0000] [109315] [INFO] Booting worker with pid: 109315
Method Not Allowed: /api/sync_data/
[2023-10-29 15:43:58 +0000] [109314] [INFO] Handling signal: int
[2023-10-29 18:43:58 +0300] [109315] [INFO] Worker exiting (pid: 109315)
[2023-10-29 15:43:59 +0000] [109314] [INFO] Shutting down: Master
[2023-10-29 15:45:59 +0000] [109366] [INFO] Starting gunicorn 21.2.0
[2023-10-29 15:45:59 +0000] [109366] [INFO] Listening at: http://0.0.0.0:8000 (109366)
[2023-10-29 15:45:59 +0000] [109366] [INFO] Using worker: sync
[2023-10-29 15:45:59 +0000] [109367] [INFO] Booting worker with pid: 109367
Method Not Allowed: /api/sync_data/
[2023-10-29 15:46:58 +0000] [109366] [CRITICAL] WORKER TIMEOUT (pid:109367)
[2023-10-29 18:46:58 +0300] [109367] [INFO] Worker exiting (pid: 109367)
[2023-10-29 15:46:59 +0000] [109366] [ERROR] Worker (pid:109367) exited with code 1
[2023-10-29 15:46:59 +0000] [109366] [ERROR] Worker (pid:109367) exited with code 1.
[2023-10-29 15:46:59 +0000] [109376] [INFO] Booting worker with pid: 109376
Method Not Allowed: /api/sync_data/
[2023-10-29 15:48:35 +0000] [109366] [CRITICAL] WORKER TIMEOUT (pid:109376)
[2023-10-29 18:48:35 +0300] [109376] [INFO] Worker exiting (pid: 109376)
[2023-10-29 15:48:36 +0000] [109366] [ERROR] Worker (pid:109376) exited with code 1
[2023-10-29 15:48:36 +0000] [109366] [ERROR] Worker (pid:109376) exited with code 1.
[2023-10-29 15:48:36 +0000] [109419] [INFO] Booting worker with pid: 109419
Method Not Allowed: /api/sync_data/
Unauthorized: /api/analytics/
Unauthorized: /api/data_issue_stats/
Unauthorized: /api/data_issues/
Unauthorized: /api/user-logs/
Unauthorized: /api/facilities/
Internal Server Error: /api/user-logs/
Traceback (most recent call last):
  File "/home/tech/DataIssueTracker/env/lib/python3.10/site-packages/django/db/backends/utils.py", line 89, in _execute
    return self.cursor.execute(sql, params)
  File "/home/tech/DataIssueTracker/env/lib/python3.10/site-packages/django/db/backends/mysql/base.py", line 75, in execute
    return self.cursor.execute(query, args)
  File "/home/tech/DataIssueTracker/env/lib/python3.10/site-packages/MySQLdb/cursors.py", line 179, in execute
    res = self._query(mogrified_query)
  File "/home/tech/DataIssueTracker/env/lib/python3.10/site-packages/MySQLdb/cursors.py", line 330, in _query
    db.query(q)
  File "/home/tech/DataIssueTracker/env/lib/python3.10/site-packages/MySQLdb/connections.py", line 255, in query
    _mysql.connection.query(self, query)
MySQLdb.ProgrammingError: (1146, "Table 'dqits.DQITAuth_userlog' doesn't exist")

The above exception was the direct cause of the following exception:

Traceback (most recent call last):
  File "/home/tech/DataIssueTracker/env/lib/python3.10/site-packages/django/core/handlers/exception.py", line 55, in inner
    response = get_response(request)
  File "/home/tech/DataIssueTracker/env/lib/python3.10/site-packages/django/core/handlers/base.py", line 197, in _get_response
    response = wrapped_callback(request, *callback_args, **callback_kwargs)
  File "/home/tech/DataIssueTracker/env/lib/python3.10/site-packages/django/views/decorators/csrf.py", line 56, in wrapper_view
    return view_func(*args, **kwargs)
  File "/home/tech/DataIssueTracker/env/lib/python3.10/site-packages/django/views/generic/base.py", line 104, in view
    return self.dispatch(request, *args, **kwargs)
  File "/home/tech/DataIssueTracker/env/lib/python3.10/site-packages/rest_framework/views.py", line 509, in dispatch
    response = self.handle_exception(exc)
  File "/home/tech/DataIssueTracker/env/lib/python3.10/site-packages/rest_framework/views.py", line 469, in handle_exception
    self.raise_uncaught_exception(exc)
  File "/home/tech/DataIssueTracker/env/lib/python3.10/site-packages/rest_framework/views.py", line 480, in raise_uncaught_exception
    raise exc
  File "/home/tech/DataIssueTracker/env/lib/python3.10/site-packages/rest_framework/views.py", line 506, in dispatch
    response = handler(request, *args, **kwargs)
  File "/home/tech/DataIssueTracker/DITApi/DQITAuth/views.py", line 312, in get
    result_page = paginator.paginate_queryset(logs, request)
  File "/home/tech/DataIssueTracker/env/lib/python3.10/site-packages/rest_framework/pagination.py", line 387, in paginate_queryset
    self.count = self.get_count(queryset)
  File "/home/tech/DataIssueTracker/env/lib/python3.10/site-packages/rest_framework/pagination.py", line 525, in get_count
    return queryset.count()
  File "/home/tech/DataIssueTracker/env/lib/python3.10/site-packages/django/db/models/query.py", line 608, in count
    return self.query.get_count(using=self.db)
  File "/home/tech/DataIssueTracker/env/lib/python3.10/site-packages/django/db/models/sql/query.py", line 568, in get_count
    return obj.get_aggregation(using, {"__count": Count("*")})["__count"]
  File "/home/tech/DataIssueTracker/env/lib/python3.10/site-packages/django/db/models/sql/query.py", line 554, in get_aggregation
    result = compiler.execute_sql(SINGLE)
  File "/home/tech/DataIssueTracker/env/lib/python3.10/site-packages/django/db/models/sql/compiler.py", line 1562, in execute_sql
    cursor.execute(sql, params)
  File "/home/tech/DataIssueTracker/env/lib/python3.10/site-packages/django/db/backends/utils.py", line 102, in execute
    return super().execute(sql, params)
  File "/home/tech/DataIssueTracker/env/lib/python3.10/site-packages/django/db/backends/utils.py", line 67, in execute
    return self._execute_with_wrappers(
  File "/home/tech/DataIssueTracker/env/lib/python3.10/site-packages/django/db/backends/utils.py", line 80, in _execute_with_wrappers
    return executor(sql, params, many, context)
  File "/home/tech/DataIssueTracker/env/lib/python3.10/site-packages/django/db/backends/utils.py", line 84, in _execute
    with self.db.wrap_database_errors:
  File "/home/tech/DataIssueTracker/env/lib/python3.10/site-packages/django/db/utils.py", line 91, in __exit__
    raise dj_exc_value.with_traceback(traceback) from exc_value
  File "/home/tech/DataIssueTracker/env/lib/python3.10/site-packages/django/db/backends/utils.py", line 89, in _execute
    return self.cursor.execute(sql, params)
  File "/home/tech/DataIssueTracker/env/lib/python3.10/site-packages/django/db/backends/mysql/base.py", line 75, in execute
    return self.cursor.execute(query, args)
  File "/home/tech/DataIssueTracker/env/lib/python3.10/site-packages/MySQLdb/cursors.py", line 179, in execute
    res = self._query(mogrified_query)
  File "/home/tech/DataIssueTracker/env/lib/python3.10/site-packages/MySQLdb/cursors.py", line 330, in _query
    db.query(q)
  File "/home/tech/DataIssueTracker/env/lib/python3.10/site-packages/MySQLdb/connections.py", line 255, in query
    _mysql.connection.query(self, query)
django.db.utils.ProgrammingError: (1146, "Table 'dqits.DQITAuth_userlog' doesn't exist")
[2023-10-29 15:55:08 +0000] [109366] [CRITICAL] WORKER TIMEOUT (pid:109419)
[2023-10-29 18:55:08 +0300] [109419] [INFO] Worker exiting (pid: 109419)
[2023-10-29 15:55:09 +0000] [109366] [ERROR] Worker (pid:109419) exited with code 1
[2023-10-29 15:55:09 +0000] [109366] [ERROR] Worker (pid:109419) exited with code 1.
[2023-10-29 15:55:09 +0000] [109487] [INFO] Booting worker with pid: 109487
[2023-10-29 15:56:18 +0000] [109366] [CRITICAL] WORKER TIMEOUT (pid:109487)
[2023-10-29 18:56:18 +0300] [109487] [INFO] Worker exiting (pid: 109487)
[2023-10-29 15:56:18 +0000] [109366] [ERROR] Worker (pid:109487) exited with code 1
[2023-10-29 15:56:18 +0000] [109366] [ERROR] Worker (pid:109487) exited with code 1.
[2023-10-29 15:56:18 +0000] [109508] [INFO] Booting worker with pid: 109508
Method Not Allowed: /api/sync_data/
Internal Server Error: /api/user-logs/
Traceback (most recent call last):
  File "/home/tech/DataIssueTracker/env/lib/python3.10/site-packages/django/db/backends/utils.py", line 89, in _execute
    return self.cursor.execute(sql, params)
  File "/home/tech/DataIssueTracker/env/lib/python3.10/site-packages/django/db/backends/mysql/base.py", line 75, in execute
    return self.cursor.execute(query, args)
  File "/home/tech/DataIssueTracker/env/lib/python3.10/site-packages/MySQLdb/cursors.py", line 179, in execute
    res = self._query(mogrified_query)
  File "/home/tech/DataIssueTracker/env/lib/python3.10/site-packages/MySQLdb/cursors.py", line 330, in _query
    db.query(q)
  File "/home/tech/DataIssueTracker/env/lib/python3.10/site-packages/MySQLdb/connections.py", line 255, in query
    _mysql.connection.query(self, query)
MySQLdb.ProgrammingError: (1146, "Table 'dqits.DQITAuth_userlog' doesn't exist")

The above exception was the direct cause of the following exception:

Traceback (most recent call last):
  File "/home/tech/DataIssueTracker/env/lib/python3.10/site-packages/django/core/handlers/exception.py", line 55, in inner
    response = get_response(request)
  File "/home/tech/DataIssueTracker/env/lib/python3.10/site-packages/django/core/handlers/base.py", line 197, in _get_response
    response = wrapped_callback(request, *callback_args, **callback_kwargs)
  File "/home/tech/DataIssueTracker/env/lib/python3.10/site-packages/django/views/decorators/csrf.py", line 56, in wrapper_view
    return view_func(*args, **kwargs)
  File "/home/tech/DataIssueTracker/env/lib/python3.10/site-packages/django/views/generic/base.py", line 104, in view
    return self.dispatch(request, *args, **kwargs)
  File "/home/tech/DataIssueTracker/env/lib/python3.10/site-packages/rest_framework/views.py", line 509, in dispatch
    response = self.handle_exception(exc)
  File "/home/tech/DataIssueTracker/env/lib/python3.10/site-packages/rest_framework/views.py", line 469, in handle_exception
    self.raise_uncaught_exception(exc)
  File "/home/tech/DataIssueTracker/env/lib/python3.10/site-packages/rest_framework/views.py", line 480, in raise_uncaught_exception
    raise exc
  File "/home/tech/DataIssueTracker/env/lib/python3.10/site-packages/rest_framework/views.py", line 506, in dispatch
    response = handler(request, *args, **kwargs)
  File "/home/tech/DataIssueTracker/DITApi/DQITAuth/views.py", line 312, in get
    result_page = paginator.paginate_queryset(logs, request)
  File "/home/tech/DataIssueTracker/env/lib/python3.10/site-packages/rest_framework/pagination.py", line 387, in paginate_queryset
    self.count = self.get_count(queryset)
  File "/home/tech/DataIssueTracker/env/lib/python3.10/site-packages/rest_framework/pagination.py", line 525, in get_count
    return queryset.count()
  File "/home/tech/DataIssueTracker/env/lib/python3.10/site-packages/django/db/models/query.py", line 608, in count
    return self.query.get_count(using=self.db)
  File "/home/tech/DataIssueTracker/env/lib/python3.10/site-packages/django/db/models/sql/query.py", line 568, in get_count
    return obj.get_aggregation(using, {"__count": Count("*")})["__count"]
  File "/home/tech/DataIssueTracker/env/lib/python3.10/site-packages/django/db/models/sql/query.py", line 554, in get_aggregation
    result = compiler.execute_sql(SINGLE)
  File "/home/tech/DataIssueTracker/env/lib/python3.10/site-packages/django/db/models/sql/compiler.py", line 1562, in execute_sql
    cursor.execute(sql, params)
  File "/home/tech/DataIssueTracker/env/lib/python3.10/site-packages/django/db/backends/utils.py", line 102, in execute
    return super().execute(sql, params)
  File "/home/tech/DataIssueTracker/env/lib/python3.10/site-packages/django/db/backends/utils.py", line 67, in execute
    return self._execute_with_wrappers(
  File "/home/tech/DataIssueTracker/env/lib/python3.10/site-packages/django/db/backends/utils.py", line 80, in _execute_with_wrappers
    return executor(sql, params, many, context)
  File "/home/tech/DataIssueTracker/env/lib/python3.10/site-packages/django/db/backends/utils.py", line 84, in _execute
    with self.db.wrap_database_errors:
  File "/home/tech/DataIssueTracker/env/lib/python3.10/site-packages/django/db/utils.py", line 91, in __exit__
    raise dj_exc_value.with_traceback(traceback) from exc_value
  File "/home/tech/DataIssueTracker/env/lib/python3.10/site-packages/django/db/backends/utils.py", line 89, in _execute
    return self.cursor.execute(sql, params)
  File "/home/tech/DataIssueTracker/env/lib/python3.10/site-packages/django/db/backends/mysql/base.py", line 75, in execute
    return self.cursor.execute(query, args)
  File "/home/tech/DataIssueTracker/env/lib/python3.10/site-packages/MySQLdb/cursors.py", line 179, in execute
    res = self._query(mogrified_query)
  File "/home/tech/DataIssueTracker/env/lib/python3.10/site-packages/MySQLdb/cursors.py", line 330, in _query
    db.query(q)
  File "/home/tech/DataIssueTracker/env/lib/python3.10/site-packages/MySQLdb/connections.py", line 255, in query
    _mysql.connection.query(self, query)
django.db.utils.ProgrammingError: (1146, "Table 'dqits.DQITAuth_userlog' doesn't exist")
Internal Server Error: /api/user-logs/
Traceback (most recent call last):
  File "/home/tech/DataIssueTracker/env/lib/python3.10/site-packages/django/db/backends/utils.py", line 89, in _execute
    return self.cursor.execute(sql, params)
  File "/home/tech/DataIssueTracker/env/lib/python3.10/site-packages/django/db/backends/mysql/base.py", line 75, in execute
    return self.cursor.execute(query, args)
  File "/home/tech/DataIssueTracker/env/lib/python3.10/site-packages/MySQLdb/cursors.py", line 179, in execute
    res = self._query(mogrified_query)
  File "/home/tech/DataIssueTracker/env/lib/python3.10/site-packages/MySQLdb/cursors.py", line 330, in _query
    db.query(q)
  File "/home/tech/DataIssueTracker/env/lib/python3.10/site-packages/MySQLdb/connections.py", line 255, in query
    _mysql.connection.query(self, query)
MySQLdb.ProgrammingError: (1146, "Table 'dqits.DQITAuth_userlog' doesn't exist")

The above exception was the direct cause of the following exception:

Traceback (most recent call last):
  File "/home/tech/DataIssueTracker/env/lib/python3.10/site-packages/django/core/handlers/exception.py", line 55, in inner
    response = get_response(request)
  File "/home/tech/DataIssueTracker/env/lib/python3.10/site-packages/django/core/handlers/base.py", line 197, in _get_response
    response = wrapped_callback(request, *callback_args, **callback_kwargs)
  File "/home/tech/DataIssueTracker/env/lib/python3.10/site-packages/django/views/decorators/csrf.py", line 56, in wrapper_view
    return view_func(*args, **kwargs)
  File "/home/tech/DataIssueTracker/env/lib/python3.10/site-packages/django/views/generic/base.py", line 104, in view
    return self.dispatch(request, *args, **kwargs)
  File "/home/tech/DataIssueTracker/env/lib/python3.10/site-packages/rest_framework/views.py", line 509, in dispatch
    response = self.handle_exception(exc)
  File "/home/tech/DataIssueTracker/env/lib/python3.10/site-packages/rest_framework/views.py", line 469, in handle_exception
    self.raise_uncaught_exception(exc)
  File "/home/tech/DataIssueTracker/env/lib/python3.10/site-packages/rest_framework/views.py", line 480, in raise_uncaught_exception
    raise exc
  File "/home/tech/DataIssueTracker/env/lib/python3.10/site-packages/rest_framework/views.py", line 506, in dispatch
    response = handler(request, *args, **kwargs)
  File "/home/tech/DataIssueTracker/DITApi/DQITAuth/views.py", line 312, in get
    result_page = paginator.paginate_queryset(logs, request)
  File "/home/tech/DataIssueTracker/env/lib/python3.10/site-packages/rest_framework/pagination.py", line 387, in paginate_queryset
    self.count = self.get_count(queryset)
  File "/home/tech/DataIssueTracker/env/lib/python3.10/site-packages/rest_framework/pagination.py", line 525, in get_count
    return queryset.count()
  File "/home/tech/DataIssueTracker/env/lib/python3.10/site-packages/django/db/models/query.py", line 608, in count
    return self.query.get_count(using=self.db)
  File "/home/tech/DataIssueTracker/env/lib/python3.10/site-packages/django/db/models/sql/query.py", line 568, in get_count
    return obj.get_aggregation(using, {"__count": Count("*")})["__count"]
  File "/home/tech/DataIssueTracker/env/lib/python3.10/site-packages/django/db/models/sql/query.py", line 554, in get_aggregation
    result = compiler.execute_sql(SINGLE)
  File "/home/tech/DataIssueTracker/env/lib/python3.10/site-packages/django/db/models/sql/compiler.py", line 1562, in execute_sql
    cursor.execute(sql, params)
  File "/home/tech/DataIssueTracker/env/lib/python3.10/site-packages/django/db/backends/utils.py", line 102, in execute
    return super().execute(sql, params)
  File "/home/tech/DataIssueTracker/env/lib/python3.10/site-packages/django/db/backends/utils.py", line 67, in execute
    return self._execute_with_wrappers(
  File "/home/tech/DataIssueTracker/env/lib/python3.10/site-packages/django/db/backends/utils.py", line 80, in _execute_with_wrappers
    return executor(sql, params, many, context)
  File "/home/tech/DataIssueTracker/env/lib/python3.10/site-packages/django/db/backends/utils.py", line 84, in _execute
    with self.db.wrap_database_errors:
  File "/home/tech/DataIssueTracker/env/lib/python3.10/site-packages/django/db/utils.py", line 91, in __exit__
    raise dj_exc_value.with_traceback(traceback) from exc_value
  File "/home/tech/DataIssueTracker/env/lib/python3.10/site-packages/django/db/backends/utils.py", line 89, in _execute
    return self.cursor.execute(sql, params)
  File "/home/tech/DataIssueTracker/env/lib/python3.10/site-packages/django/db/backends/mysql/base.py", line 75, in execute
    return self.cursor.execute(query, args)
  File "/home/tech/DataIssueTracker/env/lib/python3.10/site-packages/MySQLdb/cursors.py", line 179, in execute
    res = self._query(mogrified_query)
  File "/home/tech/DataIssueTracker/env/lib/python3.10/site-packages/MySQLdb/cursors.py", line 330, in _query
    db.query(q)
  File "/home/tech/DataIssueTracker/env/lib/python3.10/site-packages/MySQLdb/connections.py", line 255, in query
    _mysql.connection.query(self, query)
django.db.utils.ProgrammingError: (1146, "Table 'dqits.DQITAuth_userlog' doesn't exist")
Internal Server Error: /api/user-logs/
Traceback (most recent call last):
  File "/home/tech/DataIssueTracker/env/lib/python3.10/site-packages/django/db/backends/utils.py", line 89, in _execute
    return self.cursor.execute(sql, params)
  File "/home/tech/DataIssueTracker/env/lib/python3.10/site-packages/django/db/backends/mysql/base.py", line 75, in execute
    return self.cursor.execute(query, args)
  File "/home/tech/DataIssueTracker/env/lib/python3.10/site-packages/MySQLdb/cursors.py", line 179, in execute
    res = self._query(mogrified_query)
  File "/home/tech/DataIssueTracker/env/lib/python3.10/site-packages/MySQLdb/cursors.py", line 330, in _query
    db.query(q)
  File "/home/tech/DataIssueTracker/env/lib/python3.10/site-packages/MySQLdb/connections.py", line 255, in query
    _mysql.connection.query(self, query)
MySQLdb.ProgrammingError: (1146, "Table 'dqits.DQITAuth_userlog' doesn't exist")

The above exception was the direct cause of the following exception:

Traceback (most recent call last):
  File "/home/tech/DataIssueTracker/env/lib/python3.10/site-packages/django/core/handlers/exception.py", line 55, in inner
    response = get_response(request)
  File "/home/tech/DataIssueTracker/env/lib/python3.10/site-packages/django/core/handlers/base.py", line 197, in _get_response
    response = wrapped_callback(request, *callback_args, **callback_kwargs)
  File "/home/tech/DataIssueTracker/env/lib/python3.10/site-packages/django/views/decorators/csrf.py", line 56, in wrapper_view
    return view_func(*args, **kwargs)
  File "/home/tech/DataIssueTracker/env/lib/python3.10/site-packages/django/views/generic/base.py", line 104, in view
    return self.dispatch(request, *args, **kwargs)
  File "/home/tech/DataIssueTracker/env/lib/python3.10/site-packages/rest_framework/views.py", line 509, in dispatch
    response = self.handle_exception(exc)
  File "/home/tech/DataIssueTracker/env/lib/python3.10/site-packages/rest_framework/views.py", line 469, in handle_exception
    self.raise_uncaught_exception(exc)
  File "/home/tech/DataIssueTracker/env/lib/python3.10/site-packages/rest_framework/views.py", line 480, in raise_uncaught_exception
    raise exc
  File "/home/tech/DataIssueTracker/env/lib/python3.10/site-packages/rest_framework/views.py", line 506, in dispatch
    response = handler(request, *args, **kwargs)
  File "/home/tech/DataIssueTracker/DITApi/DQITAuth/views.py", line 312, in get
    result_page = paginator.paginate_queryset(logs, request)
  File "/home/tech/DataIssueTracker/env/lib/python3.10/site-packages/rest_framework/pagination.py", line 387, in paginate_queryset
    self.count = self.get_count(queryset)
  File "/home/tech/DataIssueTracker/env/lib/python3.10/site-packages/rest_framework/pagination.py", line 525, in get_count
    return queryset.count()
  File "/home/tech/DataIssueTracker/env/lib/python3.10/site-packages/django/db/models/query.py", line 608, in count
    return self.query.get_count(using=self.db)
  File "/home/tech/DataIssueTracker/env/lib/python3.10/site-packages/django/db/models/sql/query.py", line 568, in get_count
    return obj.get_aggregation(using, {"__count": Count("*")})["__count"]
  File "/home/tech/DataIssueTracker/env/lib/python3.10/site-packages/django/db/models/sql/query.py", line 554, in get_aggregation
    result = compiler.execute_sql(SINGLE)
  File "/home/tech/DataIssueTracker/env/lib/python3.10/site-packages/django/db/models/sql/compiler.py", line 1562, in execute_sql
    cursor.execute(sql, params)
  File "/home/tech/DataIssueTracker/env/lib/python3.10/site-packages/django/db/backends/utils.py", line 102, in execute
    return super().execute(sql, params)
  File "/home/tech/DataIssueTracker/env/lib/python3.10/site-packages/django/db/backends/utils.py", line 67, in execute
    return self._execute_with_wrappers(
  File "/home/tech/DataIssueTracker/env/lib/python3.10/site-packages/django/db/backends/utils.py", line 80, in _execute_with_wrappers
    return executor(sql, params, many, context)
  File "/home/tech/DataIssueTracker/env/lib/python3.10/site-packages/django/db/backends/utils.py", line 84, in _execute
    with self.db.wrap_database_errors:
  File "/home/tech/DataIssueTracker/env/lib/python3.10/site-packages/django/db/utils.py", line 91, in __exit__
    raise dj_exc_value.with_traceback(traceback) from exc_value
  File "/home/tech/DataIssueTracker/env/lib/python3.10/site-packages/django/db/backends/utils.py", line 89, in _execute
    return self.cursor.execute(sql, params)
  File "/home/tech/DataIssueTracker/env/lib/python3.10/site-packages/django/db/backends/mysql/base.py", line 75, in execute
    return self.cursor.execute(query, args)
  File "/home/tech/DataIssueTracker/env/lib/python3.10/site-packages/MySQLdb/cursors.py", line 179, in execute
    res = self._query(mogrified_query)
  File "/home/tech/DataIssueTracker/env/lib/python3.10/site-packages/MySQLdb/cursors.py", line 330, in _query
    db.query(q)
  File "/home/tech/DataIssueTracker/env/lib/python3.10/site-packages/MySQLdb/connections.py", line 255, in query
    _mysql.connection.query(self, query)
django.db.utils.ProgrammingError: (1146, "Table 'dqits.DQITAuth_userlog' doesn't exist")
Internal Server Error: /api/user-logs/
Traceback (most recent call last):
  File "/home/tech/DataIssueTracker/env/lib/python3.10/site-packages/django/db/backends/utils.py", line 89, in _execute
    return self.cursor.execute(sql, params)
  File "/home/tech/DataIssueTracker/env/lib/python3.10/site-packages/django/db/backends/mysql/base.py", line 75, in execute
    return self.cursor.execute(query, args)
  File "/home/tech/DataIssueTracker/env/lib/python3.10/site-packages/MySQLdb/cursors.py", line 179, in execute
    res = self._query(mogrified_query)
  File "/home/tech/DataIssueTracker/env/lib/python3.10/site-packages/MySQLdb/cursors.py", line 330, in _query
    db.query(q)
  File "/home/tech/DataIssueTracker/env/lib/python3.10/site-packages/MySQLdb/connections.py", line 255, in query
    _mysql.connection.query(self, query)
MySQLdb.ProgrammingError: (1146, "Table 'dqits.DQITAuth_userlog' doesn't exist")

The above exception was the direct cause of the following exception:

Traceback (most recent call last):
  File "/home/tech/DataIssueTracker/env/lib/python3.10/site-packages/django/core/handlers/exception.py", line 55, in inner
    response = get_response(request)
  File "/home/tech/DataIssueTracker/env/lib/python3.10/site-packages/django/core/handlers/base.py", line 197, in _get_response
    response = wrapped_callback(request, *callback_args, **callback_kwargs)
  File "/home/tech/DataIssueTracker/env/lib/python3.10/site-packages/django/views/decorators/csrf.py", line 56, in wrapper_view
    return view_func(*args, **kwargs)
  File "/home/tech/DataIssueTracker/env/lib/python3.10/site-packages/django/views/generic/base.py", line 104, in view
    return self.dispatch(request, *args, **kwargs)
  File "/home/tech/DataIssueTracker/env/lib/python3.10/site-packages/rest_framework/views.py", line 509, in dispatch
    response = self.handle_exception(exc)
  File "/home/tech/DataIssueTracker/env/lib/python3.10/site-packages/rest_framework/views.py", line 469, in handle_exception
    self.raise_uncaught_exception(exc)
  File "/home/tech/DataIssueTracker/env/lib/python3.10/site-packages/rest_framework/views.py", line 480, in raise_uncaught_exception
    raise exc
  File "/home/tech/DataIssueTracker/env/lib/python3.10/site-packages/rest_framework/views.py", line 506, in dispatch
    response = handler(request, *args, **kwargs)
  File "/home/tech/DataIssueTracker/DITApi/DQITAuth/views.py", line 312, in get
    result_page = paginator.paginate_queryset(logs, request)
  File "/home/tech/DataIssueTracker/env/lib/python3.10/site-packages/rest_framework/pagination.py", line 387, in paginate_queryset
    self.count = self.get_count(queryset)
  File "/home/tech/DataIssueTracker/env/lib/python3.10/site-packages/rest_framework/pagination.py", line 525, in get_count
    return queryset.count()
  File "/home/tech/DataIssueTracker/env/lib/python3.10/site-packages/django/db/models/query.py", line 608, in count
    return self.query.get_count(using=self.db)
  File "/home/tech/DataIssueTracker/env/lib/python3.10/site-packages/django/db/models/sql/query.py", line 568, in get_count
    return obj.get_aggregation(using, {"__count": Count("*")})["__count"]
  File "/home/tech/DataIssueTracker/env/lib/python3.10/site-packages/django/db/models/sql/query.py", line 554, in get_aggregation
    result = compiler.execute_sql(SINGLE)
  File "/home/tech/DataIssueTracker/env/lib/python3.10/site-packages/django/db/models/sql/compiler.py", line 1562, in execute_sql
    cursor.execute(sql, params)
  File "/home/tech/DataIssueTracker/env/lib/python3.10/site-packages/django/db/backends/utils.py", line 102, in execute
    return super().execute(sql, params)
  File "/home/tech/DataIssueTracker/env/lib/python3.10/site-packages/django/db/backends/utils.py", line 67, in execute
    return self._execute_with_wrappers(
  File "/home/tech/DataIssueTracker/env/lib/python3.10/site-packages/django/db/backends/utils.py", line 80, in _execute_with_wrappers
    return executor(sql, params, many, context)
  File "/home/tech/DataIssueTracker/env/lib/python3.10/site-packages/django/db/backends/utils.py", line 84, in _execute
    with self.db.wrap_database_errors:
  File "/home/tech/DataIssueTracker/env/lib/python3.10/site-packages/django/db/utils.py", line 91, in __exit__
    raise dj_exc_value.with_traceback(traceback) from exc_value
  File "/home/tech/DataIssueTracker/env/lib/python3.10/site-packages/django/db/backends/utils.py", line 89, in _execute
    return self.cursor.execute(sql, params)
  File "/home/tech/DataIssueTracker/env/lib/python3.10/site-packages/django/db/backends/mysql/base.py", line 75, in execute
    return self.cursor.execute(query, args)
  File "/home/tech/DataIssueTracker/env/lib/python3.10/site-packages/MySQLdb/cursors.py", line 179, in execute
    res = self._query(mogrified_query)
  File "/home/tech/DataIssueTracker/env/lib/python3.10/site-packages/MySQLdb/cursors.py", line 330, in _query
    db.query(q)
  File "/home/tech/DataIssueTracker/env/lib/python3.10/site-packages/MySQLdb/connections.py", line 255, in query
    _mysql.connection.query(self, query)
django.db.utils.ProgrammingError: (1146, "Table 'dqits.DQITAuth_userlog' doesn't exist")
Internal Server Error: /api/user-logs/
Traceback (most recent call last):
  File "/home/tech/DataIssueTracker/env/lib/python3.10/site-packages/django/db/backends/utils.py", line 89, in _execute
    return self.cursor.execute(sql, params)
  File "/home/tech/DataIssueTracker/env/lib/python3.10/site-packages/django/db/backends/mysql/base.py", line 75, in execute
    return self.cursor.execute(query, args)
  File "/home/tech/DataIssueTracker/env/lib/python3.10/site-packages/MySQLdb/cursors.py", line 179, in execute
    res = self._query(mogrified_query)
  File "/home/tech/DataIssueTracker/env/lib/python3.10/site-packages/MySQLdb/cursors.py", line 330, in _query
    db.query(q)
  File "/home/tech/DataIssueTracker/env/lib/python3.10/site-packages/MySQLdb/connections.py", line 255, in query
    _mysql.connection.query(self, query)
MySQLdb.ProgrammingError: (1146, "Table 'dqits.DQITAuth_userlog' doesn't exist")

The above exception was the direct cause of the following exception:

Traceback (most recent call last):
  File "/home/tech/DataIssueTracker/env/lib/python3.10/site-packages/django/core/handlers/exception.py", line 55, in inner
    response = get_response(request)
  File "/home/tech/DataIssueTracker/env/lib/python3.10/site-packages/django/core/handlers/base.py", line 197, in _get_response
    response = wrapped_callback(request, *callback_args, **callback_kwargs)
  File "/home/tech/DataIssueTracker/env/lib/python3.10/site-packages/django/views/decorators/csrf.py", line 56, in wrapper_view
    return view_func(*args, **kwargs)
  File "/home/tech/DataIssueTracker/env/lib/python3.10/site-packages/django/views/generic/base.py", line 104, in view
    return self.dispatch(request, *args, **kwargs)
  File "/home/tech/DataIssueTracker/env/lib/python3.10/site-packages/rest_framework/views.py", line 509, in dispatch
    response = self.handle_exception(exc)
  File "/home/tech/DataIssueTracker/env/lib/python3.10/site-packages/rest_framework/views.py", line 469, in handle_exception
    self.raise_uncaught_exception(exc)
  File "/home/tech/DataIssueTracker/env/lib/python3.10/site-packages/rest_framework/views.py", line 480, in raise_uncaught_exception
    raise exc
  File "/home/tech/DataIssueTracker/env/lib/python3.10/site-packages/rest_framework/views.py", line 506, in dispatch
    response = handler(request, *args, **kwargs)
  File "/home/tech/DataIssueTracker/DITApi/DQITAuth/views.py", line 312, in get
    result_page = paginator.paginate_queryset(logs, request)
  File "/home/tech/DataIssueTracker/env/lib/python3.10/site-packages/rest_framework/pagination.py", line 387, in paginate_queryset
    self.count = self.get_count(queryset)
  File "/home/tech/DataIssueTracker/env/lib/python3.10/site-packages/rest_framework/pagination.py", line 525, in get_count
    return queryset.count()
  File "/home/tech/DataIssueTracker/env/lib/python3.10/site-packages/django/db/models/query.py", line 608, in count
    return self.query.get_count(using=self.db)
  File "/home/tech/DataIssueTracker/env/lib/python3.10/site-packages/django/db/models/sql/query.py", line 568, in get_count
    return obj.get_aggregation(using, {"__count": Count("*")})["__count"]
  File "/home/tech/DataIssueTracker/env/lib/python3.10/site-packages/django/db/models/sql/query.py", line 554, in get_aggregation
    result = compiler.execute_sql(SINGLE)
  File "/home/tech/DataIssueTracker/env/lib/python3.10/site-packages/django/db/models/sql/compiler.py", line 1562, in execute_sql
    cursor.execute(sql, params)
  File "/home/tech/DataIssueTracker/env/lib/python3.10/site-packages/django/db/backends/utils.py", line 102, in execute
    return super().execute(sql, params)
  File "/home/tech/DataIssueTracker/env/lib/python3.10/site-packages/django/db/backends/utils.py", line 67, in execute
    return self._execute_with_wrappers(
  File "/home/tech/DataIssueTracker/env/lib/python3.10/site-packages/django/db/backends/utils.py", line 80, in _execute_with_wrappers
    return executor(sql, params, many, context)
  File "/home/tech/DataIssueTracker/env/lib/python3.10/site-packages/django/db/backends/utils.py", line 84, in _execute
    with self.db.wrap_database_errors:
  File "/home/tech/DataIssueTracker/env/lib/python3.10/site-packages/django/db/utils.py", line 91, in __exit__
    raise dj_exc_value.with_traceback(traceback) from exc_value
  File "/home/tech/DataIssueTracker/env/lib/python3.10/site-packages/django/db/backends/utils.py", line 89, in _execute
    return self.cursor.execute(sql, params)
  File "/home/tech/DataIssueTracker/env/lib/python3.10/site-packages/django/db/backends/mysql/base.py", line 75, in execute
    return self.cursor.execute(query, args)
  File "/home/tech/DataIssueTracker/env/lib/python3.10/site-packages/MySQLdb/cursors.py", line 179, in execute
    res = self._query(mogrified_query)
  File "/home/tech/DataIssueTracker/env/lib/python3.10/site-packages/MySQLdb/cursors.py", line 330, in _query
    db.query(q)
  File "/home/tech/DataIssueTracker/env/lib/python3.10/site-packages/MySQLdb/connections.py", line 255, in query
    _mysql.connection.query(self, query)
django.db.utils.ProgrammingError: (1146, "Table 'dqits.DQITAuth_userlog' doesn't exist")
[2023-10-29 16:00:34 +0000] [109366] [CRITICAL] WORKER TIMEOUT (pid:109508)
[2023-10-29 19:00:34 +0300] [109508] [INFO] Worker exiting (pid: 109508)
[2023-10-29 16:00:34 +0000] [109366] [ERROR] Worker (pid:109508) exited with code 1
[2023-10-29 16:00:34 +0000] [109366] [ERROR] Worker (pid:109508) exited with code 1.
[2023-10-29 16:00:34 +0000] [109924] [INFO] Booting worker with pid: 109924
Method Not Allowed: /api/sync_data/
[2023-10-29 19:21:23 +0300] [109924] [INFO] Parent changed, shutting down: <Worker 109924>
[2023-10-29 19:21:23 +0300] [109924] [INFO] Worker exiting (pid: 109924)
[2023-10-29 16:22:57 +0000] [110582] [INFO] Starting gunicorn 21.2.0
[2023-10-29 16:22:57 +0000] [110582] [INFO] Listening at: http://0.0.0.0:8000 (110582)
[2023-10-29 16:22:57 +0000] [110582] [INFO] Using worker: sync
[2023-10-29 16:22:57 +0000] [110583] [INFO] Booting worker with pid: 110583
Method Not Allowed: /api/sync_data/
[2023-10-29 16:32:50 +0000] [110582] [INFO] Handling signal: hup
[2023-10-29 16:32:50 +0000] [110582] [INFO] Hang up: Master
[2023-10-29 19:32:50 +0300] [110583] [INFO] Worker exiting (pid: 110583)
[2023-10-29 16:32:50 +0000] [110851] [INFO] Booting worker with pid: 110851
[2023-10-29 16:32:50 +0000] [110582] [ERROR] Worker (pid:110583) was sent SIGTERM!
[2023-10-29 16:33:20 +0000] [110582] [ERROR] Worker (pid:110851) was sent SIGHUP!
[2023-10-29 16:33:20 +0000] [110860] [INFO] Booting worker with pid: 110860
Method Not Allowed: /api/sync_data/
[2023-10-29 16:41:21 +0000] [110582] [CRITICAL] WORKER TIMEOUT (pid:110860)
[2023-10-29 19:41:21 +0300] [110860] [INFO] Worker exiting (pid: 110860)
[2023-10-29 16:41:21 +0000] [110582] [ERROR] Worker (pid:110860) exited with code 1
[2023-10-29 16:41:21 +0000] [110582] [ERROR] Worker (pid:110860) exited with code 1.
[2023-10-29 16:41:21 +0000] [111132] [INFO] Booting worker with pid: 111132
Unauthorized: /api/analytics/
Unauthorized: /api/data_issue_stats/
Unauthorized: /api/data_issues/
Unauthorized: /api/user-logs/
Unauthorized: /api/facilities/
Unauthorized: /api/analytics/
Unauthorized: /api/data_issues/
Unauthorized: /api/data_issue_stats/
Unauthorized: /api/user-logs/
Unauthorized: /api/facilities/
Unauthorized: /api/analytics/
Unauthorized: /api/data_issue_stats/
Unauthorized: /api/data_issues/
Unauthorized: /api/facilities/
Unauthorized: /api/user-logs/
Unauthorized: /api/facilities/
Unauthorized: /api/data_issues/
Unauthorized: /api/analytics/
Unauthorized: /api/data_issues/
Unauthorized: /api/data_issue_stats/
Unauthorized: /api/facilities/
Unauthorized: /api/user-logs/
Internal Server Error: /api/user-logs/
Traceback (most recent call last):
  File "/home/tech/DataIssueTracker/env/lib/python3.10/site-packages/django/db/backends/utils.py", line 89, in _execute
    return self.cursor.execute(sql, params)
  File "/home/tech/DataIssueTracker/env/lib/python3.10/site-packages/django/db/backends/mysql/base.py", line 75, in execute
    return self.cursor.execute(query, args)
  File "/home/tech/DataIssueTracker/env/lib/python3.10/site-packages/MySQLdb/cursors.py", line 179, in execute
    res = self._query(mogrified_query)
  File "/home/tech/DataIssueTracker/env/lib/python3.10/site-packages/MySQLdb/cursors.py", line 330, in _query
    db.query(q)
  File "/home/tech/DataIssueTracker/env/lib/python3.10/site-packages/MySQLdb/connections.py", line 255, in query
    _mysql.connection.query(self, query)
MySQLdb.ProgrammingError: (1146, "Table 'dqits.DQITAuth_userlog' doesn't exist")

The above exception was the direct cause of the following exception:

Traceback (most recent call last):
  File "/home/tech/DataIssueTracker/env/lib/python3.10/site-packages/django/core/handlers/exception.py", line 55, in inner
    response = get_response(request)
  File "/home/tech/DataIssueTracker/env/lib/python3.10/site-packages/django/core/handlers/base.py", line 197, in _get_response
    response = wrapped_callback(request, *callback_args, **callback_kwargs)
  File "/home/tech/DataIssueTracker/env/lib/python3.10/site-packages/django/views/decorators/csrf.py", line 56, in wrapper_view
    return view_func(*args, **kwargs)
  File "/home/tech/DataIssueTracker/env/lib/python3.10/site-packages/django/views/generic/base.py", line 104, in view
    return self.dispatch(request, *args, **kwargs)
  File "/home/tech/DataIssueTracker/env/lib/python3.10/site-packages/rest_framework/views.py", line 509, in dispatch
    response = self.handle_exception(exc)
  File "/home/tech/DataIssueTracker/env/lib/python3.10/site-packages/rest_framework/views.py", line 469, in handle_exception
    self.raise_uncaught_exception(exc)
  File "/home/tech/DataIssueTracker/env/lib/python3.10/site-packages/rest_framework/views.py", line 480, in raise_uncaught_exception
    raise exc
  File "/home/tech/DataIssueTracker/env/lib/python3.10/site-packages/rest_framework/views.py", line 506, in dispatch
    response = handler(request, *args, **kwargs)
  File "/home/tech/DataIssueTracker/DITApi/DQITAuth/views.py", line 312, in get
    result_page = paginator.paginate_queryset(logs, request)
  File "/home/tech/DataIssueTracker/env/lib/python3.10/site-packages/rest_framework/pagination.py", line 387, in paginate_queryset
    self.count = self.get_count(queryset)
  File "/home/tech/DataIssueTracker/env/lib/python3.10/site-packages/rest_framework/pagination.py", line 525, in get_count
    return queryset.count()
  File "/home/tech/DataIssueTracker/env/lib/python3.10/site-packages/django/db/models/query.py", line 608, in count
    return self.query.get_count(using=self.db)
  File "/home/tech/DataIssueTracker/env/lib/python3.10/site-packages/django/db/models/sql/query.py", line 568, in get_count
    return obj.get_aggregation(using, {"__count": Count("*")})["__count"]
  File "/home/tech/DataIssueTracker/env/lib/python3.10/site-packages/django/db/models/sql/query.py", line 554, in get_aggregation
    result = compiler.execute_sql(SINGLE)
  File "/home/tech/DataIssueTracker/env/lib/python3.10/site-packages/django/db/models/sql/compiler.py", line 1562, in execute_sql
    cursor.execute(sql, params)
  File "/home/tech/DataIssueTracker/env/lib/python3.10/site-packages/django/db/backends/utils.py", line 102, in execute
    return super().execute(sql, params)
  File "/home/tech/DataIssueTracker/env/lib/python3.10/site-packages/django/db/backends/utils.py", line 67, in execute
    return self._execute_with_wrappers(
  File "/home/tech/DataIssueTracker/env/lib/python3.10/site-packages/django/db/backends/utils.py", line 80, in _execute_with_wrappers
    return executor(sql, params, many, context)
  File "/home/tech/DataIssueTracker/env/lib/python3.10/site-packages/django/db/backends/utils.py", line 84, in _execute
    with self.db.wrap_database_errors:
  File "/home/tech/DataIssueTracker/env/lib/python3.10/site-packages/django/db/utils.py", line 91, in __exit__
    raise dj_exc_value.with_traceback(traceback) from exc_value
  File "/home/tech/DataIssueTracker/env/lib/python3.10/site-packages/django/db/backends/utils.py", line 89, in _execute
    return self.cursor.execute(sql, params)
  File "/home/tech/DataIssueTracker/env/lib/python3.10/site-packages/django/db/backends/mysql/base.py", line 75, in execute
    return self.cursor.execute(query, args)
  File "/home/tech/DataIssueTracker/env/lib/python3.10/site-packages/MySQLdb/cursors.py", line 179, in execute
    res = self._query(mogrified_query)
  File "/home/tech/DataIssueTracker/env/lib/python3.10/site-packages/MySQLdb/cursors.py", line 330, in _query
    db.query(q)
  File "/home/tech/DataIssueTracker/env/lib/python3.10/site-packages/MySQLdb/connections.py", line 255, in query
    _mysql.connection.query(self, query)
django.db.utils.ProgrammingError: (1146, "Table 'dqits.DQITAuth_userlog' doesn't exist")
Internal Server Error: /api/user-logs/
Traceback (most recent call last):
  File "/home/tech/DataIssueTracker/env/lib/python3.10/site-packages/django/db/backends/utils.py", line 89, in _execute
    return self.cursor.execute(sql, params)
  File "/home/tech/DataIssueTracker/env/lib/python3.10/site-packages/django/db/backends/mysql/base.py", line 75, in execute
    return self.cursor.execute(query, args)
  File "/home/tech/DataIssueTracker/env/lib/python3.10/site-packages/MySQLdb/cursors.py", line 179, in execute
    res = self._query(mogrified_query)
  File "/home/tech/DataIssueTracker/env/lib/python3.10/site-packages/MySQLdb/cursors.py", line 330, in _query
    db.query(q)
  File "/home/tech/DataIssueTracker/env/lib/python3.10/site-packages/MySQLdb/connections.py", line 255, in query
    _mysql.connection.query(self, query)
MySQLdb.ProgrammingError: (1146, "Table 'dqits.DQITAuth_userlog' doesn't exist")

The above exception was the direct cause of the following exception:

Traceback (most recent call last):
  File "/home/tech/DataIssueTracker/env/lib/python3.10/site-packages/django/core/handlers/exception.py", line 55, in inner
    response = get_response(request)
  File "/home/tech/DataIssueTracker/env/lib/python3.10/site-packages/django/core/handlers/base.py", line 197, in _get_response
    response = wrapped_callback(request, *callback_args, **callback_kwargs)
  File "/home/tech/DataIssueTracker/env/lib/python3.10/site-packages/django/views/decorators/csrf.py", line 56, in wrapper_view
    return view_func(*args, **kwargs)
  File "/home/tech/DataIssueTracker/env/lib/python3.10/site-packages/django/views/generic/base.py", line 104, in view
    return self.dispatch(request, *args, **kwargs)
  File "/home/tech/DataIssueTracker/env/lib/python3.10/site-packages/rest_framework/views.py", line 509, in dispatch
    response = self.handle_exception(exc)
  File "/home/tech/DataIssueTracker/env/lib/python3.10/site-packages/rest_framework/views.py", line 469, in handle_exception
    self.raise_uncaught_exception(exc)
  File "/home/tech/DataIssueTracker/env/lib/python3.10/site-packages/rest_framework/views.py", line 480, in raise_uncaught_exception
    raise exc
  File "/home/tech/DataIssueTracker/env/lib/python3.10/site-packages/rest_framework/views.py", line 506, in dispatch
    response = handler(request, *args, **kwargs)
  File "/home/tech/DataIssueTracker/DITApi/DQITAuth/views.py", line 312, in get
    result_page = paginator.paginate_queryset(logs, request)
  File "/home/tech/DataIssueTracker/env/lib/python3.10/site-packages/rest_framework/pagination.py", line 387, in paginate_queryset
    self.count = self.get_count(queryset)
  File "/home/tech/DataIssueTracker/env/lib/python3.10/site-packages/rest_framework/pagination.py", line 525, in get_count
    return queryset.count()
  File "/home/tech/DataIssueTracker/env/lib/python3.10/site-packages/django/db/models/query.py", line 608, in count
    return self.query.get_count(using=self.db)
  File "/home/tech/DataIssueTracker/env/lib/python3.10/site-packages/django/db/models/sql/query.py", line 568, in get_count
    return obj.get_aggregation(using, {"__count": Count("*")})["__count"]
  File "/home/tech/DataIssueTracker/env/lib/python3.10/site-packages/django/db/models/sql/query.py", line 554, in get_aggregation
    result = compiler.execute_sql(SINGLE)
  File "/home/tech/DataIssueTracker/env/lib/python3.10/site-packages/django/db/models/sql/compiler.py", line 1562, in execute_sql
    cursor.execute(sql, params)
  File "/home/tech/DataIssueTracker/env/lib/python3.10/site-packages/django/db/backends/utils.py", line 102, in execute
    return super().execute(sql, params)
  File "/home/tech/DataIssueTracker/env/lib/python3.10/site-packages/django/db/backends/utils.py", line 67, in execute
    return self._execute_with_wrappers(
  File "/home/tech/DataIssueTracker/env/lib/python3.10/site-packages/django/db/backends/utils.py", line 80, in _execute_with_wrappers
    return executor(sql, params, many, context)
  File "/home/tech/DataIssueTracker/env/lib/python3.10/site-packages/django/db/backends/utils.py", line 84, in _execute
    with self.db.wrap_database_errors:
  File "/home/tech/DataIssueTracker/env/lib/python3.10/site-packages/django/db/utils.py", line 91, in __exit__
    raise dj_exc_value.with_traceback(traceback) from exc_value
  File "/home/tech/DataIssueTracker/env/lib/python3.10/site-packages/django/db/backends/utils.py", line 89, in _execute
    return self.cursor.execute(sql, params)
  File "/home/tech/DataIssueTracker/env/lib/python3.10/site-packages/django/db/backends/mysql/base.py", line 75, in execute
    return self.cursor.execute(query, args)
  File "/home/tech/DataIssueTracker/env/lib/python3.10/site-packages/MySQLdb/cursors.py", line 179, in execute
    res = self._query(mogrified_query)
  File "/home/tech/DataIssueTracker/env/lib/python3.10/site-packages/MySQLdb/cursors.py", line 330, in _query
    db.query(q)
  File "/home/tech/DataIssueTracker/env/lib/python3.10/site-packages/MySQLdb/connections.py", line 255, in query
    _mysql.connection.query(self, query)
django.db.utils.ProgrammingError: (1146, "Table 'dqits.DQITAuth_userlog' doesn't exist")
Not Found: /api/null
Not Found: /api/null
Not Found: /api/null
Not Found: /api//media/profiles/logo.png
Not Found: /api//media/profiles/logo.png
Not Found: /api/media/profiles/logo.png
