[2023-10-29 14:32:01 +0000] [107971] [INFO] Starting gunicorn 21.2.0
[2023-10-29 14:32:01 +0000] [107971] [INFO] Listening at: http://0.0.0.0:8000 (107971)
[2023-10-29 14:32:01 +0000] [107971] [INFO] Using worker: sync
[2023-10-29 14:32:01 +0000] [107972] [INFO] Booting worker with pid: 107972
[2023-10-29 14:32:06 +0000] [107971] [INFO] Handling signal: int
[2023-10-29 14:32:06 +0000] [107971] [INFO] Shutting down: Master
[2023-10-29 14:32:36 +0000] [107976] [INFO] Starting gunicorn 21.2.0
[2023-10-29 14:32:36 +0000] [107976] [INFO] Listening at: http://0.0.0.0:8000 (107976)
[2023-10-29 14:32:36 +0000] [107976] [INFO] Using worker: sync
[2023-10-29 14:32:36 +0000] [107977] [INFO] Booting worker with pid: 107977
[2023-10-29 17:33:36 +0300] [107977] [ERROR] Error handling request /admin/DQITAuth/customuser/1/change/
Traceback (most recent call last):
  File "/home/tech/DataIssueTracker/env/lib/python3.10/site-packages/django/core/handlers/exception.py", line 55, in inner
    response = get_response(request)
  File "/home/tech/DataIssueTracker/env/lib/python3.10/site-packages/django/core/handlers/base.py", line 181, in _get_response
    callback, callback_args, callback_kwargs = self.resolve_request(request)
  File "/home/tech/DataIssueTracker/env/lib/python3.10/site-packages/django/core/handlers/base.py", line 313, in resolve_request
    resolver_match = resolver.resolve(request.path_info)
  File "/home/tech/DataIssueTracker/env/lib/python3.10/site-packages/django/urls/resolvers.py", line 663, in resolve
    for pattern in self.url_patterns:
  File "/home/tech/DataIssueTracker/env/lib/python3.10/site-packages/django/utils/functional.py", line 57, in __get__
    res = instance.__dict__[self.name] = self.func(instance)
  File "/home/tech/DataIssueTracker/env/lib/python3.10/site-packages/django/urls/resolvers.py", line 715, in url_patterns
    patterns = getattr(self.urlconf_module, "urlpatterns", self.urlconf_module)
  File "/home/tech/DataIssueTracker/env/lib/python3.10/site-packages/django/utils/functional.py", line 57, in __get__
    res = instance.__dict__[self.name] = self.func(instance)
  File "/home/tech/DataIssueTracker/env/lib/python3.10/site-packages/django/urls/resolvers.py", line 708, in urlconf_module
    return import_module(self.urlconf_name)
  File "/usr/lib/python3.10/importlib/__init__.py", line 126, in import_module
    return _bootstrap._gcd_import(name[level:], package, level)
  File "<frozen importlib._bootstrap>", line 1050, in _gcd_import
  File "<frozen importlib._bootstrap>", line 1027, in _find_and_load
  File "<frozen importlib._bootstrap>", line 1006, in _find_and_load_unlocked
  File "<frozen importlib._bootstrap>", line 688, in _load_unlocked
  File "<frozen importlib._bootstrap_external>", line 883, in exec_module
  File "<frozen importlib._bootstrap>", line 241, in _call_with_frames_removed
  File "/home/tech/DataIssueTracker/DITApi/DITApi/urls.py", line 27, in <module>
    path('api/',include('DQITAuth.urls')),
  File "/home/tech/DataIssueTracker/env/lib/python3.10/site-packages/django/urls/conf.py", line 38, in include
    urlconf_module = import_module(urlconf_module)
  File "/usr/lib/python3.10/importlib/__init__.py", line 126, in import_module
    return _bootstrap._gcd_import(name[level:], package, level)
  File "<frozen importlib._bootstrap>", line 1050, in _gcd_import
  File "<frozen importlib._bootstrap>", line 1027, in _find_and_load
  File "<frozen importlib._bootstrap>", line 1006, in _find_and_load_unlocked
  File "<frozen importlib._bootstrap>", line 688, in _load_unlocked
  File "<frozen importlib._bootstrap_external>", line 883, in exec_module
  File "<frozen importlib._bootstrap>", line 241, in _call_with_frames_removed
  File "/home/tech/DataIssueTracker/DITApi/DQITAuth/urls.py", line 3, in <module>
    from .views import (
  File "/home/tech/DataIssueTracker/DITApi/DQITAuth/views.py", line 88
    role = user.role.role_name if user.role else None
IndentationError: expected an indented block after 'except' statement on line 84

During handling of the above exception, another exception occurred:

Traceback (most recent call last):
  File "/home/tech/DataIssueTracker/env/lib/python3.10/site-packages/django/core/handlers/exception.py", line 55, in inner
    response = get_response(request)
  File "/home/tech/DataIssueTracker/DITApi/DQITAuth/middleware.py", line 14, in __call__
    response = self.get_response(request)
  File "/home/tech/DataIssueTracker/env/lib/python3.10/site-packages/django/core/handlers/exception.py", line 57, in inner
    response = response_for_exception(request, exc)
  File "/home/tech/DataIssueTracker/env/lib/python3.10/site-packages/django/core/handlers/exception.py", line 140, in response_for_exception
    response = handle_uncaught_exception(
  File "/home/tech/DataIssueTracker/env/lib/python3.10/site-packages/django/core/handlers/exception.py", line 181, in handle_uncaught_exception
    return debug.technical_500_response(request, *exc_info)
  File "/home/tech/DataIssueTracker/env/lib/python3.10/site-packages/django/views/debug.py", line 67, in technical_500_response
    html = reporter.get_traceback_html()
  File "/home/tech/DataIssueTracker/env/lib/python3.10/site-packages/django/views/debug.py", line 410, in get_traceback_html
    c = Context(self.get_traceback_data(), use_l10n=False)
  File "/home/tech/DataIssueTracker/env/lib/python3.10/site-packages/django/views/debug.py", line 393, in get_traceback_data
    c["raising_view_name"] = get_caller(self.request)
  File "/home/tech/DataIssueTracker/env/lib/python3.10/site-packages/django/views/debug.py", line 100, in get_caller
    resolver_match = resolve(request.path)
  File "/home/tech/DataIssueTracker/env/lib/python3.10/site-packages/django/urls/base.py", line 24, in resolve
    return get_resolver(urlconf).resolve(path)
  File "/home/tech/DataIssueTracker/env/lib/python3.10/site-packages/django/urls/resolvers.py", line 663, in resolve
    for pattern in self.url_patterns:
  File "/home/tech/DataIssueTracker/env/lib/python3.10/site-packages/django/utils/functional.py", line 57, in __get__
    res = instance.__dict__[self.name] = self.func(instance)
  File "/home/tech/DataIssueTracker/env/lib/python3.10/site-packages/django/urls/resolvers.py", line 715, in url_patterns
    patterns = getattr(self.urlconf_module, "urlpatterns", self.urlconf_module)
  File "/home/tech/DataIssueTracker/env/lib/python3.10/site-packages/django/utils/functional.py", line 57, in __get__
    res = instance.__dict__[self.name] = self.func(instance)
  File "/home/tech/DataIssueTracker/env/lib/python3.10/site-packages/django/urls/resolvers.py", line 708, in urlconf_module
    return import_module(self.urlconf_name)
  File "/usr/lib/python3.10/importlib/__init__.py", line 126, in import_module
    return _bootstrap._gcd_import(name[level:], package, level)
  File "<frozen importlib._bootstrap>", line 1050, in _gcd_import
  File "<frozen importlib._bootstrap>", line 1027, in _find_and_load
  File "<frozen importlib._bootstrap>", line 1006, in _find_and_load_unlocked
  File "<frozen importlib._bootstrap>", line 688, in _load_unlocked
  File "<frozen importlib._bootstrap_external>", line 883, in exec_module
  File "<frozen importlib._bootstrap>", line 241, in _call_with_frames_removed
  File "/home/tech/DataIssueTracker/DITApi/DITApi/urls.py", line 27, in <module>
    path('api/',include('DQITAuth.urls')),
  File "/home/tech/DataIssueTracker/env/lib/python3.10/site-packages/django/urls/conf.py", line 38, in include
    urlconf_module = import_module(urlconf_module)
  File "/usr/lib/python3.10/importlib/__init__.py", line 126, in import_module
    return _bootstrap._gcd_import(name[level:], package, level)
  File "<frozen importlib._bootstrap>", line 1050, in _gcd_import
  File "<frozen importlib._bootstrap>", line 1027, in _find_and_load
  File "<frozen importlib._bootstrap>", line 1006, in _find_and_load_unlocked
  File "<frozen importlib._bootstrap>", line 688, in _load_unlocked
  File "<frozen importlib._bootstrap_external>", line 883, in exec_module
  File "<frozen importlib._bootstrap>", line 241, in _call_with_frames_removed
  File "/home/tech/DataIssueTracker/DITApi/DQITAuth/urls.py", line 3, in <module>
    from .views import (
  File "/home/tech/DataIssueTracker/DITApi/DQITAuth/views.py", line 88
    role = user.role.role_name if user.role else None
IndentationError: expected an indented block after 'except' statement on line 84

During handling of the above exception, another exception occurred:

Traceback (most recent call last):
  File "/home/tech/DataIssueTracker/env/lib/python3.10/site-packages/django/core/handlers/exception.py", line 55, in inner
    response = get_response(request)
  File "/home/tech/DataIssueTracker/env/lib/python3.10/site-packages/django/utils/deprecation.py", line 134, in __call__
    response = response or self.get_response(request)
  File "/home/tech/DataIssueTracker/env/lib/python3.10/site-packages/django/core/handlers/exception.py", line 57, in inner
    response = response_for_exception(request, exc)
  File "/home/tech/DataIssueTracker/env/lib/python3.10/site-packages/django/core/handlers/exception.py", line 140, in response_for_exception
    response = handle_uncaught_exception(
  File "/home/tech/DataIssueTracker/env/lib/python3.10/site-packages/django/core/handlers/exception.py", line 181, in handle_uncaught_exception
    return debug.technical_500_response(request, *exc_info)
  File "/home/tech/DataIssueTracker/env/lib/python3.10/site-packages/django/views/debug.py", line 67, in technical_500_response
    html = reporter.get_traceback_html()
  File "/home/tech/DataIssueTracker/env/lib/python3.10/site-packages/django/views/debug.py", line 410, in get_traceback_html
    c = Context(self.get_traceback_data(), use_l10n=False)
  File "/home/tech/DataIssueTracker/env/lib/python3.10/site-packages/django/views/debug.py", line 393, in get_traceback_data
    c["raising_view_name"] = get_caller(self.request)
  File "/home/tech/DataIssueTracker/env/lib/python3.10/site-packages/django/views/debug.py", line 100, in get_caller
    resolver_match = resolve(request.path)
  File "/home/tech/DataIssueTracker/env/lib/python3.10/site-packages/django/urls/base.py", line 24, in resolve
    return get_resolver(urlconf).resolve(path)
  File "/home/tech/DataIssueTracker/env/lib/python3.10/site-packages/django/urls/resolvers.py", line 663, in resolve
    for pattern in self.url_patterns:
  File "/home/tech/DataIssueTracker/env/lib/python3.10/site-packages/django/utils/functional.py", line 57, in __get__
    res = instance.__dict__[self.name] = self.func(instance)
  File "/home/tech/DataIssueTracker/env/lib/python3.10/site-packages/django/urls/resolvers.py", line 715, in url_patterns
    patterns = getattr(self.urlconf_module, "urlpatterns", self.urlconf_module)
  File "/home/tech/DataIssueTracker/env/lib/python3.10/site-packages/django/utils/functional.py", line 57, in __get__
    res = instance.__dict__[self.name] = self.func(instance)
  File "/home/tech/DataIssueTracker/env/lib/python3.10/site-packages/django/urls/resolvers.py", line 708, in urlconf_module
    return import_module(self.urlconf_name)
  File "/usr/lib/python3.10/importlib/__init__.py", line 126, in import_module
    return _bootstrap._gcd_import(name[level:], package, level)
  File "<frozen importlib._bootstrap>", line 1050, in _gcd_import
  File "<frozen importlib._bootstrap>", line 1027, in _find_and_load
  File "<frozen importlib._bootstrap>", line 1006, in _find_and_load_unlocked
  File "<frozen importlib._bootstrap>", line 688, in _load_unlocked
  File "<frozen importlib._bootstrap_external>", line 883, in exec_module
  File "<frozen importlib._bootstrap>", line 241, in _call_with_frames_removed
  File "/home/tech/DataIssueTracker/DITApi/DITApi/urls.py", line 27, in <module>
    path('api/',include('DQITAuth.urls')),
  File "/home/tech/DataIssueTracker/env/lib/python3.10/site-packages/django/urls/conf.py", line 38, in include
    urlconf_module = import_module(urlconf_module)
  File "/usr/lib/python3.10/importlib/__init__.py", line 126, in import_module
    return _bootstrap._gcd_import(name[level:], package, level)
  File "<frozen importlib._bootstrap>", line 1050, in _gcd_import
  File "<frozen importlib._bootstrap>", line 1027, in _find_and_load
  File "<frozen importlib._bootstrap>", line 1006, in _find_and_load_unlocked
  File "<frozen importlib._bootstrap>", line 688, in _load_unlocked
  File "<frozen importlib._bootstrap_external>", line 883, in exec_module
  File "<frozen importlib._bootstrap>", line 241, in _call_with_frames_removed
  File "/home/tech/DataIssueTracker/DITApi/DQITAuth/urls.py", line 3, in <module>
    from .views import (
  File "/home/tech/DataIssueTracker/DITApi/DQITAuth/views.py", line 88
    role = user.role.role_name if user.role else None
IndentationError: expected an indented block after 'except' statement on line 84

During handling of the above exception, another exception occurred:

Traceback (most recent call last):
  File "/home/tech/DataIssueTracker/env/lib/python3.10/site-packages/django/core/handlers/exception.py", line 55, in inner
    response = get_response(request)
  File "/home/tech/DataIssueTracker/env/lib/python3.10/site-packages/django/utils/deprecation.py", line 134, in __call__
    response = response or self.get_response(request)
  File "/home/tech/DataIssueTracker/env/lib/python3.10/site-packages/django/core/handlers/exception.py", line 57, in inner
    response = response_for_exception(request, exc)
  File "/home/tech/DataIssueTracker/env/lib/python3.10/site-packages/django/core/handlers/exception.py", line 140, in response_for_exception
    response = handle_uncaught_exception(
  File "/home/tech/DataIssueTracker/env/lib/python3.10/site-packages/django/core/handlers/exception.py", line 181, in handle_uncaught_exception
    return debug.technical_500_response(request, *exc_info)
  File "/home/tech/DataIssueTracker/env/lib/python3.10/site-packages/django/views/debug.py", line 67, in technical_500_response
    html = reporter.get_traceback_html()
  File "/home/tech/DataIssueTracker/env/lib/python3.10/site-packages/django/views/debug.py", line 410, in get_traceback_html
    c = Context(self.get_traceback_data(), use_l10n=False)
  File "/home/tech/DataIssueTracker/env/lib/python3.10/site-packages/django/views/debug.py", line 393, in get_traceback_data
    c["raising_view_name"] = get_caller(self.request)
  File "/home/tech/DataIssueTracker/env/lib/python3.10/site-packages/django/views/debug.py", line 100, in get_caller
    resolver_match = resolve(request.path)
  File "/home/tech/DataIssueTracker/env/lib/python3.10/site-packages/django/urls/base.py", line 24, in resolve
    return get_resolver(urlconf).resolve(path)
  File "/home/tech/DataIssueTracker/env/lib/python3.10/site-packages/django/urls/resolvers.py", line 663, in resolve
    for pattern in self.url_patterns:
  File "/home/tech/DataIssueTracker/env/lib/python3.10/site-packages/django/utils/functional.py", line 57, in __get__
    res = instance.__dict__[self.name] = self.func(instance)
  File "/home/tech/DataIssueTracker/env/lib/python3.10/site-packages/django/urls/resolvers.py", line 715, in url_patterns
    patterns = getattr(self.urlconf_module, "urlpatterns", self.urlconf_module)
  File "/home/tech/DataIssueTracker/env/lib/python3.10/site-packages/django/utils/functional.py", line 57, in __get__
    res = instance.__dict__[self.name] = self.func(instance)
  File "/home/tech/DataIssueTracker/env/lib/python3.10/site-packages/django/urls/resolvers.py", line 708, in urlconf_module
    return import_module(self.urlconf_name)
  File "/usr/lib/python3.10/importlib/__init__.py", line 126, in import_module
    return _bootstrap._gcd_import(name[level:], package, level)
  File "<frozen importlib._bootstrap>", line 1050, in _gcd_import
  File "<frozen importlib._bootstrap>", line 1027, in _find_and_load
  File "<frozen importlib._bootstrap>", line 1006, in _find_and_load_unlocked
  File "<frozen importlib._bootstrap>", line 688, in _load_unlocked
  File "<frozen importlib._bootstrap_external>", line 883, in exec_module
  File "<frozen importlib._bootstrap>", line 241, in _call_with_frames_removed
  File "/home/tech/DataIssueTracker/DITApi/DITApi/urls.py", line 27, in <module>
    path('api/',include('DQITAuth.urls')),
  File "/home/tech/DataIssueTracker/env/lib/python3.10/site-packages/django/urls/conf.py", line 38, in include
    urlconf_module = import_module(urlconf_module)
  File "/usr/lib/python3.10/importlib/__init__.py", line 126, in import_module
    return _bootstrap._gcd_import(name[level:], package, level)
  File "<frozen importlib._bootstrap>", line 1050, in _gcd_import
  File "<frozen importlib._bootstrap>", line 1027, in _find_and_load
  File "<frozen importlib._bootstrap>", line 1006, in _find_and_load_unlocked
  File "<frozen importlib._bootstrap>", line 688, in _load_unlocked
  File "<frozen importlib._bootstrap_external>", line 883, in exec_module
  File "<frozen importlib._bootstrap>", line 241, in _call_with_frames_removed
  File "/home/tech/DataIssueTracker/DITApi/DQITAuth/urls.py", line 3, in <module>
    from .views import (
  File "/home/tech/DataIssueTracker/DITApi/DQITAuth/views.py", line 88
    role = user.role.role_name if user.role else None
IndentationError: expected an indented block after 'except' statement on line 84

During handling of the above exception, another exception occurred:

Traceback (most recent call last):
  File "/home/tech/DataIssueTracker/env/lib/python3.10/site-packages/django/core/handlers/exception.py", line 55, in inner
    response = get_response(request)
  File "/home/tech/DataIssueTracker/env/lib/python3.10/site-packages/django/utils/deprecation.py", line 134, in __call__
    response = response or self.get_response(request)
  File "/home/tech/DataIssueTracker/env/lib/python3.10/site-packages/django/core/handlers/exception.py", line 57, in inner
    response = response_for_exception(request, exc)
  File "/home/tech/DataIssueTracker/env/lib/python3.10/site-packages/django/core/handlers/exception.py", line 140, in response_for_exception
    response = handle_uncaught_exception(
  File "/home/tech/DataIssueTracker/env/lib/python3.10/site-packages/django/core/handlers/exception.py", line 181, in handle_uncaught_exception
    return debug.technical_500_response(request, *exc_info)
  File "/home/tech/DataIssueTracker/env/lib/python3.10/site-packages/django/views/debug.py", line 67, in technical_500_response
    html = reporter.get_traceback_html()
  File "/home/tech/DataIssueTracker/env/lib/python3.10/site-packages/django/views/debug.py", line 410, in get_traceback_html
    c = Context(self.get_traceback_data(), use_l10n=False)
  File "/home/tech/DataIssueTracker/env/lib/python3.10/site-packages/django/views/debug.py", line 393, in get_traceback_data
    c["raising_view_name"] = get_caller(self.request)
  File "/home/tech/DataIssueTracker/env/lib/python3.10/site-packages/django/views/debug.py", line 100, in get_caller
    resolver_match = resolve(request.path)
  File "/home/tech/DataIssueTracker/env/lib/python3.10/site-packages/django/urls/base.py", line 24, in resolve
    return get_resolver(urlconf).resolve(path)
  File "/home/tech/DataIssueTracker/env/lib/python3.10/site-packages/django/urls/resolvers.py", line 663, in resolve
    for pattern in self.url_patterns:
  File "/home/tech/DataIssueTracker/env/lib/python3.10/site-packages/django/utils/functional.py", line 57, in __get__
    res = instance.__dict__[self.name] = self.func(instance)
  File "/home/tech/DataIssueTracker/env/lib/python3.10/site-packages/django/urls/resolvers.py", line 715, in url_patterns
    patterns = getattr(self.urlconf_module, "urlpatterns", self.urlconf_module)
  File "/home/tech/DataIssueTracker/env/lib/python3.10/site-packages/django/utils/functional.py", line 57, in __get__
    res = instance.__dict__[self.name] = self.func(instance)
  File "/home/tech/DataIssueTracker/env/lib/python3.10/site-packages/django/urls/resolvers.py", line 708, in urlconf_module
    return import_module(self.urlconf_name)
  File "/usr/lib/python3.10/importlib/__init__.py", line 126, in import_module
    return _bootstrap._gcd_import(name[level:], package, level)
  File "<frozen importlib._bootstrap>", line 1050, in _gcd_import
  File "<frozen importlib._bootstrap>", line 1027, in _find_and_load
  File "<frozen importlib._bootstrap>", line 1006, in _find_and_load_unlocked
  File "<frozen importlib._bootstrap>", line 688, in _load_unlocked
  File "<frozen importlib._bootstrap_external>", line 883, in exec_module
  File "<frozen importlib._bootstrap>", line 241, in _call_with_frames_removed
  File "/home/tech/DataIssueTracker/DITApi/DITApi/urls.py", line 27, in <module>
    path('api/',include('DQITAuth.urls')),
  File "/home/tech/DataIssueTracker/env/lib/python3.10/site-packages/django/urls/conf.py", line 38, in include
    urlconf_module = import_module(urlconf_module)
  File "/usr/lib/python3.10/importlib/__init__.py", line 126, in import_module
    return _bootstrap._gcd_import(name[level:], package, level)
  File "<frozen importlib._bootstrap>", line 1050, in _gcd_import
  File "<frozen importlib._bootstrap>", line 1027, in _find_and_load
  File "<frozen importlib._bootstrap>", line 1006, in _find_and_load_unlocked
  File "<frozen importlib._bootstrap>", line 688, in _load_unlocked
  File "<frozen importlib._bootstrap_external>", line 883, in exec_module
  File "<frozen importlib._bootstrap>", line 241, in _call_with_frames_removed
  File "/home/tech/DataIssueTracker/DITApi/DQITAuth/urls.py", line 3, in <module>
    from .views import (
  File "/home/tech/DataIssueTracker/DITApi/DQITAuth/views.py", line 88
    role = user.role.role_name if user.role else None
IndentationError: expected an indented block after 'except' statement on line 84

During handling of the above exception, another exception occurred:

Traceback (most recent call last):
  File "/home/tech/DataIssueTracker/env/lib/python3.10/site-packages/django/core/handlers/exception.py", line 55, in inner
    response = get_response(request)
  File "/home/tech/DataIssueTracker/env/lib/python3.10/site-packages/django/utils/deprecation.py", line 134, in __call__
    response = response or self.get_response(request)
  File "/home/tech/DataIssueTracker/env/lib/python3.10/site-packages/django/core/handlers/exception.py", line 57, in inner
    response = response_for_exception(request, exc)
  File "/home/tech/DataIssueTracker/env/lib/python3.10/site-packages/django/core/handlers/exception.py", line 140, in response_for_exception
    response = handle_uncaught_exception(
  File "/home/tech/DataIssueTracker/env/lib/python3.10/site-packages/django/core/handlers/exception.py", line 181, in handle_uncaught_exception
    return debug.technical_500_response(request, *exc_info)
  File "/home/tech/DataIssueTracker/env/lib/python3.10/site-packages/django/views/debug.py", line 67, in technical_500_response
    html = reporter.get_traceback_html()
  File "/home/tech/DataIssueTracker/env/lib/python3.10/site-packages/django/views/debug.py", line 410, in get_traceback_html
    c = Context(self.get_traceback_data(), use_l10n=False)
  File "/home/tech/DataIssueTracker/env/lib/python3.10/site-packages/django/views/debug.py", line 393, in get_traceback_data
    c["raising_view_name"] = get_caller(self.request)
  File "/home/tech/DataIssueTracker/env/lib/python3.10/site-packages/django/views/debug.py", line 100, in get_caller
    resolver_match = resolve(request.path)
  File "/home/tech/DataIssueTracker/env/lib/python3.10/site-packages/django/urls/base.py", line 24, in resolve
    return get_resolver(urlconf).resolve(path)
  File "/home/tech/DataIssueTracker/env/lib/python3.10/site-packages/django/urls/resolvers.py", line 663, in resolve
    for pattern in self.url_patterns:
  File "/home/tech/DataIssueTracker/env/lib/python3.10/site-packages/django/utils/functional.py", line 57, in __get__
    res = instance.__dict__[self.name] = self.func(instance)
  File "/home/tech/DataIssueTracker/env/lib/python3.10/site-packages/django/urls/resolvers.py", line 715, in url_patterns
    patterns = getattr(self.urlconf_module, "urlpatterns", self.urlconf_module)
  File "/home/tech/DataIssueTracker/env/lib/python3.10/site-packages/django/utils/functional.py", line 57, in __get__
    res = instance.__dict__[self.name] = self.func(instance)
  File "/home/tech/DataIssueTracker/env/lib/python3.10/site-packages/django/urls/resolvers.py", line 708, in urlconf_module
    return import_module(self.urlconf_name)
  File "/usr/lib/python3.10/importlib/__init__.py", line 126, in import_module
    return _bootstrap._gcd_import(name[level:], package, level)
  File "<frozen importlib._bootstrap>", line 1050, in _gcd_import
  File "<frozen importlib._bootstrap>", line 1027, in _find_and_load
  File "<frozen importlib._bootstrap>", line 1006, in _find_and_load_unlocked
  File "<frozen importlib._bootstrap>", line 688, in _load_unlocked
  File "<frozen importlib._bootstrap_external>", line 883, in exec_module
  File "<frozen importlib._bootstrap>", line 241, in _call_with_frames_removed
  File "/home/tech/DataIssueTracker/DITApi/DITApi/urls.py", line 27, in <module>
    path('api/',include('DQITAuth.urls')),
  File "/home/tech/DataIssueTracker/env/lib/python3.10/site-packages/django/urls/conf.py", line 38, in include
    urlconf_module = import_module(urlconf_module)
  File "/usr/lib/python3.10/importlib/__init__.py", line 126, in import_module
    return _bootstrap._gcd_import(name[level:], package, level)
  File "<frozen importlib._bootstrap>", line 1050, in _gcd_import
  File "<frozen importlib._bootstrap>", line 1027, in _find_and_load
  File "<frozen importlib._bootstrap>", line 1006, in _find_and_load_unlocked
  File "<frozen importlib._bootstrap>", line 688, in _load_unlocked
  File "<frozen importlib._bootstrap_external>", line 883, in exec_module
  File "<frozen importlib._bootstrap>", line 241, in _call_with_frames_removed
  File "/home/tech/DataIssueTracker/DITApi/DQITAuth/urls.py", line 3, in <module>
    from .views import (
  File "/home/tech/DataIssueTracker/DITApi/DQITAuth/views.py", line 88
    role = user.role.role_name if user.role else None
IndentationError: expected an indented block after 'except' statement on line 84

During handling of the above exception, another exception occurred:

Traceback (most recent call last):
  File "/home/tech/DataIssueTracker/env/lib/python3.10/site-packages/django/core/handlers/exception.py", line 55, in inner
    response = get_response(request)
  File "/home/tech/DataIssueTracker/env/lib/python3.10/site-packages/django/utils/deprecation.py", line 134, in __call__
    response = response or self.get_response(request)
  File "/home/tech/DataIssueTracker/env/lib/python3.10/site-packages/django/core/handlers/exception.py", line 57, in inner
    response = response_for_exception(request, exc)
  File "/home/tech/DataIssueTracker/env/lib/python3.10/site-packages/django/core/handlers/exception.py", line 140, in response_for_exception
    response = handle_uncaught_exception(
  File "/home/tech/DataIssueTracker/env/lib/python3.10/site-packages/django/core/handlers/exception.py", line 181, in handle_uncaught_exception
    return debug.technical_500_response(request, *exc_info)
  File "/home/tech/DataIssueTracker/env/lib/python3.10/site-packages/django/views/debug.py", line 67, in technical_500_response
    html = reporter.get_traceback_html()
  File "/home/tech/DataIssueTracker/env/lib/python3.10/site-packages/django/views/debug.py", line 410, in get_traceback_html
    c = Context(self.get_traceback_data(), use_l10n=False)
  File "/home/tech/DataIssueTracker/env/lib/python3.10/site-packages/django/views/debug.py", line 393, in get_traceback_data
    c["raising_view_name"] = get_caller(self.request)
  File "/home/tech/DataIssueTracker/env/lib/python3.10/site-packages/django/views/debug.py", line 100, in get_caller
    resolver_match = resolve(request.path)
  File "/home/tech/DataIssueTracker/env/lib/python3.10/site-packages/django/urls/base.py", line 24, in resolve
    return get_resolver(urlconf).resolve(path)
  File "/home/tech/DataIssueTracker/env/lib/python3.10/site-packages/django/urls/resolvers.py", line 663, in resolve
    for pattern in self.url_patterns:
  File "/home/tech/DataIssueTracker/env/lib/python3.10/site-packages/django/utils/functional.py", line 57, in __get__
    res = instance.__dict__[self.name] = self.func(instance)
  File "/home/tech/DataIssueTracker/env/lib/python3.10/site-packages/django/urls/resolvers.py", line 715, in url_patterns
    patterns = getattr(self.urlconf_module, "urlpatterns", self.urlconf_module)
  File "/home/tech/DataIssueTracker/env/lib/python3.10/site-packages/django/utils/functional.py", line 57, in __get__
    res = instance.__dict__[self.name] = self.func(instance)
  File "/home/tech/DataIssueTracker/env/lib/python3.10/site-packages/django/urls/resolvers.py", line 708, in urlconf_module
    return import_module(self.urlconf_name)
  File "/usr/lib/python3.10/importlib/__init__.py", line 126, in import_module
    return _bootstrap._gcd_import(name[level:], package, level)
  File "<frozen importlib._bootstrap>", line 1050, in _gcd_import
  File "<frozen importlib._bootstrap>", line 1027, in _find_and_load
  File "<frozen importlib._bootstrap>", line 1006, in _find_and_load_unlocked
  File "<frozen importlib._bootstrap>", line 688, in _load_unlocked
  File "<frozen importlib._bootstrap_external>", line 883, in exec_module
  File "<frozen importlib._bootstrap>", line 241, in _call_with_frames_removed
  File "/home/tech/DataIssueTracker/DITApi/DITApi/urls.py", line 27, in <module>
    path('api/',include('DQITAuth.urls')),
  File "/home/tech/DataIssueTracker/env/lib/python3.10/site-packages/django/urls/conf.py", line 38, in include
    urlconf_module = import_module(urlconf_module)
  File "/usr/lib/python3.10/importlib/__init__.py", line 126, in import_module
    return _bootstrap._gcd_import(name[level:], package, level)
  File "<frozen importlib._bootstrap>", line 1050, in _gcd_import
  File "<frozen importlib._bootstrap>", line 1027, in _find_and_load
  File "<frozen importlib._bootstrap>", line 1006, in _find_and_load_unlocked
  File "<frozen importlib._bootstrap>", line 688, in _load_unlocked
  File "<frozen importlib._bootstrap_external>", line 883, in exec_module
  File "<frozen importlib._bootstrap>", line 241, in _call_with_frames_removed
  File "/home/tech/DataIssueTracker/DITApi/DQITAuth/urls.py", line 3, in <module>
    from .views import (
  File "/home/tech/DataIssueTracker/DITApi/DQITAuth/views.py", line 88
    role = user.role.role_name if user.role else None
IndentationError: expected an indented block after 'except' statement on line 84

During handling of the above exception, another exception occurred:

Traceback (most recent call last):
  File "/home/tech/DataIssueTracker/env/lib/python3.10/site-packages/django/core/handlers/exception.py", line 55, in inner
    response = get_response(request)
  File "/home/tech/DataIssueTracker/env/lib/python3.10/site-packages/corsheaders/middleware.py", line 56, in __call__
    result = self.get_response(request)
  File "/home/tech/DataIssueTracker/env/lib/python3.10/site-packages/django/core/handlers/exception.py", line 57, in inner
    response = response_for_exception(request, exc)
  File "/home/tech/DataIssueTracker/env/lib/python3.10/site-packages/django/core/handlers/exception.py", line 140, in response_for_exception
    response = handle_uncaught_exception(
  File "/home/tech/DataIssueTracker/env/lib/python3.10/site-packages/django/core/handlers/exception.py", line 181, in handle_uncaught_exception
    return debug.technical_500_response(request, *exc_info)
  File "/home/tech/DataIssueTracker/env/lib/python3.10/site-packages/django/views/debug.py", line 67, in technical_500_response
    html = reporter.get_traceback_html()
  File "/home/tech/DataIssueTracker/env/lib/python3.10/site-packages/django/views/debug.py", line 410, in get_traceback_html
    c = Context(self.get_traceback_data(), use_l10n=False)
  File "/home/tech/DataIssueTracker/env/lib/python3.10/site-packages/django/views/debug.py", line 393, in get_traceback_data
    c["raising_view_name"] = get_caller(self.request)
  File "/home/tech/DataIssueTracker/env/lib/python3.10/site-packages/django/views/debug.py", line 100, in get_caller
    resolver_match = resolve(request.path)
  File "/home/tech/DataIssueTracker/env/lib/python3.10/site-packages/django/urls/base.py", line 24, in resolve
    return get_resolver(urlconf).resolve(path)
  File "/home/tech/DataIssueTracker/env/lib/python3.10/site-packages/django/urls/resolvers.py", line 663, in resolve
    for pattern in self.url_patterns:
  File "/home/tech/DataIssueTracker/env/lib/python3.10/site-packages/django/utils/functional.py", line 57, in __get__
    res = instance.__dict__[self.name] = self.func(instance)
  File "/home/tech/DataIssueTracker/env/lib/python3.10/site-packages/django/urls/resolvers.py", line 715, in url_patterns
    patterns = getattr(self.urlconf_module, "urlpatterns", self.urlconf_module)
  File "/home/tech/DataIssueTracker/env/lib/python3.10/site-packages/django/utils/functional.py", line 57, in __get__
    res = instance.__dict__[self.name] = self.func(instance)
  File "/home/tech/DataIssueTracker/env/lib/python3.10/site-packages/django/urls/resolvers.py", line 708, in urlconf_module
    return import_module(self.urlconf_name)
  File "/usr/lib/python3.10/importlib/__init__.py", line 126, in import_module
    return _bootstrap._gcd_import(name[level:], package, level)
  File "<frozen importlib._bootstrap>", line 1050, in _gcd_import
  File "<frozen importlib._bootstrap>", line 1027, in _find_and_load
  File "<frozen importlib._bootstrap>", line 1006, in _find_and_load_unlocked
  File "<frozen importlib._bootstrap>", line 688, in _load_unlocked
  File "<frozen importlib._bootstrap_external>", line 883, in exec_module
  File "<frozen importlib._bootstrap>", line 241, in _call_with_frames_removed
  File "/home/tech/DataIssueTracker/DITApi/DITApi/urls.py", line 27, in <module>
    path('api/',include('DQITAuth.urls')),
  File "/home/tech/DataIssueTracker/env/lib/python3.10/site-packages/django/urls/conf.py", line 38, in include
    urlconf_module = import_module(urlconf_module)
  File "/usr/lib/python3.10/importlib/__init__.py", line 126, in import_module
    return _bootstrap._gcd_import(name[level:], package, level)
  File "<frozen importlib._bootstrap>", line 1050, in _gcd_import
  File "<frozen importlib._bootstrap>", line 1027, in _find_and_load
  File "<frozen importlib._bootstrap>", line 1006, in _find_and_load_unlocked
  File "<frozen importlib._bootstrap>", line 688, in _load_unlocked
  File "<frozen importlib._bootstrap_external>", line 883, in exec_module
  File "<frozen importlib._bootstrap>", line 241, in _call_with_frames_removed
  File "/home/tech/DataIssueTracker/DITApi/DQITAuth/urls.py", line 3, in <module>
    from .views import (
  File "/home/tech/DataIssueTracker/DITApi/DQITAuth/views.py", line 88
    role = user.role.role_name if user.role else None
IndentationError: expected an indented block after 'except' statement on line 84

During handling of the above exception, another exception occurred:

Traceback (most recent call last):
  File "/home/tech/DataIssueTracker/env/lib/python3.10/site-packages/django/core/handlers/exception.py", line 55, in inner
    response = get_response(request)
  File "/home/tech/DataIssueTracker/env/lib/python3.10/site-packages/django/utils/deprecation.py", line 134, in __call__
    response = response or self.get_response(request)
  File "/home/tech/DataIssueTracker/env/lib/python3.10/site-packages/django/core/handlers/exception.py", line 57, in inner
    response = response_for_exception(request, exc)
  File "/home/tech/DataIssueTracker/env/lib/python3.10/site-packages/django/core/handlers/exception.py", line 140, in response_for_exception
    response = handle_uncaught_exception(
  File "/home/tech/DataIssueTracker/env/lib/python3.10/site-packages/django/core/handlers/exception.py", line 181, in handle_uncaught_exception
    return debug.technical_500_response(request, *exc_info)
  File "/home/tech/DataIssueTracker/env/lib/python3.10/site-packages/django/views/debug.py", line 67, in technical_500_response
    html = reporter.get_traceback_html()
  File "/home/tech/DataIssueTracker/env/lib/python3.10/site-packages/django/views/debug.py", line 410, in get_traceback_html
    c = Context(self.get_traceback_data(), use_l10n=False)
  File "/home/tech/DataIssueTracker/env/lib/python3.10/site-packages/django/views/debug.py", line 393, in get_traceback_data
    c["raising_view_name"] = get_caller(self.request)
  File "/home/tech/DataIssueTracker/env/lib/python3.10/site-packages/django/views/debug.py", line 100, in get_caller
    resolver_match = resolve(request.path)
  File "/home/tech/DataIssueTracker/env/lib/python3.10/site-packages/django/urls/base.py", line 24, in resolve
    return get_resolver(urlconf).resolve(path)
  File "/home/tech/DataIssueTracker/env/lib/python3.10/site-packages/django/urls/resolvers.py", line 663, in resolve
    for pattern in self.url_patterns:
  File "/home/tech/DataIssueTracker/env/lib/python3.10/site-packages/django/utils/functional.py", line 57, in __get__
    res = instance.__dict__[self.name] = self.func(instance)
  File "/home/tech/DataIssueTracker/env/lib/python3.10/site-packages/django/urls/resolvers.py", line 715, in url_patterns
    patterns = getattr(self.urlconf_module, "urlpatterns", self.urlconf_module)
  File "/home/tech/DataIssueTracker/env/lib/python3.10/site-packages/django/utils/functional.py", line 57, in __get__
    res = instance.__dict__[self.name] = self.func(instance)
  File "/home/tech/DataIssueTracker/env/lib/python3.10/site-packages/django/urls/resolvers.py", line 708, in urlconf_module
    return import_module(self.urlconf_name)
  File "/usr/lib/python3.10/importlib/__init__.py", line 126, in import_module
    return _bootstrap._gcd_import(name[level:], package, level)
  File "<frozen importlib._bootstrap>", line 1050, in _gcd_import
  File "<frozen importlib._bootstrap>", line 1027, in _find_and_load
  File "<frozen importlib._bootstrap>", line 1006, in _find_and_load_unlocked
  File "<frozen importlib._bootstrap>", line 688, in _load_unlocked
  File "<frozen importlib._bootstrap_external>", line 883, in exec_module
  File "<frozen importlib._bootstrap>", line 241, in _call_with_frames_removed
  File "/home/tech/DataIssueTracker/DITApi/DITApi/urls.py", line 27, in <module>
    path('api/',include('DQITAuth.urls')),
  File "/home/tech/DataIssueTracker/env/lib/python3.10/site-packages/django/urls/conf.py", line 38, in include
    urlconf_module = import_module(urlconf_module)
  File "/usr/lib/python3.10/importlib/__init__.py", line 126, in import_module
    return _bootstrap._gcd_import(name[level:], package, level)
  File "<frozen importlib._bootstrap>", line 1050, in _gcd_import
  File "<frozen importlib._bootstrap>", line 1027, in _find_and_load
  File "<frozen importlib._bootstrap>", line 1006, in _find_and_load_unlocked
  File "<frozen importlib._bootstrap>", line 688, in _load_unlocked
  File "<frozen importlib._bootstrap_external>", line 883, in exec_module
  File "<frozen importlib._bootstrap>", line 241, in _call_with_frames_removed
  File "/home/tech/DataIssueTracker/DITApi/DQITAuth/urls.py", line 3, in <module>
    from .views import (
  File "/home/tech/DataIssueTracker/DITApi/DQITAuth/views.py", line 88
    role = user.role.role_name if user.role else None
IndentationError: expected an indented block after 'except' statement on line 84

During handling of the above exception, another exception occurred:

Traceback (most recent call last):
  File "/home/tech/DataIssueTracker/env/lib/python3.10/site-packages/django/core/handlers/exception.py", line 55, in inner
    response = get_response(request)
  File "/home/tech/DataIssueTracker/env/lib/python3.10/site-packages/django/utils/deprecation.py", line 134, in __call__
    response = response or self.get_response(request)
  File "/home/tech/DataIssueTracker/env/lib/python3.10/site-packages/django/core/handlers/exception.py", line 57, in inner
    response = response_for_exception(request, exc)
  File "/home/tech/DataIssueTracker/env/lib/python3.10/site-packages/django/core/handlers/exception.py", line 140, in response_for_exception
    response = handle_uncaught_exception(
  File "/home/tech/DataIssueTracker/env/lib/python3.10/site-packages/django/core/handlers/exception.py", line 181, in handle_uncaught_exception
    return debug.technical_500_response(request, *exc_info)
  File "/home/tech/DataIssueTracker/env/lib/python3.10/site-packages/django/views/debug.py", line 67, in technical_500_response
    html = reporter.get_traceback_html()
  File "/home/tech/DataIssueTracker/env/lib/python3.10/site-packages/django/views/debug.py", line 410, in get_traceback_html
    c = Context(self.get_traceback_data(), use_l10n=False)
  File "/home/tech/DataIssueTracker/env/lib/python3.10/site-packages/django/views/debug.py", line 393, in get_traceback_data
    c["raising_view_name"] = get_caller(self.request)
  File "/home/tech/DataIssueTracker/env/lib/python3.10/site-packages/django/views/debug.py", line 100, in get_caller
    resolver_match = resolve(request.path)
  File "/home/tech/DataIssueTracker/env/lib/python3.10/site-packages/django/urls/base.py", line 24, in resolve
    return get_resolver(urlconf).resolve(path)
  File "/home/tech/DataIssueTracker/env/lib/python3.10/site-packages/django/urls/resolvers.py", line 663, in resolve
    for pattern in self.url_patterns:
  File "/home/tech/DataIssueTracker/env/lib/python3.10/site-packages/django/utils/functional.py", line 57, in __get__
    res = instance.__dict__[self.name] = self.func(instance)
  File "/home/tech/DataIssueTracker/env/lib/python3.10/site-packages/django/urls/resolvers.py", line 715, in url_patterns
    patterns = getattr(self.urlconf_module, "urlpatterns", self.urlconf_module)
  File "/home/tech/DataIssueTracker/env/lib/python3.10/site-packages/django/utils/functional.py", line 57, in __get__
    res = instance.__dict__[self.name] = self.func(instance)
  File "/home/tech/DataIssueTracker/env/lib/python3.10/site-packages/django/urls/resolvers.py", line 708, in urlconf_module
    return import_module(self.urlconf_name)
  File "/usr/lib/python3.10/importlib/__init__.py", line 126, in import_module
    return _bootstrap._gcd_import(name[level:], package, level)
  File "<frozen importlib._bootstrap>", line 1050, in _gcd_import
  File "<frozen importlib._bootstrap>", line 1027, in _find_and_load
  File "<frozen importlib._bootstrap>", line 1006, in _find_and_load_unlocked
  File "<frozen importlib._bootstrap>", line 688, in _load_unlocked
  File "<frozen importlib._bootstrap_external>", line 883, in exec_module
  File "<frozen importlib._bootstrap>", line 241, in _call_with_frames_removed
  File "/home/tech/DataIssueTracker/DITApi/DITApi/urls.py", line 27, in <module>
    path('api/',include('DQITAuth.urls')),
  File "/home/tech/DataIssueTracker/env/lib/python3.10/site-packages/django/urls/conf.py", line 38, in include
    urlconf_module = import_module(urlconf_module)
  File "/usr/lib/python3.10/importlib/__init__.py", line 126, in import_module
    return _bootstrap._gcd_import(name[level:], package, level)
  File "<frozen importlib._bootstrap>", line 1050, in _gcd_import
  File "<frozen importlib._bootstrap>", line 1027, in _find_and_load
  File "<frozen importlib._bootstrap>", line 1006, in _find_and_load_unlocked
  File "<frozen importlib._bootstrap>", line 688, in _load_unlocked
  File "<frozen importlib._bootstrap_external>", line 883, in exec_module
  File "<frozen importlib._bootstrap>", line 241, in _call_with_frames_removed
  File "/home/tech/DataIssueTracker/DITApi/DQITAuth/urls.py", line 3, in <module>
    from .views import (
  File "/home/tech/DataIssueTracker/DITApi/DQITAuth/views.py", line 88
    role = user.role.role_name if user.role else None
IndentationError: expected an indented block after 'except' statement on line 84

During handling of the above exception, another exception occurred:

Traceback (most recent call last):
  File "/home/tech/DataIssueTracker/env/lib/python3.10/site-packages/gunicorn/workers/sync.py", line 135, in handle
    self.handle_request(listener, req, client, addr)
  File "/home/tech/DataIssueTracker/env/lib/python3.10/site-packages/gunicorn/workers/sync.py", line 178, in handle_request
    respiter = self.wsgi(environ, resp.start_response)
  File "/home/tech/DataIssueTracker/env/lib/python3.10/site-packages/django/core/handlers/wsgi.py", line 124, in __call__
    response = self.get_response(request)
  File "/home/tech/DataIssueTracker/env/lib/python3.10/site-packages/django/core/handlers/base.py", line 140, in get_response
    response = self._middleware_chain(request)
  File "/home/tech/DataIssueTracker/env/lib/python3.10/site-packages/django/core/handlers/exception.py", line 57, in inner
    response = response_for_exception(request, exc)
  File "/home/tech/DataIssueTracker/env/lib/python3.10/site-packages/django/core/handlers/exception.py", line 140, in response_for_exception
    response = handle_uncaught_exception(
  File "/home/tech/DataIssueTracker/env/lib/python3.10/site-packages/django/core/handlers/exception.py", line 181, in handle_uncaught_exception
    return debug.technical_500_response(request, *exc_info)
  File "/home/tech/DataIssueTracker/env/lib/python3.10/site-packages/django/views/debug.py", line 67, in technical_500_response
    html = reporter.get_traceback_html()
  File "/home/tech/DataIssueTracker/env/lib/python3.10/site-packages/django/views/debug.py", line 410, in get_traceback_html
    c = Context(self.get_traceback_data(), use_l10n=False)
  File "/home/tech/DataIssueTracker/env/lib/python3.10/site-packages/django/views/debug.py", line 393, in get_traceback_data
    c["raising_view_name"] = get_caller(self.request)
  File "/home/tech/DataIssueTracker/env/lib/python3.10/site-packages/django/views/debug.py", line 100, in get_caller
    resolver_match = resolve(request.path)
  File "/home/tech/DataIssueTracker/env/lib/python3.10/site-packages/django/urls/base.py", line 24, in resolve
    return get_resolver(urlconf).resolve(path)
  File "/home/tech/DataIssueTracker/env/lib/python3.10/site-packages/django/urls/resolvers.py", line 663, in resolve
    for pattern in self.url_patterns:
  File "/home/tech/DataIssueTracker/env/lib/python3.10/site-packages/django/utils/functional.py", line 57, in __get__
    res = instance.__dict__[self.name] = self.func(instance)
  File "/home/tech/DataIssueTracker/env/lib/python3.10/site-packages/django/urls/resolvers.py", line 715, in url_patterns
    patterns = getattr(self.urlconf_module, "urlpatterns", self.urlconf_module)
  File "/home/tech/DataIssueTracker/env/lib/python3.10/site-packages/django/utils/functional.py", line 57, in __get__
    res = instance.__dict__[self.name] = self.func(instance)
  File "/home/tech/DataIssueTracker/env/lib/python3.10/site-packages/django/urls/resolvers.py", line 708, in urlconf_module
    return import_module(self.urlconf_name)
  File "/usr/lib/python3.10/importlib/__init__.py", line 126, in import_module
    return _bootstrap._gcd_import(name[level:], package, level)
  File "<frozen importlib._bootstrap>", line 1050, in _gcd_import
  File "<frozen importlib._bootstrap>", line 1027, in _find_and_load
  File "<frozen importlib._bootstrap>", line 1006, in _find_and_load_unlocked
  File "<frozen importlib._bootstrap>", line 688, in _load_unlocked
  File "<frozen importlib._bootstrap_external>", line 883, in exec_module
  File "<frozen importlib._bootstrap>", line 241, in _call_with_frames_removed
  File "/home/tech/DataIssueTracker/DITApi/DITApi/urls.py", line 27, in <module>
    path('api/',include('DQITAuth.urls')),
  File "/home/tech/DataIssueTracker/env/lib/python3.10/site-packages/django/urls/conf.py", line 38, in include
    urlconf_module = import_module(urlconf_module)
  File "/usr/lib/python3.10/importlib/__init__.py", line 126, in import_module
    return _bootstrap._gcd_import(name[level:], package, level)
  File "<frozen importlib._bootstrap>", line 1050, in _gcd_import
  File "<frozen importlib._bootstrap>", line 1027, in _find_and_load
  File "<frozen importlib._bootstrap>", line 1006, in _find_and_load_unlocked
  File "<frozen importlib._bootstrap>", line 688, in _load_unlocked
  File "<frozen importlib._bootstrap_external>", line 883, in exec_module
  File "<frozen importlib._bootstrap>", line 241, in _call_with_frames_removed
  File "/home/tech/DataIssueTracker/DITApi/DQITAuth/urls.py", line 3, in <module>
    from .views import (
  File "/home/tech/DataIssueTracker/DITApi/DQITAuth/views.py", line 88
    role = user.role.role_name if user.role else None
IndentationError: expected an indented block after 'except' statement on line 84
[2023-10-29 14:33:49 +0000] [107976] [INFO] Handling signal: int
[2023-10-29 14:33:50 +0000] [107976] [INFO] Shutting down: Master
[2023-10-29 14:36:14 +0000] [108015] [INFO] Starting gunicorn 21.2.0
[2023-10-29 14:36:14 +0000] [108015] [INFO] Listening at: http://0.0.0.0:8000 (108015)
[2023-10-29 14:36:14 +0000] [108015] [INFO] Using worker: sync
[2023-10-29 14:36:14 +0000] [108016] [INFO] Booting worker with pid: 108016
[2023-10-29 14:38:01 +0000] [108034] [INFO] Starting gunicorn 21.2.0
[2023-10-29 14:38:01 +0000] [108034] [INFO] Listening at: http://0.0.0.0:8001 (108034)
[2023-10-29 14:38:01 +0000] [108034] [INFO] Using worker: sync
[2023-10-29 14:38:01 +0000] [108035] [INFO] Booting worker with pid: 108035
[2023-10-29 14:38:29 +0000] [108038] [INFO] Starting gunicorn 21.2.0
[2023-10-29 14:38:29 +0000] [108038] [ERROR] Connection in use: ('0.0.0.0', 8001)
[2023-10-29 14:38:29 +0000] [108038] [ERROR] Retrying in 1 second.
[2023-10-29 14:38:30 +0000] [108038] [ERROR] Connection in use: ('0.0.0.0', 8001)
[2023-10-29 14:38:30 +0000] [108038] [ERROR] Retrying in 1 second.
[2023-10-29 14:38:31 +0000] [108038] [ERROR] Connection in use: ('0.0.0.0', 8001)
[2023-10-29 14:38:31 +0000] [108038] [ERROR] Retrying in 1 second.
[2023-10-29 14:38:32 +0000] [108038] [ERROR] Connection in use: ('0.0.0.0', 8001)
[2023-10-29 14:38:32 +0000] [108038] [ERROR] Retrying in 1 second.
[2023-10-29 14:38:33 +0000] [108038] [ERROR] Connection in use: ('0.0.0.0', 8001)
[2023-10-29 14:38:33 +0000] [108038] [ERROR] Retrying in 1 second.
[2023-10-29 14:38:34 +0000] [108038] [ERROR] Can't connect to ('0.0.0.0', 8001)
[2023-10-29 14:40:55 +0000] [108134] [INFO] Starting gunicorn 21.2.0
[2023-10-29 14:40:55 +0000] [108134] [INFO] Listening at: http://0.0.0.0:8001 (108134)
[2023-10-29 14:40:55 +0000] [108134] [INFO] Using worker: sync
[2023-10-29 14:40:55 +0000] [108135] [INFO] Booting worker with pid: 108135
[2023-10-29 14:50:20 +0000] [108316] [INFO] Starting gunicorn 21.2.0
[2023-10-29 14:50:20 +0000] [108316] [INFO] Listening at: http://0.0.0.0:8000 (108316)
[2023-10-29 14:50:20 +0000] [108316] [INFO] Using worker: sync
[2023-10-29 14:50:20 +0000] [108317] [INFO] Booting worker with pid: 108317
[2023-10-29 14:50:25 +0000] [108316] [INFO] Handling signal: int
[2023-10-29 14:50:26 +0000] [108316] [INFO] Shutting down: Master
[2023-10-29 15:10:27 +0000] [108696] [INFO] Starting gunicorn 21.2.0
[2023-10-29 15:10:27 +0000] [108696] [ERROR] Connection in use: ('0.0.0.0', 8000)
[2023-10-29 15:10:27 +0000] [108696] [ERROR] Retrying in 1 second.
[2023-10-29 15:10:28 +0000] [108696] [ERROR] Connection in use: ('0.0.0.0', 8000)
[2023-10-29 15:10:28 +0000] [108696] [ERROR] Retrying in 1 second.
[2023-10-29 15:10:29 +0000] [108696] [ERROR] Connection in use: ('0.0.0.0', 8000)
[2023-10-29 15:10:29 +0000] [108696] [ERROR] Retrying in 1 second.
[2023-10-29 15:10:30 +0000] [108696] [ERROR] Connection in use: ('0.0.0.0', 8000)
[2023-10-29 15:10:30 +0000] [108696] [ERROR] Retrying in 1 second.
[2023-10-29 15:10:31 +0000] [108696] [ERROR] Connection in use: ('0.0.0.0', 8000)
[2023-10-29 15:10:31 +0000] [108696] [ERROR] Retrying in 1 second.
[2023-10-29 15:10:32 +0000] [108696] [ERROR] Can't connect to ('0.0.0.0', 8000)
